Workbook

Sheet Summary All Towers
B2: Lakecity Roof Gardens - Projected Cash Flow
B3: (Structural & Finishes Works Nov 2024 to Jan 2026) | I3: Combined | U3: =TODAY() -> 46010
B4: S.No. | C4: Area | D4: Start Date Planned | E4: Consultant Budget NADA/SEMS | F4: Budget As per Initial Quotation Received | G4: Awarded Value | H4: Actual Spending | I4: Balance Amount | J4: Pending Approvals | K4: Actual Value On Completion | L4: Remarks | M4: %age | N4: 45597 | O4: 45627 | P4: 45658 | Q4: 45689 | R4: 45717 | T4: 45809 | U4: 45962 | V4: 45992 | W4: 46023 | X4: 46055 | Y4: 46084 | Z4: 46116
B5: A | C5: Structure ( I , L1 , L2,SOG ) Three Towers | G5: ='Summary I Tower'!G5+'Summary L1 Tower'!G5+'Summary L2 Tower'!G5 -> 2495608676 | H5: 2581111533 | K5: ='Summary I Tower'!K5+'Summary L1 Tower'!K5+'Summary L2 Tower'!K5 -> 0 | L5: ='Summary I Tower'!L5+'Summary L1 Tower'!L5+'Summary L2 Tower'!L5 -> 0 | M5: ='Summary I Tower'!M5+'Summary L1 Tower'!#REF!+'Summary L2 Tower'!#REF! -> #REF! | N5: ='Summary I Tower'!N5+'Summary L1 Tower'!#REF!+'Summary L2 Tower'!#REF! -> #REF! | O5: ='Summary I Tower'!O5+'Summary L1 Tower'!#REF!+'Summary L2 Tower'!#REF! -> #REF! | P5: ='Summary I Tower'!P5+'Summary L1 Tower'!#REF!+'Summary L2 Tower'!#REF! -> #REF! | Q5: ='Summary I Tower'!Q5+'Summary L1 Tower'!#REF!+'Summary L2 Tower'!#REF! -> #REF! | R5: ='Summary I Tower'!R5+'Summary L1 Tower'!#REF!+'Summary L2 Tower'!#REF! -> #REF! | T5: ='Summary I Tower'!S5+'Summary L2 Tower'!#REF!+'Summary L1 Tower'!#REF! -> #REF! | U5: ='Summary I Tower'!T5+'Summary L2 Tower'!M5+'Summary L1 Tower'!M5 -> 10562111
B6: A1 | C6: Ground Floor - I-Tower | F6: =60304169 -> 60304169 | G6: ='Approved Item-Actual'!C239 -> 51394568 | H6: ='Approved Item-Actual'!D239 -> 17120010 | I6: ='Approved Item-Actual'!E239 -> 34274558 | J6: =F6-G6 -> 8909601 | U6: ='Approved Item-Actual'!G239 -> 15640589 | V6: ='Approved Item-Actual'!H239 -> 11066984 | W6: ='Approved Item-Actual'!I239 -> 7566984
B7: A3 | C7: GYM+Business Center+Game room | G7: ='Approved Item-Actual'!C246 -> 67266238 | H7: ='Approved Item-Actual'!D246 -> 25816560 | I7: ='Approved Item-Actual'!E246 -> 49266238 | U7: ='Approved Item-Actual'!G246 -> 7816559.5 | V7: ='Approved Item-Actual'!H246 -> 30506495 | W7: ='Approved Item-Actual'!I246 -> 10943183
B8: A4 | C8: External Development | F8: 131000000 | G8: ='Court Yard'!J22 -> 15932000 | H8: =13000000+5000000+9000000+2000000+6500000+9000000 -> 44500000 | I8: =G8-J8-H8 -> -33518000 | J8: 4950000 | V8: 20000000 | W8: 5000000 | X8: 11000000 | Z8: 11000000
B10: B | C10: Façade Works ( I, L1,L2 tower) | E10: 86456205 | G10: ='Summary I Tower'!G7+'Summary L2 Tower'!G7+'Summary L1 Tower'!G7 -> 141508845 | H10: ='Summary I Tower'!H7+'Summary L2 Tower'!H7+'Summary L1 Tower'!H7 -> 128430940 | I10: ='Summary I Tower'!I7+'Summary L2 Tower'!I7+'Summary L1 Tower'!I7 -> 13077905 | K10: ='Summary I Tower'!K7+'Summary L1 Tower'!K7+'Summary L2 Tower'!K7 -> 0 | L10: ='Summary I Tower'!L7+'Summary L1 Tower'!L7+'Summary L2 Tower'!L7 -> #VALUE! | M10: ='Summary I Tower'!M7+'Summary L1 Tower'!#REF!+'Summary L2 Tower'!#REF! -> #REF! | N10: ='Summary I Tower'!N7+'Summary L1 Tower'!#REF!+'Summary L2 Tower'!#REF! -> #REF! | O10: ='Summary I Tower'!O7+'Summary L1 Tower'!#REF!+'Summary L2 Tower'!#REF! -> #REF! | P10: ='Summary I Tower'!P7+'Summary L1 Tower'!#REF!+'Summary L2 Tower'!#REF! -> #REF! | Q10: ='Summary I Tower'!Q7+'Summary L1 Tower'!#REF!+'Summary L2 Tower'!#REF! -> #REF! | R10: ='Summary I Tower'!R7+'Summary L1 Tower'!#REF!+'Summary L2 Tower'!#REF! -> #REF! | S10: ='Summary L1 Tower'!#REF!+'Summary L2 Tower'!#REF!+6523569 -> #REF! | T10: ='Summary I Tower'!S7+'Summary L2 Tower'!#REF!+'Summary L1 Tower'!#REF! -> #REF! | U10: 13077905
B12: C | C12: Finishes For Tower I , L1 ,L2 | F12: ='Summary I Tower'!F9+'Summary L2 Tower'!F9+'Summary L1 Tower'!F9 -> 5.0346786e+09 | G12: ='Summary I Tower'!G9+'Summary L1 Tower'!G9+'Summary L2 Tower'!G9 -> 2.1721203e+09 | H12: ='Summary I Tower'!H9+'Summary L1 Tower'!H9+'Summary L2 Tower'!H9 -> 1.1044648e+09 | I12: ='I Finishes'!I82+'Summary L1 Tower'!I9+'Summary L2 Tower'!I9 -> 1.0555989e+09 | J12: ='I Finishes'!J82+'Summary L1 Tower'!J9+'Summary L2 Tower'!J9+J8+J6 -> 2.5484457e+09 | K12: ='Summary I Tower'!K9+'Summary L1 Tower'!K9+'Summary L2 Tower'!K9 -> 0 | L12: ='Summary I Tower'!L9+'Summary L1 Tower'!L9+'Summary L2 Tower'!L9 -> 4382502 | M12: ='Summary I Tower'!M9+'Summary L1 Tower'!#REF!+'Summary L2 Tower'!#REF! -> #REF! | N12: ='Summary I Tower'!N9+'Summary L1 Tower'!#REF!+'Summary L2 Tower'!#REF! -> #REF! | O12: ='Summary I Tower'!O9+'Summary L1 Tower'!#REF!+'Summary L2 Tower'!#REF! -> #REF! | P12: ='Summary I Tower'!P9+'Summary L1 Tower'!#REF!+'Summary L2 Tower'!#REF! -> #REF! | Q12: ='Summary I Tower'!Q9+'Summary L1 Tower'!#REF!+'Summary L2 Tower'!#REF! -> #REF! | R12: ='Summary I Tower'!R9+'Summary L1 Tower'!#REF!+'Summary L2 Tower'!#REF! -> #REF! | S12: ='Summary I Tower'!#REF!+'Summary L1 Tower'!#REF!+'Summary L2 Tower'!#REF!+'L2 Finishes'!R6 -> #REF! | T12: ='Summary I Tower'!S9+'Summary L1 Tower'!#REF!+'Summary L2 Tower'!#REF! -> #REF! | U12: ='Summary I Tower'!T9+'Summary L1 Tower'!M9+'Summary L2 Tower'!N9 -> 4.2812417e+08 | V12: ='Summary I Tower'!U9+'Summary L1 Tower'!N9+'Summary L2 Tower'!O9 -> 4.6640304e+08 | W12: ='Summary I Tower'!V9+'Summary L1 Tower'!O9+'Summary L2 Tower'!P9 -> 3.7041621e+08 | X12: ='Summary I Tower'!W9+'Summary L1 Tower'!P9+'Summary L2 Tower'!Q9 -> 1.2473132e+08 | Y12: ='Summary I Tower'!X9+'Summary L1 Tower'!Q9+'Summary L2 Tower'!R9 -> 1793266.3 | Z12: ='Summary I Tower'!Y9+'Summary L1 Tower'!R9+'Summary L2 Tower'!S9 -> 0
C14: Total | G14: =SUM(G5,G10,G6,G7,G8,G12) -> 4.9438307e+09 | H14: =SUM(H5,H10,H6,H7,H8,H12) -> 3.9014439e+09 | I14: =SUM(I5,I10,I6,I7,I8,I12) -> 1.1186996e+09 | J14: =SUM(J5,J10,J6,J7,J8,J12) -> 2.5623053e+09 | K14: =SUM(K5,K10,K6,K7,K8,K12) -> 0 | L14: =SUM(L5,L10,L6,L7,L8,L12) -> #VALUE! | M14: =SUM(M5,M10,M6,M7,M8,M12) -> #REF! | N14: =SUM(N5,N10,N6,N7,N8,N12) -> #REF! | ... Y14: =SUM(Y5,Y10,Y6,Y7,Y8,Y12) -> 1793266.3 | Z14: =Z6+Z10+Z12+Z5 -> 0
C15: Note : Exclusions are ( Roof top & MEP, Courtyard Finishes, Bridges Related Finishes, Basement)
Q16: =2369350563-2552633529 -> -183282966

Sheet Summary I Tower
B2: Lakecity Roof Gardens - Projected Cash Flow | L2: 45483
B3: (Structural & Finishes Works Jun 2025 to Jan 2026) | H3: I-Tower | U3: =TODAY() -> 46010
B4: S.No. | C4: Area | D4: Start Date Planned | E4: Consultant Budget NADA/SEMS | F4: Budget As per Initial Quotation Received | G4: Awarded Value | H4: Actual Spending | I4: Balance Amount | J4: Pending Approval | K4: Actual Value On Completion | L4: Remarks | M4: %age | N4: 45627 | O4: 45658 | P4: 45689 | Q4: 45717 | R4: 45748 | S4: 45809 | T4: 45962 | U4: 45992 | V4: 46023 | W4: 46054 | X4: 46082
B5: A | C5: Structure | G5: 1095058864 | H5: =1075105541+4500000+5453323+1464003 -> 1086522867 | I5: =G5-H5 -> 8535997 | T5: 3539864
B7: B | C7: Façade Works ( I tower) | E7: 86456205 | F7: 64000000 | G7: 52883243 | H7: ='I Finishes'!H6 -> 48820745 | I7: =G7-H7 -> 4062498 | L7: In progress ( 86% completed) 3 sides | M7: 0.38832334 | N7: ='I Finishes'!N6 -> 0 | O7: ='I Finishes'!O6 -> 0 | P7: ='I Finishes'!P6 -> 0 | T7: 4062498
B9: C | C9: Finishes For Tower 1 | F9: ='I Finishes'!F82 -> 2.2959485e+09 | G9: ='I Finishes'!G82 -> 1591289242 | H9: ='I Finishes'!H82 -> 9.2636621e+08 | I9: ='I Finishes'!I82 -> 6.6624049e+08 | J9: ='I Finishes'!J82 -> 4.5970393e+08 | L9: 1460834 | M9: 37.517879 | N9: ='I Finishes'!#REF! -> #REF! | O9: ='I Finishes'!#REF! -> #REF! | T9: ='I Finishes'!V82 -> 3.377139e+08 | U9: ='I Finishes'!W82 -> 3.5526608e+08 | V9: ='I Finishes'!X82 -> 2.9997504e+08 | W9: ='I Finishes'!Y82 -> 89399782 | X9: ='I Finishes'!Z82 -> 0
C11: Total | G11: =SUM(G5,G7,G9) -> 2739231349 | H11: =SUM(H5,H7,H9) -> 2.0617098e+09 | I11: =SUM(I5,I7,I9) -> 6.7883899e+08 | J11: =SUM(J5,J7,J9) -> 4.5970393e+08 | K11: =SUM(K5,K7,K9) -> 0 | L11: =SUM(L5,L7,L9) -> 1460834 | M11: =SUM(M5,M7,M9) -> 37.906202 | N11: =SUM(N5,N7,N9) -> #REF! | ... R11: =SUM(R5,R7,R9) -> 0 | T11: =SUM(T5,T7,T9) -> 3.4531626e+08 | U11: =SUM(U5,U7,U9) -> 3.5526608e+08 | V11: =SUM(V5,V7,V9) -> 2.9997504e+08 | W11: =SUM(W5,W7,W9) -> 89399782 | X11: =SUM(X5,X7,X9) -> 0

Sheet Summary L1 Tower
B2: Lakecity Roof Gardens - Projected Cash Flow | L2: 45483
B3: (Structural & Finishes Works Jun 2025 to Jan 2026) | I3: L 1 Tower | P3: =TODAY() -> 46010
B4: S.No. | C4: Area | D4: Start Date Planned | E4: Consultant Budget NADA/SEMS | F4: Budget As per Initial Quotation Received | G4: Awarded Value | H4: Actual Spending | I4: Balance Amount | J4: Pending Approvals | K4: Actual Value On Completion | L4: Remarks | M4: 45962 | N4: 45992 | O4: 46023 | P4: 46054 | Q4: 46082
B5: A | C5: Structure | G5: =H5+I5 -> 696162769 | H5: =649815453+18864933+20000000+4000000 -> 692680386 | I5: 3482383 | M5: 3482383
B7: B | C7: Façade Works (L1 tower) | E7: 86456205 | F7: 64000000 | G7: 40291143 | H7: ='L1 Finishes'!H4 -> 35449591 | I7: =G7-H7 -> 4841552 | M7: 4841552
B9: C | C9: Finishes For Tower L1 | F9: ='L1 Finishes'!F77 -> 1.4301803e+09 | G9: ='L1 Finishes'!G77 -> 341560587 | H9: ='L1 Finishes'!H77 -> 1.4677802e+08 | I9: ='L1 Finishes'!I77 -> 1.8140853e+08 | J9: ='L1 Finishes'!J77 -> 991071164 | L9: 1460834 | M9: ='L1 Finishes'!P77 -> 47266940 | N9: ='L1 Finishes'!Q77 -> 60059632 | O9: ='L1 Finishes'!R77 -> 25946459 | P9: ='L1 Finishes'!S77 -> 6667630 | Q9: ='L1 Finishes'!T77 -> 1793266.3
C11: Total | G11: =SUM(G5,G7,G9) -> 1078014499 | H11: =SUM(H5,H7,H9) -> 8.74908e+08 | I11: =SUM(I5,I7,I9) -> 1.8973247e+08 | J11: =J9 -> 991071164 | K11: =SUM(K5,K7,K9) -> 0 | L11: =SUM(L5,L7,L9) -> 1460834 | M11: =SUM(M5,M7,M9) -> 55590875 | N11: =SUM(N5,N7,N9) -> 60059632 | O11: =SUM(O5,O7,O9) -> 25946459 | P11: =SUM(P5,P7,P9) -> 6667630 | Q11: =SUM(Q5,Q7,Q9) -> 1793266.3

Sheet Summary L2 Tower
B2: Lakecity Roof Gardens - Projected Cash Flow
B3: (Structural & Finishes Works Jun 2025 to Jan 2026) | I3: L-2 Tower | Q3: =TODAY() -> 46010
B4: S.No. | C4: Area | D4: Start Date Planned | E4: Consultant Budget NADA/SEMS | F4: Budget As per Initial Quotation Received | G4: Awarded Value | H4: Actual Spending | I4: Balance Amount | J4: Pending Approvals | K4: Actual Value On Completion | L4: Remarks | M4: 45962 | N4: 45992 | O4: 46023 | P4: 46054 | Q4: 46082
B5: A | C5: Structure | G5: 704387043 | H5: =672622745+18864933+4000000+2500000 -> 697987678 | I5: =G5-H5 -> 6399365 | M5: 3539864
B7: B | C7: Façade Works (L2 tower) | E7: 86456205 | F7: 64000000 | G7: ='L2 Finishes'!G4 -> 48334459 | H7: ='L2 Finishes'!H4 -> 44160604 | I7: ='L2 Finishes'!I4 -> 4173855 | M7: 5370108
B9: C | C9: Finishes For Tower L2 | F9: ='L2 Finishes'!F65 -> 1308549823 | G9: ='L2 Finishes'!G65 -> 2.3927051e+08 | H9: ='L2 Finishes'!H65 -> 31320606 | I9: ='L2 Finishes'!I65 -> 2.0794991e+08 | J9: ='L2 Finishes'!J65 -> 1.083811e+09 | L9: 1460834 | M9: ='L2 Finishes'!O77 -> 49629394 | N9: ='L2 Finishes'!P77 -> 43143327 | O9: ='L2 Finishes'!Q77 -> 51077327 | P9: ='L2 Finishes'!R77 -> 44494709 | Q9: ='L2 Finishes'!S77 -> 28663907
C11: Total | G11: =SUM(G5,G7,G9) -> 9.9199202e+08 | H11: =SUM(H5,H7,H9) -> 773468888 | I11: =SUM(I5,I7,I9) -> 2.1852313e+08 | J11: =J9 -> 1.083811e+09 | K11: =SUM(K5,K7,K9) -> 0 | L11: =SUM(L5,L7,L9) -> 1460834 | M11: =SUM(M5,M7,M9) -> 58539366 | N11: =SUM(N5,N7,N9) -> 43143327 | O11: =SUM(O5,O7,O9) -> 51077327 | P11: =SUM(P5,P7,P9) -> 44494709 | Q11: =SUM(Q5,Q7,Q9) -> 28663907

Sheet I Finishes
B3: Lakecity Roof Gardens - Projected Cash Flow | Q3: =TODAY() -> 46010
B4: (Structural & Finishes Works Jun 2025 to Jan 2026) | G4: I- Tower | AB4: =TODAY() -> 46010
B5: S.No. | C5: Area | D5: Start Date Planned | E5: Consultant Budget NADA/SEMS | F5: Budget As per Initial Quotation Received | G5: Awarded Value | H5: Actual Spending | I5: Actual Balance Amount | J5: Pending approval | K5: Actual Value On Completion | L5: Remarks | M5: %age | N5: 45627 | O5: 45658 | P5: 45691 | Q5: 45724 | R5: 45787 | S5: 45870 | T5: 45902 | U5: 45934 | V5: 45966 | W5: 45998 | X5: 46030 | Y5: 46062 | AB5: Remarks
B6: A | C6: Façade Works ( I tower) | E6: 86456205 | F6: 64000000 | G6: 52883243 | H6: =43643500+2689245+1200000+1288000 -> 48820745 | I6: =G6-H6 -> 4062498 | M6: =1-G6/E6 -> 0.38832334 | T6: =I6 -> 4062498 | AB6: In progress
C7: Finishes For Tower 1
B8: 1 | C8: External Brick Works (M+L) | D8: 45292 | E8: 19400000 | F8: 14809000 | G8: 14500000 | H8: 14500000 | I8: =G8-H8 -> 0 | K8: 14609802 | L8: Completed | M8: =1-G8/E8 -> 0.25257732 | Z8: =I8+J8 -> 0
B9: 2 | C9: Internal Brick Works (M+L) | D9: 45324 | E9: 105250505 | F9: 93557500 | G9: 92385014 | H9: =41491446+18320118+4856414+18962187+5089451+474828+3872000 -> 93066444 | I9: =G9-H9 -> -681430 | K9: =G9-H9-I9 -> 0 | M9: =1-G9/E9 -> 0.12223686 | Z9: =I9+J9 -> -681430 | AA9: =Z9-V9-W9-X9-Y9 -> -681430
B10: 3 | C10: Electrical Conduiting (M+L) | D10: 45354 | E10: 42123560 | F10: 34734900 | G10: 29485630 | H10: =25814800+97344+3658042*0.7 -> 28472773 | I10: =G10-H10 -> 1012856.6 | K10: =G10-H10-I10 -> 0 | M10: =1-G10/E10 -> 0.30002046 | S10: 2440816 | T10: 1132670 | V10: =I10 -> 1012856.6 | Z10: =I10+J10 -> 1012856.6 | AA10: =Z10-V10-W10-X10-Y10 -> 0 | AB10: In progress
B11: 4 | C11: Plumbing Conduiting (M+L) | D11: 45386 | E11: 33256400 | F11: 25013632 | G11: 23645601 | H11: =20811384+198564 -> 21009948 | I11: =G11-H11 -> 2635653 | K11: =G11-H11-I11 -> 0 | M11: =1-G11/E11 -> 0.28899096 | S11: 1767701 | T11: 867952 | V11: =I11 -> 2635653 | Z11: =I11+J11 -> 2635653 | AA11: =Z11-V11-W11-X11-Y11 -> 0 | AB11: In progress
B12: 5 | C12: SOIL, WASTE VENT AND RAIN WATER DRAINAGE SYSTEM (M) | D12: 45471 | E12: 67805200 | F12: 22173540 | G12: 19367707 | H12: =13960440+2623918+1312023+33740+917251+319455+196109 -> 19362936 | I12: =G12-H12 -> 4771 | K12: =G12-H12-I12 -> 0 | M12: =1-G12/E12 -> 0.71436251 | S12: 2763349 | V12: =I12 -> 4771 | Z12: =I12+J12 -> 4771 | AA12: =Z12-V12-W12-X12-Y12 -> 0 | AB12: In progress
B13: 6 | C13: PCC (M+L) | D13: 45386 | E13: 43589100 | F13: 32900000 | G13: 27569921 | H13: 26661230 | I13: =G13-H13 -> 908691 | K13: =G13-H13-I13 -> 0 | M13: =1-G13/E13 -> 0.36750424 | S13: 2748201.7 | T13: 5107221.7 | V13: =I13 -> 908691 | Z13: =I13+J13 -> 908691 | AA13: =Z13-V13-W13-X13-Y13 -> 0 | AB13: In progress
B14: 7 | C14: External Plaster (M+L) | D14: 45387 | E14: 11073231 | F14: 6841856 | G14: 6841856 | H14: =2292643+1419494 -> 3712137 | I14: =G14-H14 -> 3129719 | K14: =G14-H14-I14 -> 0 | M14: =1-G14/E14 -> 0.3821265 | S14: 1785429.8 | T14: 1344289.2 | V14: =I14 -> 3129719 | Z14: =I14+J14 -> 3129719 | AA14: =Z14-V14-W14-X14-Y14 -> 0 | AB14: In progress
B15: 8 | C15: Internal Plaster (M+L) | D15: 45418 | E15: 72699100 | F15: 57158144 | G15: 57158144 | H15: =42002436+2214306 -> 44216742 | I15: =G15-H15 -> 12941402 | M15: =1-G15/E15 -> 0.21377095 | S15: 4906620.2 | T15: 8034781.8 | V15: =I15/2 -> 6470701 | W15: 6470701 | Z15: =I15+J15 -> 12941402 | AA15: =Z15-V15-W15-X15-Y15 -> 0 | AB15: In progress
B16: 9 | C16: Boundary Wall (M+L) | D16: 45419 | E16: 36982115 | F16: 36982115 | G16: =H16+I16 -> 25545140 | H16: 23545140 | I16: 2000000 | K16: =G16-H16-I16 -> 0 | M16: =1-G16/E16 -> 0.30925692 | V16: 2000000 | Z16: =I16+J16 -> 2000000 | AA16: =Z16-V16-W16-X16-Y16 -> 0 | AB16: In progress
B17: 10 | C17: Subcontract Electrical (L) | D17: 45450 | E17: 37629817 | F17: 31686490 | G17: 21095340 | H17: =1820120+814944+1266100+1352002+1294899*0.5 -> 5900615.5 | I17: =G17-H17 -> 15194724 | K17: =G17-H17-I17 -> 0 | M17: =1-G17/E17 -> 0.43939828 | S17: 1245757.2 | T17: 2475516.2 | V17: 3475516.2 | W17: 4475516.2 | X17: 5258330.2 | Y17: 1985362 | Z17: =I17+J17 -> 15194724 | AA17: =Z17-V17-W17-X17-Y17 -> 0 | AB17: In progress
B18: 11 | C18: Subcontract Plumbing (L) | D18: 45469 | E18: 35604250 | F18: 27427180 | G18: 25674500 | H18: =2116343+2691508+1800000+2259658+1345416+1294899*0.5 -> 10860374 | I18: =G18-H18 -> 14814126 | K18: =G18-H18-I18 -> 0 | M18: =1-G18/E18 -> 0.27889227 | S18: 1635220.5 | T18: 3834045.5 | V18: 3219511.5 | W18: 5219511.5 | X18: 5219511.5 | Y18: 1155591.1 | Z18: =I18+J18 -> 14814126 | AA18: =Z18-V18-W18-X18-Y18 -> 0 | AB18: In progress
B19: 12 | C19: CABLE CONTAINMENT (M) | D19: 45466 | E19: 31018260 | F19: 28656500 | G19: 19470000 | H19: =16476180+26512 -> 16502692 | I19: =G19-H19 -> 2967308 | K19: =G19-H19-I19 -> 0 | M19: =1-G19/E19 -> 0.37230522 | Z19: =I19+J19 -> 2967308 | AA19: =Z19-V19-W19-X19-Y19 -> 2967308 | AB19: In progress
B20: 13 | C20: Subcontract Firefighting (L) | D20: 45502 | E20: 8670000 | F20: 6679244 | G20: 5000000 | H20: =3791533+107035 -> 3898568 | I20: =G20-H20 -> 1101432 | M20: =1-G20/E20 -> 0.42329873 | S20: 339349 | T20: 839349 | W20: 1101432 | Z20: =I20+J20 -> 1101432 | AA20: =Z20-V20-W20-X20-Y20 -> 0 | AB20: In progress
B21: 14 | C21: FSS Works (Piping) (M) | D21: 45502 | E21: 33264800 | F21: 25124723 | G21: 18686350 | H21: =15234537+382304 -> 15616841 | I21: =G21-H21 -> 3069509 | K21: =G21-H21-I21 -> 0 | M21: =1-G21/E21 -> 0.43825455 | S21: 1549431 | V21: =1902382+1549431 -> 3451813 | Z21: =I21+J21 -> 3069509 | AA21: =Z21-V21-W21-X21-Y21 -> -382304 | AB21: In progress
B22: 15 | C22: Subcontract HVAC (M+L) | D22: 45502 | E22: 20290815 | F22: 16644196 | G22: 11000000 | H22: =3300000+3600+2286362+385757+4103060*0.3 -> 7206637 | I22: =G22-H22 -> 3793363 | K22: =G22-H22-I22 -> 0 | M22: =1-G22/E22 -> 0.45788279 | S22: 1925000 | T22: 1563638 | V22: 1921400 | W22: 1871963 | Z22: =I22+J22 -> 3793363 | AA22: =Z22-V22-W22-X22-Y22 -> 0 | AB22: In progress
B23: 16 | C23: Copper Pipe + Accessories (M+L) | D23: 45497 | E23: 39351450 | F23: 32836457 | G23: 20000000 | H23: =6600000+4955116+1253794+4103060*0.7+1848245 -> 17529297 | I23: =G23-H23 -> 2470703 | K23: =G23-H23-I23 -> 0 | M23: =1-G23/E23 -> 0.49175952 | S23: 460449 | T23: 3444884 | V23: 2900000 | W23: 1418948 | Z23: =I23+J23 -> 2470703 | AA23: =Z23-V23-W23-X23-Y23 -> -1848245 | AB23: In progress
B24: 17 | C24: LPG Works (M) | D24: 45468 | F24: =8857793+10232307 -> 19090100 | G24: 6500000 | H24: =2680796+836528+225850+304143 -> 4047317 | I24: =G24-H24 -> 2452683 | J24: =F24-G24 -> 12590100 | K24: =G24-H24-I24 -> 0 | L24: Dropped | S24: 5196700 | T24: 5196700 | V24: 5196700 | W24: =819204+9090100 -> 9909304 | Z24: =I24+J24 -> 15042783 | AB24: Partial -
B25: 18 | C25: WIRING / WIRING ACCESSORIES (M) | D25: 45503 | E25: 85098584 | F25: 51089750 | G25: 45147657 | H25: =36633106+260243+2746182+8043793*0.6 -> 44465807 | I25: =G25-H25 -> 681850.2 | K25: =G25-H25-I25 -> 0 | M25: =1-G25/E25 -> 0.46946642 | T25: 5508126 | V25: 681850.2 | Z25: =I25+J25 -> 681850.2 | AA25: =Z25-V25-W25-X25-Y25 -> 0 | AB25: In progress
B26: 19 | C26: MAIN / SUB-MAIN CABLES (M) | D26: 45474 | E26: 21986420 | F26: 18632283 | G26: 17180375 | H26: =13756310+8043793*0.4 -> 16973827 | I26: =G26-H26 -> 206547.8 | K26: =G26-H26-I26 -> 0 | M26: =1-G26/E26 -> 0.21859152 | S26: 3424065 | V26: 206547.8 | Z26: =I26+J26 -> 206547.8 | AA26: =Z26-V26-W26-X26-Y26 -> 0 | AB26: In progress
B27: 20 | C27: VOICE & DATA COMMUNICATION (M+L) | D27: 45592 | E27: 21124350 | F27: 16692700 | G27: =1698760+3838900 -> 5537660 | H27: 4688280 | I27: =G27-H27 -> 849380 | J27: =F27-G27 -> 11155040 | K27: =G27-H27-I27 -> 0 | L27: =D27 -> 45592 | M27: =1-G27/E27 -> 0.73785418 | S27: 3782116.7 | T27: 3782116.7 | V27: 3658070 | W27: =782116+7655040 -> 8437156 | Z27: =I27+J27 -> 12004420 | AB27: In progress
B28: 21 | C28: Pipes for Water Supply and fitting (M) | D28: 45593 | E28: 18218500 | F28: 13469930 | G28: 13000000 | H28: =9298883+1682370+134167+3658042*0.3 -> 12212833 | I28: =G28-H28 -> 787167.4 | K28: =G28-H28-I28 -> 0 | M28: =1-G28/E28 -> 0.28643961 | S28: 3177196 | T28: 523921 | W28: 787167.4 | Z28: =I28+J28 -> 787167.4 | AA28: =Z28-V28-W28-X28-Y28 -> 0 | AB28: In progress
B29: 22 | C29: Elevator (M+L) | D29: 45592 | E29: 121424000 | F29: 55000000 | G29: =26500*1.45*280*4+6000000 -> 49036000 | H29: =55000*280+2400000 -> 17800000 | I29: =G29-H29 -> 31236000 | K29: =G29-H29-I29 -> 0 | L29: =D29 -> 45592 | M29: =1-G29/E29 -> 0.59615891 | T29: 28404500 | V29: 26004500 | W29: 5231500 | Z29: =I29+J29 -> 31236000 | AA29: =Z29-V29-W29-X29-Y29 -> 0
B30: 23 | C30: BORE WELL WATER SUPPLY SYSTEM (M+L) | D30: 45592 | E30: 15263600 | F30: 12349580 | I30: =G30-H30 -> 0 | J30: =F30 -> 12349580 | K30: =G30-H30-I30 -> 0 | L30: =D30 -> 45592 | M30: =1-G30/E30 -> 1 | S30: 6174790 | V30: 6174790 | W30: 6174790 | Z30: =I30+J30 -> 12349580 | AA30: =Z30-V30-W30-X30-Y30 -> 0
B31: 24 | C31: Aluminum Work (M+L) | D31: 45592 | E31: 117000000 | F31: =39424791.59+11216060 -> 50640852 | G31: 68331343 | H31: =17082836+14369678 -> 31452514 | I31: =G31-H31 -> 36878829 | K31: =G31-H31-I31 -> 0 | L31: =D31 -> 45592 | M31: =1-G31/E31 -> 0.41597143 | T31: 10917164 | V31: 17000000 | W31: 17000000 | X31: 9000000 | Y31: =8331343-82836 -> 8248507 | Z31: =I31+J31 -> 36878829 | AA31: =Z31-V31-W31-X31-Y31 -> -14369678 | AB31: In progress
B32: 24 a | C32: Glass Work (M+L) | D32: 45593 | F32: =49825209.42+16265329.6-5674000 -> 60416539 | G32: 31460182 | H32: =G32*0.25 -> 7865045.5 | I32: =G32-H32 -> 23595136 | K32: =G32-H32-I32 -> 0 | S32: 6609053.9 | T32: 6609053.9 | V32: 8609053.9 | W32: 8609053.9 | X32: 8609053.9 | Y32: 5609053.9 | Z32: =I32+J32 -> 23595136
B33: 24 b | C33: Balcony Glass Railing (M+L) | D33: 45717 | F33: =10943856+5674000 -> 16617856 | G33: 5269856 | H33: =G33*0.25 -> 1317464 | I33: 5269856 | J33: 5674000 | S33: 2634500 | T33: 2634500 | V33: =2634500+3000000 -> 5634500 | W33: =3040356+2300000 -> 5340356 | Z33: =I33+J33 -> 10943856 | AB33: Partial -
B34: 25 | C34: Ceiling Work (M+L) | D34: 45592 | E34: 72011500 | F34: 42282623 | G34: =15235815*2+7700000 -> 38171630 | H34: =2762264+250800+2070000+903256+3392647 -> 9378967 | I34: =G34-H34 -> 28792663 | K34: =G34-H34-I34 -> 0 | L34: =D34 -> 45592 | M34: =1-G34/E34 -> 0.46992314 | T34: 6094326 | V34: 7094326 | W34: 7094326 | X34: =6094326+235206 -> 6329532 | Y34: 3967126 | Z34: =I34+J34 -> 28792663 | AA34: =Z34-V34-W34-X34-Y34 -> 4307353 | AB34: In progress
B35: 26 | C35: DISTRIBUTION BOARDS (M) | D35: 45592 | E35: 34752905 | F35: 34752905 | G35: 46267080 | H35: =23113540+2668858 -> 25782398 | I35: =G35-H35 -> 20484682 | K35: =G35-H35-I35 -> 0 | L35: =D35 -> 45592 | M35: =1-G35/E35 -> -0.33131547 | S35: 5900000 | T35: 8850000 | V35: 8850000 | W35: 8850000 | X35: =5900000-3115318 -> 2784682 | Z35: =I35+J35 -> 20484682 | AA35: =Z35-V35-W35-X35-Y35 -> 0
B36: 27 | C36: Paint (M+L) Internal | D36: 45629 | E36: =95688755-E37 -> 77163155 | F36: 60269252 | G36: =1234000*38.5 -> 47509000 | H36: 7761441 | I36: =G36-H36 -> 39747559 | K36: =G36-H36-I36 -> 0 | L36: =D36 -> 45629 | M36: =1-G36/E36 -> 0.38430459 | S36: 3611920 | T36: 7350000 | V36: 9850000 | W36: 9850000 | X36: 9850000 | Y36: 9850000 | Z36: =I36+J36 -> 39747559 | AB36: In progress
B37: 27 a | C37: Paint (M+L) External | D37: 45630 | E37: 18525600 | F37: 16000000 | G37: 9961998 | H37: 2490500 | I37: =G37-H37 -> 7471498 | K37: =G37-H37-I37 -> 0 | S37: 2490499.3 | T37: 2490499.3 | V37: 2490499.3 | W37: 4980998.7 | Z37: =I37+J37 -> 7471498 | AA37: =Z37-V37-W37-X37-Y37 -> 0
B38: 28 | C38: Tile ( M+L) | D38: 45539 | E38: =312133855-34256200 -> 277877655 | F38: 1.5472292e+08 | G38: =79817400+46500000+(65*411603) -> 153071595 | H38: =79817400+4206500+135000+3514951+54000+243000+302500+2000000+36677+360750+447090+247500+698500+721500+855625+909090+3827164+3769951+388220+384400 -> 102919818 | I38: =G38-H38 -> 50151777 | K38: =G38-H38-I38 -> 0 | L38: =D38 -> 45539 | M38: =1-G38/E38 -> 0.44914032 | S38: =4267588-360750-447090 -> 3459748 | T38: 13782539 | V38: 7782539 | W38: 15782539 | X38: 15782539 | Y38: 11173895 | Z38: =I38+J38 -> 50151777 | AA38: =Z38-V38-W38-X38-Y38 -> -369735
B39: 28 a | C39: Marble Work (M+L) | D39: 45962 | E39: 34256200 | F39: 29000000 | G39: =3150000+25165671 -> 28315671 | H39: 10066031 | I39: =G39-H39 -> 18249640 | K39: =G39-H39-I39 -> 0 | L39: =D39 -> 45962 | T39: 5249640 | V39: 7000000 | W39: 7000000 | X39: =5000000-750360 -> 4249640 | Z39: =I39+J39 -> 18249640 | AA39: =Z39-V39-W39-X39-Y39 -> 0 | AB39: Partial -
B40: 29 | C40: BUSWAYS (M) | D40: 45600 | E40: 60199030 | F40: 55750703 | G40: 46267080 | H40: 9773346 | I40: =G40-H40 -> 36493734 | K40: =G40-H40-I40 -> 0 | L40: =D40 -> 45600 | M40: =1-G40/E40 -> 0.23143147 | S40: 9773346 | T40: =16350000-9773346 -> 6576654 | W40: 16350000 | X40: 20143734 | Z40: =I40+J40 -> 36493734 | AA40: =Z40-V40-W40-X40-Y40 -> 0
B41: 30 | C41: Wood Works (M+L) | D41: 45600 | E41: =418623550-60118449 -> 358505101 | F41: 280680000 | G41: =200000000+651423+(2*4750000) -> 210151423 | H41: =17700866*2+4750000+17700866+13845314 -> 71697912 | I41: =G41-H41 -> 138453511 | J41: 15500000 | K41: =G41-H41-I41 -> 0 | L41: 45600 | M41: 1 | T41: 38519654 | V41: 38519654 | W41: 38519654 | X41: 38519654 | Y41: 38394550 | Z41: =I41+J41 -> 153953511 | AA41: =Z41-V41-W41-X41-Y41 -> 0 | AB41: In progress
B42: 30a | C42: Steel Works ( M+L) | D42: 45689 | E42: 27000000 | F42: 20000000 | I42: =G42-H42 -> 0 | J42: =F42 -> 20000000 | K42: =G42-H42-I42 -> 0 | S42: 5000000 | T42: 3500000 | V42: 8500000 | W42: 7000000 | X42: 3500000 | Y42: 1000000 | Z42: =I42+J42 -> 20000000 | AA42: =Z42-V42-W42-X42-Y42 -> 0
...

Sheet L1 Finishes
B2: Lakecity Roof Gardens - Projected Cash Flow (Structural & Finishes Works June 2025 to Jan 2026) | F2: L1 Finishes | W2: =TODAY() -> 46010
B3: S.No. | C3: Area | D3: Time line | E3: Consultant Budget NADA/SEMS | F3: Budget As per Initial Quotation Received | G3: Awarded Value | H3: Actual Spending | I3: Actual Balance Amount | J3: Pending approval | K3: 45722 | L3: 45810 | M3: 45873 | N3: 45905 | O3: 45936 | P3: 45967 | Q3: 46000 | R3: 46023 | S3: 46055 | T3: 46082 | U3: 46113 | V3: 46143 | W3: Remarks
B4: C | C4: Façade Works ( L 1 tower) | D4: 45566 | E4: 49636205 | F4: 40291143 | G4: 40291143 | H4: =1394227+10296700+2000000+1500000+3600000+1229846+13155658+2273160 -> 35449591 | I4: =G4-H4 -> 4841552 | M4: =I4 -> 4841552 | W4: In progress
B5: Finishes For Tower L 1
B6: 1 | C6: External Brick Works (M+L) | D6: 45536 | E6: 12735095 | F6: 9235361 | G6: 9235361 | H6: =3113135+82552+191097+2924289 -> 6311073 | I6: =G6-H6 -> 2924288 | J6: =F6-G6 -> 0 | M6: 2924288.5 | P6: =I6 -> 2924288 | W6: In progress
B7: 2 | C7: Internal Brick Works (M+L) | D7: 45566 | E7: 77560123 | F7: 67811217 | G7: 74421345 | H7: =151606+(139397*19.5)+470*1450+2960465+3202560+1345600+9176789+4798256+6203045+8512749+5467708+1500000+1269000+1480800+3288000+1557690+18500000 -> 72814010 | I7: =G7-H7 -> 1607335.5 | M7: 13318255 | N7: 7930808 | P7: =I7 -> 1607335.5 | W7: In progress
B8: 3 | C8: Electrical Conduiting (M+L) | D8: M-03/ 6 Month | E8: 26773680 | F8: 18313647 | G8: =4774150+402740+5130440+2760000 -> 13067330 | H8: =G8*0.1+1187577+326004+2453463*0.6 -> 4292391.8 | I8: =G8-H8 -> 8774938.2 | J8: =F8-G8 -> 5246317 | M8: 6104549.1 | N8: 6104549.1 | O8: 6104549.1 | P8: =I8/2+2600000 -> 6987469.1 | Q8: =P8 -> 6987469.1 | W8: Partial
B9: 4 | C9: Plumbing Conduiting (M+L) | D9: M-03/ 6 Month | E9: 21137725 | F9: 15669062 | G9: =3273209+410040+9175367 -> 12858616 | H9: =G9*0.1+218071+1629613+126698+8000+2159406+463839+828000+2453463*0.4 -> 7700873.8 | I9: =G9-H9 -> 5157742.2 | J9: =F9-G9 -> 2810446 | M9: 5223020.8 | N9: 5223020.8 | O9: 5223020.8 | P9: =I9/2+1400000 -> 3978871.1 | Q9: =P9 -> 3978871.1 | W9: Partial
B10: 5 | C10: SOIL, WASTE VENT AND RAIN WATER DRAINAGE SYSTEM (M) | D10: M-03/ 8 Month | E10: 55044200 | F10: 11666143 | G10: =F10 -> 11666143 | H10: =1264419+212935 -> 1477354 | I10: =G10-H10 -> 10188789 | J10: =F10-G10 -> 0 | M10: 1944357.2 | N10: 1944357.2 | O10: 1944357.2 | P10: 3944357.2 | Q10: 3944357.2 | R10: 1944357.2
B11: 6 | C11: PCC (M+L) | D11: M-04 | E11: 28000000 | F11: 21356000 | G11: 21356000 | H11: 11203560 | J11: =F11-G11 -> 0
B12: 7 | C12: External Plaster (M+L) | D12: M-05 | E12: 5851000 | F12: 5364800 | G12: 5364800 | H12: 1592000 | I12: =G12-H12 -> 3772800 | M12: 2185920 | N12: 1592600 | P12: =I12 -> 3772800
B13: 8 | C13: Internal Plaster (M+L) | D13: M-05 | E13: 45095450 | F13: 34785601 | G13: 34785601 | H13: =1860000+2504004 -> 4364004 | I13: =G13-H13 -> 30421597 | M13: =8696400.25-1860000 -> 6836400.2 | N13: 8696400.2 | O13: 8696400.2 | P13: 8696400.2 | Q13: 8696400.2 | R13: 8696400.2
B14: 10 | C14: Subcontract Electrical (L) | D14: M-06 | E14: 21992008 | F14: 14221499 | G14: =11030060+1848250 -> 12878310 | H14: =G14*0.1 -> 1287831 | I14: =G14-H14 -> 11590479 | M14: 643915.5 | N14: 643915.5 | O14: 1931746.5 | P14: 2575662 | Q14: 2575662 | R14: 3931746.5 | S14: 3287831
B15: 11 | C15: Subcontract Plumbing (L) | D15: M-06 | E15: 27128000 | F15: 17542773 | G15: 16256850 | H15: =G15*0.1+352371 -> 1978056 | I15: =G15-H15 -> 14278794 | M15: 793266.33 | N15: 793266.33 | O15: 2379799 | P15: 2379799 | Q15: 3379799 | R15: 3379799 | S15: 3379799 | T15: 1793266.3 | W15: In progress
B16: 12 | C16: CABLE CONTAINMENT (M) | D16: M-06 | E16: 11326915 | F16: 12130712 | G16: =F16 -> 12130712 | I16: =G16 -> 12130712 | J16: =F16-G16 -> 0
B17: 13 | C17: Subcontract Firefighting (L) | D17: M-06 | E17: 6947660 | F17: 4500000 | G17: 4293868 | I17: 4293868 | J17: =F17-G17 -> 206132
B18: 14 | C18: FSS Works (Piping) (M) | D18: M-06 | E18: 21654600 | F18: 14003308 | G18: =F18 -> 14003308 | I18: 11369213 | J18: =F18-G18 -> 0
B19: 15 | C19: Subcontract HVAC (M+L) | D19: M-06 | E19: 13159810 | F19: 8510010 | J19: =F19-G19 -> 8510010
B20: 16 | C20: Copper Pipe + Accessories (M+L) | D20: M-06 | E20: 21076800 | F20: 13629664 | G20: 14000000 | H20: =4200000+3295229 -> 7495229 | I20: =G20-H20 -> 6504771
B21: 17 | C21: LPG Works (M) | F21: 7500000 | G21: 4952283 | H21: =3380342+1111460 -> 4491802 | I21: =G21-H21 -> 460481 | J21: =F21-G21 -> 2547717 | M21: 1666666.7 | N21: 1666666.7 | O21: 1666666.7 | P21: 1250000 | Q21: 1250000 | W21: Partial
B22: 18 | C22: WIRING / WIRING ACCESSORIES (M) | D22: M-06 | E22: 50927366 | F22: 32933030 | J22: =F22-G22 -> 32933030
B23: 19 | C23: MAIN / SUB-MAIN CABLES (M) | D23: M-06 | E23: 22324236 | F23: 11436340 | J23: =F23-G23 -> 11436340
B24: 20 | C24: VOICE & DATA COMMUNICATION (M+L) | D24: M-06 | E24: 11332805 | F24: 22692700 | J24: =F24-G24 -> 22692700
B25: 21 | C25: Pipes for Water Supply and fitting (M) | D25: M-07 | E25: 14218500 | F25: 7469930 | J25: =F25-G25 -> 7469930
B26: 22 | C26: Elevator (M+L) | D26: M-07 | E26: 60712000 | F26: 44687500 | G26: 33292000 | H26: =4200000+600000 -> 4800000 | I26: =G26-H26 -> 28492000 | N26: 19065385 | Q26: 14226615
B27: 24 a | C27: Aluminum Work (M+L) | D27: M-08 | E27: 97040526 | F27: 91826667 | J27: =F27-G27 -> 91826667
B28: 24 b | C28: Glass Work (M+L)
B29: 24 b | C29: Balcony Glass (M+L)
B30: 25 | C30: Ceiling Work (M+L) | D30: M-08 | E30: 44903000 | F30: 31464928 | J30: =F30-G30 -> 31464928
B31: 26 | C31: DISTRIBUTION BOARDS (M) | D31: M-08 | E31: =23695163+7000000 -> 30695163 | F31: =19322872+7000000 -> 26322872 | J31: =F31-G31 -> 26322872
B32: 27 a | C32: Internal Paint (M+L) | D32: M-08 | E32: 58348355 | F32: =37731936-F33 -> 28494951 | J32: =F32-G32 -> 28494951
B33: 27 b | C33: External Paint | F33: 9236985 | G33: 8105205 | H33: 2026300 | I33: =G33-H33 -> 6078905 | O33: 2026301.7 | P33: 2026301.7 | Q33: 2026301.7
B34: 28 | C34: Tile (M+L) | D34: M-08 | E34: 201253640 | F34: 140144021 | J34: =F34-G34 -> 140144021
B35: 28 b | C35: Marble Works | J35: =F35-G35 -> 0
B36: 29 | C36: BUSWAYS (M) | D36: M-08 | E36: 38302485 | F36: 28768940 | J36: =F36-G36 -> 28768940
B37: 30 a | C37: Wood (M+L) | D37: M-09 | E37: 302206050 | F37: 195426579 | J37: =F37-G37 -> 195426579
B38: 30 b | C38: Steel Work (M+L) | J38: =F38-G38 -> 0
B39: 31 | C39: Dry Type Transformers (M) | D39: M-09 | E39: =26853260-7000000 -> 19853260 | F39: =19365108-7000000 -> 12365108 | G39: =9950000*1.18 -> 11741000 | H39: =G39*0.5 -> 5870500 | I39: =G39-H39 -> 5870500 | Q39: 5870500 | R39: 5870500
B40: 32 | C40: DIESEL GENERATOR & ALLIED WORKS (M+L) | D40: M-09 | E40: 1.0506634e+08 | F40: 67942901 | J40: =F40-G40 -> 67942901
B41: 33 | C41: Chute (M+L) | D41: M-09 | E41: 4000000 | F41: 4000000 | J41: =F41-G41 -> 4000000
...

Sheet L2 Finishes
B2: Lakecity Roof Gardens - Projected Cash Flow (Structural & Finishes Works June 2025 to Jan 2026) | F2: L2 Finishes | Y2: =TODAY() -> 46010
B3: S.No | C3: Area | D3: Plan Start Month/Duration | E3: NADA/SEMs Budget | F3: First Quotation Received | G3: Awarded Value | H3: Actual Spending | I3: Actual Balance Amount | J3: Pending approval | K3: 45810 | L3: 45873 | M3: 45905 | N3: 45937 | O3: 45969 | P3: 46001 | Q3: 46033 | R3: 46065 | S3: 46097 | T3: 46129 | U3: 46161 | V3: 46193 | W3: 46194 | X3: 46226 | Y3: =TODAY() -> 46010
B4: C | C4: Façade Works ( L 2 tower) | D4: 45748 | E4: 49636205 | F4: 49134722 | G4: =26076554+25500000-3242095 -> 48334459 | H4: =13268250+2400000+6214336+3197000+138159+339801+6603058+12000000 -> 44160604 | I4: =G4-H4 -> 4173855 | O4: 4550108
B5: Finishes For Tower L 2
B6: 1 | C6: External Brick Works (M+L) | D6: 45536 | E6: 12735095 | F6: 9235361 | G6: 9308278 | H6: 8200000 | I6: =G6-H6 -> 1108278 | O6: 1108278
B7: 2 | C7: Internal Brick Works (M+L) | D7: 45566 | E7: 77560123 | F7: 67811217 | G7: 74421345 | H7: 6852212 | I7: =G7-H7 -> 67569133 | O7: 13550108 | P7: 13550108 | Q7: 13550108 | R7: 13550108 | S7: 13550108
B8: 3 | C8: Electrical Conduiting (M+L) | D8: M-03/ 6 Month | E8: 26773680 | F8: 18313647 | G8: =F8*0.45 -> 8241141.2 | I8: =G8 -> 8241141.2 | J8: =F8-G8 -> 10072506 | O8: 3102759.3 | P8: 3102759.3 | Q8: 3102759.3 | S8: =R8/6 -> 0
B9: 4 | C9: Plumbing Conduiting (M+L) | D9: M-03/ 6 Month | E9: 21137725 | F9: 15669062 | G9: =F9*0.45 -> 7051077.9 | I9: =G9 -> 7051077.9 | J9: =F9-G9 -> 8617984.1 | O9: =G9/3 -> 2350359.3 | P9: 2350359.3 | Q9: 2350359.3 | S9: =R9/6 -> 0
B10: 5 | C10: SOIL, WASTE VENT AND RAIN WATER DRAINAGE SYSTEM (M) | D10: M-03/ 8 Month | E10: 55044200 | F10: 11666143 | G10: 11666143 | I10: =G10 -> 11666143 | O10: 2333229 | P10: 2333229 | Q10: 2333229 | R10: 2333229 | S10: 2333229
B11: 6 | C11: PCC (M+L) | D11: M-04 | E11: 28000000 | F11: 21356000 | J11: =F11 -> 21356000
B12: 7 | C12: External Plaster (M+L) | D12: M-05 | E12: 5851000 | F12: 5364800 | G12: 5364800 | H12: =2163265+2064324 -> 4227589 | I12: =G12-H12 -> 1137211 | O12: =I12 -> 1137211 | S12: =R12/6 -> 0
B13: 8 | C13: Internal Plaster (M+L) | D13: M-05 | E13: 45095450 | F13: 34785601 | G13: 34785601 | I13: =G13-H13 -> 34785601 | P13: =I13/5 -> 6957120.2 | Q13: =P13 -> 6957120.2 | R13: =Q13 -> 6957120.2 | S13: =R13 -> 6957120.2 | T13: =S13 -> 6957120.2
B14: 10 | C14: Subcontract Electrical (L) | D14: M-06 | E14: 21992008 | F14: 14221499 | G14: =F14*0.45 -> 6399674.5 | I14: =G14-H14 -> 6399674.5 | J14: =F14-G14 -> 7821824.5 | O14: =J14/3 -> 2607274.8 | P14: 2607274.8 | Q14: 2607274.8 | R14: 2607274.8 | S14: 2607274.8 | T14: 1607274.8
B15: 11 | C15: Subcontract Plumbing (L) | D15: M-06 | E15: 27128000 | F15: 17542773 | G15: =F15*0.45 -> 7894247.9 | I15: =G15-H15 -> 7894247.9 | J15: =F15-G15 -> 9648525.1 | O15: =J15/3 -> 3216175 | P15: 3216175 | Q15: 3216175 | R15: 3216175 | S15: 3216175 | T15: 3216175
B16: 12 | C16: CABLE CONTAINMENT (M) | D16: M-06 | E16: 11326915 | F16: 12130712 | J16: =F16 -> 12130712 | S16: =R16/6 -> 0
B17: 13 | C17: Subcontract Firefighting (L) | D17: M-06 | E17: 6947660 | F17: 4500000 | J17: =F17 -> 4500000 | S17: =R17/6 -> 0
B18: 14 | C18: FSS Works (Piping) (M) | D18: M-06 | E18: 21654600 | F18: 14003308 | J18: =F18 -> 14003308 | S18: =R18/6 -> 0
B19: 15 | C19: Subcontract HVAC (M+L) | D19: M-06 | E19: 13159810 | F19: 8510010 | J19: =F19 -> 8510010 | S19: =R19/6 -> 0
B20: 16 | C20: Copper Pipe + Accessories (M+L) | D20: M-06 | E20: 21076800 | F20: 13629664 | J20: =F20 -> 13629664 | S20: =R20/6 -> 0
B21: 17 | C21: LPG Works (M) | F21: 7500000 | J21: =F21 -> 7500000 | S21: =R21/6 -> 0
B22: 18 | C22: WIRING / WIRING ACCESSORIES (M) | D22: M-06 | E22: 50927366 | F22: 32933030 | J22: =F22 -> 32933030 | S22: =R22/6 -> 0
B23: 19 | C23: MAIN / SUB-MAIN CABLES (M) | D23: M-06 | E23: 22324236 | F23: 11436340 | J23: =F23 -> 11436340 | S23: =R23/6 -> 0
B24: 20 | C24: VOICE & DATA COMMUNICATION (M+L) | D24: M-06 | E24: 11332805 | F24: 22692700 | J24: =F24 -> 22692700 | S24: =R24/6 -> 0
B25: 21 | C25: Pipes for Water Supply and fitting (M) | D25: M-07 | E25: 14218500 | F25: 7469930 | J25: =F25 -> 7469930 | S25: =R25/6 -> 0
B26: 22 | C26: Elevator (M+L) | D26: M-07 | E26: 60712000 | F26: 44687500 | G26: 33292000 | I26: =G26-H26 -> 33292000 | O26: 13224000 | Q26: 11934000 | R26: 7934000
B27: 24 a | C27: Aluminum Work (M+L) | D27: M-08 | E27: 97040526 | F27: 91826667 | J27: =F27 -> 91826667 | S27: =R27/6 -> 0
B28: 24 b | C28: Glass Work (M+L) | J28: =F28 -> 0 | S28: =R28/6 -> 0
B29: 24 b | C29: Balcony Glass (M+L) | J29: =F29 -> 0 | S29: =R29/6 -> 0
B30: 25 | C30: Ceiling Work (M+L) | D30: M-08 | E30: 44903000 | F30: 31464928 | J30: =F30 -> 31464928 | S30: =R30/6 -> 0
B31: 26 | C31: DISTRIBUTION BOARDS (M) | D31: M-08 | E31: 33695162 | F31: =23695163+7000000 -> 30695163 | J31: =F31-G31 -> 30695163 | S31: =R31/6 -> 0
B32: 27 a | C32: Internal Paint (M+L) | D32: M-08 | E32: 58348355 | F32: =37731936-F33 -> 28494951 | J32: =F32 -> 28494951 | S32: =R32/6 -> 0
B33: 27 b | C33: External Paint | F33: 9236985 | G33: 8105205 | H33: 2026300 | I33: =G33-H33 -> 6078905 | P33: 2026301.7 | Q33: 2026301.7 | R33: 2026301.7
B34: 28 | C34: Tile (M+L) | D34: M-08 | E34: 201253640 | F34: 140144021 | J34: =F34 -> 140144021 | S34: =R34/6 -> 0
B35: 28 b | C35: Marble Works | J35: =F35 -> 0 | S35: =R35/6 -> 0
B36: 29 | C36: BUSWAYS (M) | D36: M-08 | E36: 38302485 | F36: 28768940 | J36: =F36 -> 28768940 | S36: =R36/6 -> 0
B37: 30 a | C37: Wood (M+L) | D37: M-09 | E37: 302206050 | F37: 195426579 | J37: =F37 -> 195426579 | S37: =R37/6 -> 0
B38: 30 b | C38: Steel Work (M+L) | J38: =F38 -> 0 | S38: =R38/6 -> 0
B39: 31 | C39: Dry Type Transformers (M) | D39: M-09 | E39: =26853260-7000000 -> 19853260 | F39: =19365108-7000000 -> 12365108 | G39: =9950000*1.18 -> 11741000 | H39: =G39*0.5 -> 5870500 | I39: =G39-H39 -> 5870500 | R39: 5870500
B40: 32 | C40: DIESEL GENERATOR & ALLIED WORKS (M+L) | D40: M-09 | E40: 1.0506634e+08 | F40: 67942901 | J40: =F40 -> 67942901 | S40: =R40/6 -> 0
B41: 33 | C41: Chute (M+L) | D41: M-09 | E41: 4000000 | F41: 4000000 | J41: =F41 -> 4000000 | S41: =R41/6 -> 0
...

Sheet Ground Floor
B3: Ground floor
B4: S.No | C4: Area | D4: Plan Start Month/Duration | E4: NADA/SEMs Budget | F4: Consultant Budget NADA/SEMS | G4: First Quotation Received | H4: Awarded Value | I4: Actual Spending | J4: Actual Balance Amount | K4: Pending approval
B5: 1 | C5: Electrical Work | D5: not finalize yet | E5: Yet to finalize | G5: 11820919 | H5: 6220700 | I5: 2762019 | J5: 3458681
B6: 2 | C6: Plumbing work | D6: not finalize yet | E6: Yet to finalize | G6: 9924504.8 | H6: 9428921 | I6: 5928921 | J6: 3500000
B7: 3 | C7: Fire fighting works | D7: not finalize yet | E7: Yet to finalize | G7: 5240700 | H7: 2868500 | I7: 1241083 | J7: 1627417
B8: 4 | C8: Copper piping | D8: not finalize yet | E8: Yet to finalize | G8: 21498750 | H8: 1900000 | J8: 1900000
B9: 5 | C9: Insulation of pipes | D9: not finalize yet | E9: Yet to finalize | G9: 1755000 | H9: 3141525 | I9: 2054018 | J9: 1087507
B10: 6 | C10: Marble | D10: not finalize yet | E10: Yet to finalize | G10: 6750000 | H10: 12834922 | I10: 5133968.8 | J10: 7700953.2
B11: 7 | C11: Aluminum Work (M+L) | D11: not finalize yet | E11: Yet to finalize | G11: 10800000 | H11: 15000000 | K11: =H11 -> 15000000
B12: 8 | C12: Total Lobby | D12: not finalize yet | E12: Yet to finalize | G12: =SUM(G5:G11) -> 67789873 | H12: =SUM(H5:H11) -> 51394568 | I12: =SUM(I5:I11) -> 17120010 | J12: =SUM(J5:J11) -> 19274558 | K12: =SUM(K5:K11) -> 15000000
B13: 10 | C13: Gym Equipment | D13: not finalize yet | E13: Yet to finalize | G13: 36000000 | H13: 36000000 | I13: 27000000 | J13: =H13-I13 -> 9000000
B14: 11 | C14: Gym | D14: not finalize yet | E14: Yet to finalize | G14: 18000000 | H14: 16999424 | I14: =H14*0.25 -> 4249856 | J14: =H14 -> 16999424
B15: 12 | C15: Business Center | D15: not finalize yet | E15: Yet to finalize | G15: 6500000 | H15: 5916720 | I15: =H15*0.25 -> 1479180 | J15: =H15 -> 5916720
B16: 13 | C16: Game Room | D16: not finalize yet | E16: Yet to finalize | G16: 8600000 | H16: 8350094 | I16: =H16*0.25 -> 2087523.5 | J16: =H16 -> 8350094
B17: 15 | C17: MEP Work | D17: not finalize yet | E17: Yet to finalize | G17: 5600000 | H17: 4000000 | K17: =H17 -> 4000000
B18: 16 | C18: Total Remaining | D18: not finalize yet | E18: Yet to finalize | G18: =SUM(G13:G17) -> 74700000 | H18: =SUM(H13:H17) -> 71266238 | I18: =SUM(I13:I17) -> 34816560 | J18: =SUM(J13:J17) -> 40266238 | K18: =SUM(K13:K17) -> 4000000
C19: Additional Items
B20: 17 | C20: Acs | G20: 13000000 | K20: =G20 -> 13000000
B21: 18 | C21: Furniture | G21: 15000000 | K21: =G21 -> 15000000
C23: Grand Total | G23: =G18+G12+G20+G21 -> 1.7048987e+08 | H23: =H18+H12+H20+H21 -> 122660806 | I23: =I18+I12+I20+I21 -> 51936569 | J23: =J18+J12+J20+J21 -> 59540796 | K23: =K18+K12+K20+K21 -> 47000000

Sheet Court Yard
B3: Court Yard Related
B4: S.No | C4: Area | D4: Plan Start Month/Duration | E4: NADA/SEMs Budget | F4: First Quotation Received | G4: Awarded Value | H4: Actual Spending | I4: Actual Balance Amount | J4: Pending approval | K4: If Contract finalize by 20.06.2025
B5: 1 | C5: Sewerage System ( Main holes system) | D5: not finalize yet | F5: 18000000 | G5: 18000000 | H5: 13000000 | I5: =G5-H5 -> 5000000
B6: 2 | C6: Boundary Wall | D6: not finalize yet | F6: 7351485 | G6: 7351485 | H6: 5000000 | I6: =G6-H6 -> 2351485
B7: 3 | C7: Boundary Wall Paint | D7: not finalize yet | F7: 1782000 | G7: 1782000 | H7: =F7 -> 1782000 | J7: 1782000
B8: 4 | C8: Boundary Wall Louvers | D8: not finalize yet | F8: =1750*9100 -> 15925000 | G8: =1750*9100 -> 15925000 | H8: =G8*0.4 -> 6370000 | I8: =G8-H8 -> 9555000
B9: 5 | C9: Electrical Works ( Main hole System) | D9: not finalize yet | F9: 1300000 | G9: 1300000 | H9: =F9-G9 -> 0 | I9: =G9-H9 -> 1300000
B10: 6 | C10: Road Base Structure | D10: not finalize yet | F10: 5000000 | G10: 5000000 | H10: =F10 -> 5000000
B11: 7 | C11: Fire Fighting System (Base Network) | D11: not finalize yet | F11: 8000000 | G11: 8000000 | H11: 5500000 | I11: =G11-H11 -> 2500000
B12: 8 | C12: External Drain channel | D12: not finalize yet | F12: 3200000 | J12: 3200000
B13: 10 | C13: Re-charge pit | D13: not finalize yet | F13: 3500000 | J13: 3500000
B14: 11 | C14: PCC.+Drain | D14: not finalize yet | F14: =11500000+1000000+(45000*45)+5400000 -> 19925000 | G14: =11500000+1000000+(45000*45)+5400000 -> 19925000 | H14: =F14*0.35 -> 6973750 | I14: =G14-H14 -> 12951250 | K14: 38000 Sft.Wtaer proofing+Filling
B15: 12 | C15: Street Poles Lamp foundation | D15: not finalize yet | K15: Removed
B16: 13 | C16: Internal Drain Channels | D16: not finalize yet | F16: 2500000 | J16: 2500000
B17: 15 | C17: Paver system | D17: not finalize yet | F17: 36000000 | G17: 36000000 | H17: =13500000 -> 13500000 | I17: =G17-H17 -> 22500000 | K17: 108000 Sft Pavers
B18: 16 | C18: Plantations+Benches+ | D18: not finalize yet
B19: 18 | C19: Steps | D19: not finalize yet | F19: 3500000 | J19: 3500000
B20: 19 | C20: Fountain tile works | D20: not finalize yet | F20: =725*2000 -> 1450000 | J20: =725*2000 -> 1450000
C22: Grand Total | F22: =SUM(F5:F21) -> 127433485 | G22: =SUM(G5:G21) -> 113283485 | H22: =SUM(H5:H21) -> 57125750 | I22: =SUM(I5:I21) -> 56157735 | J22: =SUM(J5:J21) -> 15932000
F24: =SUM(F5:F23) -> 254866970 | G24: =SUM(G5:G23) -> 226566970 | H24: =SUM(H5:H23) -> 114251500 | I24: =SUM(I5:I23) -> 112315470

Sheet Approved Item-Actual
A2: Lakecity Roof Gardens - Projected Cash Flow | C2: Approved Item Only | N2: =TODAY() -> 46010 | R2: =TODAY() -> 46010 | X2: =TODAY() -> 46010
A3: (Structural & Finishes Works Jun 2024 to Jan 2026)
A4: S.No. | B4: Cash Flow | C4: Awarded Value | D4: Actual Spending | E4: Balance Amount | F4: Jun-25 | G4: Nov-25 | H4: 46016 | I4: 46047 | J4: 46078 | K4: 46106 | L4: 46137 | M4: 46167
A5: A1 | B5: Structure for I Tower | F5: ='Summary I Tower'!S5 -> 0 | G5: 10000000
A6: A2 | B6: Structure for L1 Tower | F6: ='Summary L1 Tower'!#REF! -> #REF!
A7: A3 | B7: Structure Works for L2
A8: A4 | B8: Façade Works ( I tower) | G8: 5350498
A9: A5 | B9: Façade Works ( L 1 tower) | F9: ='L1 Finishes'!L4 -> 0 | G9: ='L1 Finishes'!M4 -> 4841552 | H9: ='L1 Finishes'!N4 -> 0 | I9: ='L1 Finishes'!O4 -> 0
A10: A6 | B10: Façade Works ( L 2 tower) | F10: ='L2 Finishes'!K4 -> 0 | G10: ='L2 Finishes'!L4 -> 0 | H10: ='L2 Finishes'!M4 -> 0 | I10: ='L2 Finishes'!N4 -> 0
B11: Total | F11: =SUM(F5:F10) -> #REF! | G11: =SUM(G5:G10) -> 20192050 | H11: =SUM(H5:H10) -> 0 | I11: =SUM(I5:I10) -> 0
B12: Finishes For Tower 1
A13: 1 | B13: ='I Finishes'!C8 -> External Brick Works (M+L) | C13: ='I Finishes'!G8 -> 14500000 | D13: ='I Finishes'!H8 -> 14500000 | E13: ='I Finishes'!I8 -> 0 | G13: ='I Finishes'!S8 -> 0 | M13: =C13-D13-E13 -> 0
A14: 2 | B14: ='I Finishes'!C9 -> Internal Brick Works (M+L) | C14: ='I Finishes'!G9 -> 92385014 | D14: ='I Finishes'!H9 -> 93066444 | E14: ='I Finishes'!I9 -> -681430 | G14: ='I Finishes'!S9 -> 0 | M14: =C14-D14-E14 -> 0
A15: 3 | B15: ='I Finishes'!C10 -> Electrical Conduiting (M+L) | C15: ='I Finishes'!G10 -> 29485630 | D15: ='I Finishes'!H10 -> 28472773 | E15: ='I Finishes'!I10 -> 1012856.6 | G15: ='I Finishes'!V10 -> 1012856.6 | H15: ='I Finishes'!W10 -> 0 | I15: ='I Finishes'!X10 -> 0 | J15: ='I Finishes'!Y10 -> 0 | M15: =C15-D15-E15 -> 0 | N15: =E15-G15-H15-I15-J15-K15 -> 0
A16: 4 | B16: ='I Finishes'!C11 -> Plumbing Conduiting (M+L) | C16: ='I Finishes'!G11 -> 23645601 | D16: ='I Finishes'!H11 -> 21009948 | E16: ='I Finishes'!I11 -> 2635653 | G16: ='I Finishes'!V11 -> 2635653 | H16: ='I Finishes'!W11 -> 0 | I16: ='I Finishes'!X11 -> 0 | J16: ='I Finishes'!Y11 -> 0 | M16: =C16-D16-E16 -> 0 | N16: =E16-G16-H16-I16-J16-K16 -> 0
A17: 5 | B17: ='I Finishes'!C12 -> SOIL, WASTE VENT AND RAIN WATER DRAINAGE SYSTEM (M) | C17: ='I Finishes'!G12 -> 19367707 | D17: ='I Finishes'!H12 -> 19362936 | E17: ='I Finishes'!I12 -> 4771 | G17: ='I Finishes'!V12 -> 4771 | H17: ='I Finishes'!W12 -> 0 | I17: ='I Finishes'!X12 -> 0 | J17: ='I Finishes'!Y12 -> 0 | M17: =C17-D17-E17 -> 0 | N17: =E17-G17-H17-I17-J17-K17 -> 0
A18: 6 | B18: ='I Finishes'!C13 -> PCC (M+L) | C18: ='I Finishes'!G13 -> 27569921 | D18: ='I Finishes'!H13 -> 26661230 | E18: ='I Finishes'!I13 -> 908691 | G18: ='I Finishes'!V13 -> 908691 | H18: ='I Finishes'!W13 -> 0 | I18: ='I Finishes'!X13 -> 0 | J18: ='I Finishes'!Y13 -> 0 | M18: =C18-D18-E18 -> 0 | N18: =E18-G18-H18-I18-J18-K18 -> 0
A19: 7 | B19: ='I Finishes'!C14 -> External Plaster (M+L) | C19: ='I Finishes'!G14 -> 6841856 | D19: ='I Finishes'!H14 -> 3712137 | E19: ='I Finishes'!I14 -> 3129719 | G19: ='I Finishes'!V14 -> 3129719 | H19: ='I Finishes'!W14 -> 0 | I19: ='I Finishes'!X14 -> 0 | J19: ='I Finishes'!Y14 -> 0 | M19: =C19-D19-E19 -> 0 | N19: =E19-G19-H19-I19-J19-K19 -> 0
A20: 8 | B20: ='I Finishes'!C15 -> Internal Plaster (M+L) | C20: ='I Finishes'!G15 -> 57158144 | D20: ='I Finishes'!H15 -> 44216742 | E20: ='I Finishes'!I15 -> 12941402 | G20: ='I Finishes'!V15 -> 6470701 | H20: ='I Finishes'!W15 -> 6470701 | I20: ='I Finishes'!X15 -> 0 | J20: ='I Finishes'!Y15 -> 0 | M20: =C20-D20-E20 -> 0
A21: 9 | B21: ='I Finishes'!C16 -> Boundary Wall (M+L) | C21: ='I Finishes'!G16 -> 25545140 | D21: ='I Finishes'!H16 -> 23545140 | E21: ='I Finishes'!I16 -> 2000000 | G21: ='I Finishes'!V16 -> 2000000 | H21: ='I Finishes'!W16 -> 0 | I21: ='I Finishes'!X16 -> 0 | J21: ='I Finishes'!Y16 -> 0 | M21: =C21-D21-E21 -> 0
A22: 10 | B22: ='I Finishes'!C17 -> Subcontract Electrical (L) | C22: ='I Finishes'!G17 -> 21095340 | D22: ='I Finishes'!H17 -> 5900615.5 | E22: ='I Finishes'!I17 -> 15194724 | G22: ='I Finishes'!V17 -> 3475516.2 | H22: ='I Finishes'!W17 -> 4475516.2 | I22: ='I Finishes'!X17 -> 5258330.2 | J22: ='I Finishes'!Y17 -> 1985362 | M22: =C22-D22-E22 -> 0
A23: 11 | B23: ='I Finishes'!C18 -> Subcontract Plumbing (L) | C23: ='I Finishes'!G18 -> 25674500 | D23: ='I Finishes'!H18 -> 10860374 | E23: ='I Finishes'!I18 -> 14814126 | G23: ='I Finishes'!V18 -> 3219511.5 | H23: ='I Finishes'!W18 -> 5219511.5 | I23: ='I Finishes'!X18 -> 5219511.5 | J23: ='I Finishes'!Y18 -> 1155591.1 | M23: =C23-D23-E23 -> 0
A24: 12 | B24: ='I Finishes'!C19 -> CABLE CONTAINMENT (M) | C24: ='I Finishes'!G19 -> 19470000 | D24: ='I Finishes'!H19 -> 16502692 | E24: =C24-D24 -> 2967308 | G24: ='I Finishes'!V19 -> 0 | H24: ='I Finishes'!W19 -> 0 | I24: ='I Finishes'!X19 -> 0 | J24: ='I Finishes'!Y19 -> 0 | M24: =C24-D24-E24 -> 0
A25: 13 | B25: ='I Finishes'!C20 -> Subcontract Firefighting (L) | C25: ='I Finishes'!G20 -> 5000000 | D25: ='I Finishes'!H20 -> 3898568 | E25: ='I Finishes'!I20 -> 1101432 | G25: ='I Finishes'!V20 -> 0 | H25: ='I Finishes'!W20 -> 1101432 | I25: ='I Finishes'!X20 -> 0 | J25: ='I Finishes'!Y20 -> 0 | M25: =C25-D25-E25 -> 0
A26: 14 | B26: ='I Finishes'!C21 -> FSS Works (Piping) (M) | C26: ='I Finishes'!G21 -> 18686350 | D26: ='I Finishes'!H21 -> 15616841 | E26: ='I Finishes'!I21 -> 3069509 | G26: ='I Finishes'!V21 -> 3451813 | H26: ='I Finishes'!W21 -> 0 | I26: ='I Finishes'!X21 -> 0 | J26: ='I Finishes'!Y21 -> 0 | M26: =C26-D26-E26 -> 0
A27: 15 | B27: ='I Finishes'!C22 -> Subcontract HVAC (M+L) | C27: ='I Finishes'!G22 -> 11000000 | D27: ='I Finishes'!H22 -> 7206637 | E27: ='I Finishes'!I22 -> 3793363 | G27: ='I Finishes'!V22 -> 1921400 | H27: ='I Finishes'!W22 -> 1871963 | I27: ='I Finishes'!X22 -> 0 | J27: ='I Finishes'!Y22 -> 0 | M27: =C27-D27-E27 -> 0
A28: 16 | B28: ='I Finishes'!C23 -> Copper Pipe + Accessories (M+L) | C28: ='I Finishes'!G23 -> 20000000 | D28: ='I Finishes'!H23 -> 17529297 | E28: ='I Finishes'!I23 -> 2470703 | G28: ='I Finishes'!V23 -> 2900000 | H28: ='I Finishes'!W23 -> 1418948 | I28: ='I Finishes'!X23 -> 0 | J28: ='I Finishes'!Y23 -> 0 | M28: =C28-D28-E28 -> 0
A29: 17 | B29: ='I Finishes'!C24 -> LPG Works (M) | C29: ='I Finishes'!G24 -> 6500000 | D29: ='I Finishes'!H24 -> 4047317 | E29: ='I Finishes'!I24 -> 2452683 | H29: 2452683 | I29: ='I Finishes'!X24 -> 0 | J29: ='I Finishes'!Y24 -> 0 | M29: =C29-D29-E29 -> 0
A30: 18 | B30: ='I Finishes'!C25 -> WIRING / WIRING ACCESSORIES (M) | C30: ='I Finishes'!G25 -> 45147657 | D30: ='I Finishes'!H25 -> 44465807 | E30: ='I Finishes'!I25 -> 681850.2 | G30: ='I Finishes'!V25 -> 681850.2 | H30: ='I Finishes'!W25 -> 0 | I30: ='I Finishes'!X25 -> 0 | J30: ='I Finishes'!Y25 -> 0 | M30: =C30-D30-E30 -> 0
A31: 19 | B31: ='I Finishes'!C26 -> MAIN / SUB-MAIN CABLES (M) | C31: ='I Finishes'!G26 -> 17180375 | D31: ='I Finishes'!H26 -> 16973827 | E31: ='I Finishes'!I26 -> 206547.8 | G31: ='I Finishes'!V26 -> 206547.8 | H31: ='I Finishes'!W26 -> 0 | I31: ='I Finishes'!X26 -> 0 | J31: ='I Finishes'!Y26 -> 0 | M31: =C31-D31-E31 -> 0
A32: 20 | B32: ='I Finishes'!C27 -> VOICE & DATA COMMUNICATION (M+L) | C32: ='I Finishes'!G27 -> 5537660 | D32: ='I Finishes'!H27 -> 4688280 | E32: ='I Finishes'!I27 -> 849380 | H32: 849380 | I32: ='I Finishes'!X27 -> 0 | J32: ='I Finishes'!Y27 -> 0 | M32: =C32-D32-E32 -> 0
A33: 21 | B33: ='I Finishes'!C28 -> Pipes for Water Supply and fitting (M) | C33: ='I Finishes'!G28 -> 13000000 | D33: ='I Finishes'!H28 -> 12212833 | E33: ='I Finishes'!I28 -> 787167.4 | G33: ='I Finishes'!V28 -> 0 | H33: ='I Finishes'!W28 -> 787167.4 | I33: ='I Finishes'!X28 -> 0 | J33: ='I Finishes'!Y28 -> 0 | M33: =C33-D33-E33 -> 0
A34: 22 | B34: ='I Finishes'!C29 -> Elevator (M+L) | C34: ='I Finishes'!G29 -> 49036000 | D34: ='I Finishes'!H29 -> 17800000 | E34: ='I Finishes'!I29 -> 31236000 | G34: ='I Finishes'!V29 -> 26004500 | H34: ='I Finishes'!W29 -> 5231500 | I34: ='I Finishes'!X29 -> 0 | J34: ='I Finishes'!Y29 -> 0 | M34: =C34-D34-E34 -> 0
A35: 23 | B35: ='I Finishes'!C30 -> BORE WELL WATER SUPPLY SYSTEM (M+L) | C35: ='I Finishes'!G30 -> 0 | D35: ='I Finishes'!H30 -> 0 | E35: ='I Finishes'!I30 -> 0 | G35: ='I Finishes'!V30 -> 6174790 | H35: ='I Finishes'!W30 -> 6174790 | I35: ='I Finishes'!X30 -> 0 | J35: ='I Finishes'!Y30 -> 0 | M35: =C35-D35-E35 -> 0
A36: 24 | B36: ='I Finishes'!C31 -> Aluminum Work (M+L) | C36: ='I Finishes'!G31 -> 68331343 | D36: ='I Finishes'!H31 -> 31452514 | E36: ='I Finishes'!I31 -> 36878829 | H36: ='I Finishes'!W31 -> 17000000 | I36: 12000000 | J36: ='I Finishes'!Y31 -> 8248507 | M36: =C36-D36-E36 -> 0
A37: 24 a | B37: ='I Finishes'!C32 -> Glass Work (M+L) | C37: ='I Finishes'!G32 -> 31460182 | D37: ='I Finishes'!H32 -> 7865045.5 | E37: ='I Finishes'!I32 -> 23595136 | G37: ='I Finishes'!V32 -> 8609053.9 | H37: ='I Finishes'!W32 -> 8609053.9 | I37: ='I Finishes'!X32 -> 8609053.9 | J37: ='I Finishes'!Y32+23966 -> 5633019.9 | M37: =C37-D37-E37 -> 0
A38: 24 b | B38: ='I Finishes'!C33 -> Balcony Glass Railing (M+L) | C38: 5269856 | D38: ='I Finishes'!H33 -> 1317464 | E38: ='I Finishes'!I33 -> 5269856 | H38: 5269856 | I38: ='I Finishes'!X33 -> 0 | J38: ='I Finishes'!Y33 -> 0 | M38: =C38-D38-E38 -> -1317464
A39: 25 | B39: ='I Finishes'!C34 -> Ceiling Work (M+L) | C39: ='I Finishes'!G34 -> 38171630 | D39: ='I Finishes'!H34 -> 9378967 | E39: ='I Finishes'!I34 -> 28792663 | G39: ='I Finishes'!V34 -> 7094326 | H39: ='I Finishes'!W34 -> 7094326 | I39: ='I Finishes'!X34 -> 6329532 | J39: ='I Finishes'!Y34 -> 3967126 | M39: =C39-D39-E39 -> 0
A40: 26 | B40: ='I Finishes'!C35 -> DISTRIBUTION BOARDS (M) | C40: ='I Finishes'!G35 -> 46267080 | D40: ='I Finishes'!H35 -> 25782398 | E40: ='I Finishes'!I35 -> 20484682 | G40: ='I Finishes'!V35 -> 8850000 | H40: ='I Finishes'!W35 -> 8850000 | I40: ='I Finishes'!X35 -> 2784682 | J40: ='I Finishes'!Y35 -> 0 | M40: =C40-D40-E40 -> 0 | N40: =E40-G40-H40-I40-J40-K40 -> 0
A41: 27 | B41: ='I Finishes'!C36 -> Paint (M+L) Internal | C41: ='I Finishes'!G36 -> 47509000 | D41: ='I Finishes'!H36 -> 7761441 | E41: ='I Finishes'!I36 -> 39747559 | G41: ='I Finishes'!V36 -> 9850000 | H41: ='I Finishes'!W36 -> 9850000 | I41: ='I Finishes'!X36 -> 9850000 | J41: ='I Finishes'!Y36+347559 -> 10197559 | M41: =C41-D41-E41 -> 0 | N41: =E41-G41-H41-I41-J41-K41 -> 0
...

Sheet Table 1
A1: Lake City Roof Gardens Project Tracking Sheet ( On going ) | N1: =TODAY() -> 46010
A2: Sr. No. | B2: Activity | C2: Resposible Contractor | D2: Approved Budget | E2: Consumed Budget | F2: Consumed Busget % | G2: Duration Months | H2: Planned Start Date | I2: Planned Finish Date | J2: Effective Finish Date | K2: Actual Finish Date | L2: Planned % | M2: Current Status % | N2: Remarks | R2: =TODAY() -> 46010 | X2: =TODAY() -> 46010
A4: Structure Work
A5: 2 | B5: Mumty, Generator Pad, Swimming Pool | C5: ICPL/GE | H5: 45703 | I5: 45792 | J5: 45792 | L5: 1 | M5: 0.96
A6: Finishes of I-Tower
A7: 0 | B7: External Brick Works (M+L) | C7: GE | D7: ='Approved Item-Actual'!C13 -> 14500000 | E7: ='Approved Item-Actual'!D13 -> 14500000 | F7: =E7/D7 -> 1 | G7: 4 | H7: 45311 | I7: =H7+(30*3) -> 45401 | J7: 45491 | L7: 1 | M7: 1
A8: 0 | B8: Internal Brick Works (M+L) | C8: GE | D8: ='Approved Item-Actual'!C14 -> 92385014 | E8: ='Approved Item-Actual'!D14 -> 93066444 | F8: =E8/D8 -> 1.007376 | G8: 8 | H8: 45371 | I8: =H8+242 -> 45613 | J8: 45613 | L8: 1 | M8: 1
A9: 0 | B9: Boundary wall | C9: GE | D9: ='Approved Item-Actual'!C21 -> 25545140 | E9: ='Approved Item-Actual'!D21 -> 23545140 | L9: 1 | M9: 1
A10: 1 | B10: Electrical Conduiting | C10: Qatalytic Eng. | D10: ='Approved Item-Actual'!C15 -> 29485630 | E10: ='Approved Item-Actual'!D15 -> 28472773 | F10: =E10/D10 -> 0.96564915 | G10: 6 | H10: 45402 | I10: 45585 | J10: 45915 | L10: 1 | M10: 1
A11: 2 | B11: Plumbing Conduiting | C11: Qatalytic Eng. | D11: ='Approved Item-Actual'!C16 -> 23645601 | E11: ='Approved Item-Actual'!D16 -> 21009948 | F11: =E11/D11 -> 0.88853517 | G11: 6 | H11: 45402 | I11: 45585 | J11: 45916 | L11: 1 | M11: 1
A12: 3 | B12: P.C.C | C12: GE | D12: ='Approved Item-Actual'!C18 -> 27569921 | E12: ='Approved Item-Actual'!D18 -> 26661230 | F12: =E12/D12 -> 0.96704049 | G12: 4 | H12: 45474 | I12: 45596 | J12: 45895 | L12: 1 | M12: 1
A13: 4 | B13: External Plaster | C13: Ezymix | D13: ='Approved Item-Actual'!C19 -> 6841856 | E13: ='Approved Item-Actual'!D19 -> 3712137 | F13: =E13/D13 -> 0.54256287 | G13: 8 | H13: 45402 | I13: 45641 | J13: 45916 | L13: 1 | M13: 0.57
A14: 5 | B14: Internal Plaster | C14: Ezymix | D14: ='Approved Item-Actual'!C20 -> 57158144 | E14: ='Approved Item-Actual'!D20 -> 44216742 | F14: =E14/D14 -> 0.77358604 | G14: 8 | H14: 45402 | I14: 45641 | J14: 45916 | L14: 0.98 | M14: 0.91
A15: 6 | B15: Electrical work | C15: Qatalytic Eng. | D15: =SUM('Approved Item-Actual'!C22,'Approved Item-Actual'!C24,'Approved Item-Actual'!C30,'Approved Item-Actual'!C31,'Approved Item-Actual'!C40,'Approved Item-Actual'!C45,'Approved Item-Actual'!C48,'Approved Item-Actual'!C57,'Approved Item-Actual'!C58,'Approved Item-Actual'!C66,'Approved Item-Actual'!C63) -> 298237905 | E15: =SUM('Approved Item-Actual'!D22,'Approved Item-Actual'!D24,'Approved Item-Actual'!D30,'Approved Item-Actual'!D31,'Approved Item-Actual'!D40,'Approved Item-Actual'!D63,'Approved Item-Actual'!D45,'Approved Item-Actual'!D48,'Approved Item-Actual'!D57,'Approved Item-Actual'!D58,'Approved Item-Actual'!D66,'Approved Item-Actual'!D63) -> 1.8328662e+08 | F15: =E15/D15 -> 0.61456513 | G15: 12 | H15: 45488 | I15: 45852 | J15: 45930 | L15: 0.82 | M15: 0.7
A16: 7 | B16: Plumbing Work | C16: Qatalytic Eng. | D16: =SUM('Approved Item-Actual'!C17,'Approved Item-Actual'!C23,'Approved Item-Actual'!C33,'Approved Item-Actual'!C53,'Approved Item-Actual'!C61) -> 131534857 | E16: =SUM('Approved Item-Actual'!D17,'Approved Item-Actual'!D23,'Approved Item-Actual'!D33,'Approved Item-Actual'!D53,'Approved Item-Actual'!D55,'Approved Item-Actual'!D61) -> 90813182 | F16: =E16/D16 -> 0.69041153 | G16: 12 | H16: 45498 | I16: 45862 | J16: 45930 | L16: 0.82 | M16: 0.7
A17: 8 | B17: Fire fighting | C17: Captive Aire | D17: =SUM('Approved Item-Actual'!C25,'Approved Item-Actual'!C26,'Approved Item-Actual'!C62,'Approved Item-Actual'!C70) -> 90048330 | E17: =SUM('Approved Item-Actual'!D25,'Approved Item-Actual'!D26,'Approved Item-Actual'!D62,'Approved Item-Actual'!D70) -> 42491446 | F17: =E17/D17 -> 0.47187378 | G17: 4 | H17: 45519 | I17: 45642 | J17: 45915 | L17: 0.9 | M17: 0.95
A18: 9 | B18: HVAC Ductng | C18: Al Ahamd | D18: ='Approved Item-Actual'!C27 -> 11000000 | E18: ='Approved Item-Actual'!D27 -> 7206637 | F18: =E18/D18 -> 0.65514882 | G18: 4 | H18: 45523 | I18: 45645 | J18: 45915 | L18: 1 | M18: 0.9
A19: 10 | B19: Copper Piping | C19: Al Ahamd | D19: ='Approved Item-Actual'!C28 -> 20000000 | E19: ='Approved Item-Actual'!D28 -> 17529297 | F19: =E19/D19 -> 0.87646485 | G19: 6 | H19: 45523 | I19: 45645 | J19: 45923 | L19: 1 | M19: 1
A20: 11 | B20: Travertine Marble | C20: Rock stone | D20: ='Approved Item-Actual'!C74 -> 23835258 | E20: ='Approved Item-Actual'!D74 -> 22912798 | F20: =E20/D20 -> 0.96129851 | G20: 4 | H20: 45627 | I20: 45747 | J20: 45924 | L20: 0.95 | M20: 0.93
A21: 12 | B21: False ceiling | C21: Star/Elegance/BuildKo | D21: ='Approved Item-Actual'!C39 -> 38171630 | E21: ='Approved Item-Actual'!D39 -> 9378967 | F21: =E21/D21 -> 0.24570517 | G21: 4 | H21: 45616 | I21: 45736 | J21: 45945 | L21: 0.85 | M21: 0.7
A22: 13 | B22: Paint Work(internal) | C22: Juton | D22: ='Approved Item-Actual'!C41 -> 47509000 | E22: ='Approved Item-Actual'!D41 -> 7761441 | F22: =E22/D22 -> 0.1633678 | G22: 6 | H22: 45632 | I22: 45783 | J22: 45955 | L22: 0.55 | M22: 0.36
A23: 14 | B23: Paint Work(External) | C23: Rock shield | D23: ='Approved Item-Actual'!C42 -> 9961998 | E23: ='Approved Item-Actual'!D42 -> 2490500 | F23: =E23/D23 -> 0.25000005 | L23: 0.2 | M23: 0.2
A24: 15 | B24: Aluminium Work | C24: Chawala | D24: ='Approved Item-Actual'!C36 -> 68331343 | E24: ='Approved Item-Actual'!D36 -> 31452514 | F24: =E24/D24 -> 0.4602941 | G24: 5 | H24: 45542 | J24: 45920 | L24: 0.66 | M24: 0.6
