Workbook

Sheet LCRG Progress
B1: Tower | C1: Area | D1: Apartment Progress | E1: External development | F1: Ground Floor | G1: Roof Top | H1: Common Area | I1: Cleaning | J1: Progress %
C2: LCRG-Over All | D2: =D8*60%+D13*40% -> 0.59426624 | E2: =E8*60%+E13*40% -> 0.65766667 | F2: =F8*60%+F13*40% -> 0.48652 | G2: =G8*60%+G13*40% -> 0.44728 | H2: =H8*60%+H13*40% -> 0.669116 | I2: =I8*60%+I13*40% -> 0.46 | J2: =(J8*60%+J13*40%)*1.05 -> 0.6286399
C3: Weightages-Finishes | D3: 0.59 | E3: 0.1 | F3: 0.1 | G3: 0.1 | H3: 0.1 | I3: 0.01
C4: I Tower-Over All | D4: =D9*60%+D14*40% -> 0.81129287 | E4: =E9*60%+E14*40% -> 0.65766667 | F4: =F9*60%+F14*40% -> 0.6163 | G4: =G9*60%+G14*40% -> 0.5182 | H4: =H9*60%+H14*40% -> 0.72699714 | I4: =I9*60%+I14*40% -> 0.46 | J4: =J9*60%+J14*40% -> 0.77875247
C5: L1 Tower Over All | D5: =D10*60%+D15*40% -> 0.47576364 | E5: =E10*60%+E15*40% -> 0.65766667 | F5: =F10*60%+F15*40% -> 0.4 | G5: =G10*60%+G15*40% -> 0.4 | H5: =H10*60%+H15*40% -> 0.63524286 | I5: =I10*60%+I15*40% -> 0.46 | J5: =J10*60%+J15*40% -> 0.4945915
C6: L2 Tower Over All | D6: =D11*60%+D16*40% -> 0.4234 | E6: =E11*60%+E16*40% -> 0.65766667 | F6: =F11*60%+F16*40% -> 0.4 | G6: =G11*60%+G16*40% -> 0.4 | H6: =H11*60%+H16*40% -> 0.62581429 | I6: =I11*60%+I16*40% -> 0.46 | J6: =J11*60%+J16*40% -> 0.4627541
C7: FINISHES
C8: Finishes-LCRG | D8: =D9*40%+D10*30%+D11*30% -> 0.32377707 | E8: =E9*40%+E10*30%+E11*30% -> 0.42944444 | F8: =F9*40%+F10*30%+F11*30% -> 0.1442 | G8: =G9*40%+G10*30%+G11*30% -> 0.0788 | H8: =H9*40%+H10*30%+H11*30% -> 0.44852667 | I8: =I9*40%+I10*30%+I11*30% -> 0.1 | J8: =J9*40%+J10*30%+J11*30% -> 0.33117444
B9: I | C9: I Tower Progress | D9: ='Apartment Progress'!Q3 -> 0.68548812 | E9: ='External Development'!I3 -> 0.42944444 | F9: ='Ground Floor'!O3 -> 0.3605 | G9: ='Roof top'!P3 -> 0.197 | H9: ='Common Area'!I4 -> 0.54499524 | I9: 0.1 | J9: =SUMPRODUCT(D9:I9, D$3:I$3)*1.13 -> 0.63125411
B10: L1 | C10: L1 Tower Progress | D10: ='Apartment Progress'!Q192 -> 0.12627273 | E10: ='External Development'!I13 -> 0.42944444 | F10: ='Ground Floor'!O9 -> 0 | G10: ='Roof top'!P5 -> 0 | H10: ='Common Area'!I18 -> 0.39207143 | I10: 0.1 | J10: =SUMPRODUCT(D10:I10, D$3:I$3) -> 0.1576525
B11: L2 | C11: L2 Tower Progress | D11: ='Apartment Progress'!Q380 -> 0.039 | E11: ='External Development'!I23 -> 0.42944444 | F11: ='Ground Floor'!O15 -> 0 | G11: ='Roof top'!P7 -> 0 | H11: ='Common Area'!I31 -> 0.37635714 | I11: 0.1 | J11: =SUMPRODUCT(D11:I11, D$3:I$3) -> 0.10459016
C12: Structure
C13: Structure-LCRG | D13: =D14*40%+D15*30%+D16*30% -> 1 | E13: =E14*40%+E15*30%+E16*30% -> 1 | F13: =F14*40%+F15*30%+F16*30% -> 1 | G13: =G14*40%+G15*30%+G16*30% -> 1 | H13: =H14*40%+H15*30%+H16*30% -> 1 | I13: =I14*40%+I15*30%+I16*30% -> 1 | J13: =J14*40%+J15*30%+J16*30% -> 1
B14: I | C14: I Tower Progress | D14: 1 | E14: 1 | F14: 1 | G14: 1 | H14: 1 | I14: 1 | J14: =SUMPRODUCT(D14:I14, D$3:I$3) -> 1
B15: L1 | C15: L1 Tower Progress | D15: 1 | E15: 1 | F15: 1 | G15: 1 | H15: 1 | I15: 1 | J15: =SUMPRODUCT(D15:I15, D$3:I$3) -> 1
B16: L2 | C16: L2 Tower Progress | D16: 1 | E16: 1 | F16: 1 | G16: 1 | H16: 1 | I16: 1 | J16: =SUMPRODUCT(D16:I16, D$3:I$3) -> 1

Sheet Apartment Progress
B1: Tower | C1: Floor | D1: Apartment No | E1: MEP Work | F1: Ceiling | G1: Tile Work | H1: Paint Work | I1: Aluminum Work | J1: Wood Work | K1: MEP Fixtures | L1: MS Work | M1: External Plaster | N1: External Travertine | O1: External Paint | P1: Cleaning | Q1: Progress %
E2: 0.12 | F2: 0.15 | G2: 0.22 | H2: 0.1 | I2: 0.1 | J2: 0.2 | K2: 0.05 | L2: 0.02 | M2: 0.01 | N2: 0.01 | O2: 0.01 | P2: 0.01
B3: I | D3: I Tower Progress | E3: =AVERAGE(E4,E21,E55,E89,E72,E38,E106,E123,E140,E157,E174) -> 0.99090909 | F3: =AVERAGE(F4,F21,F55,F89,F72,F38,F106,F123,F140,F157,F174)*1.18 -> 0.83075576 | G3: =AVERAGE(G4,G21,G55,G89,G72,G38,G106,G123,G140,G157,G174)*1.05 -> 0.89499773 | H3: =AVERAGE(H4,H21,H55,H89,H72,H38,H106,H123,H140,H157,H174)*1.15 -> 0.33768182 | I3: =AVERAGE(I4,I21,I55,I89,I72,I38,I106,I123,I140,I157,I174)*1.1 -> 0.63636667 | J3: =AVERAGE(J4,J21,J55,J89,J72,J38,J106,J123,J140,J157,J174)*1.1 -> 0.4126 | K3: =AVERAGE(K4,K21,K55,K89,K72,K38,K106,K123,K140,K157,K174)*1.15 -> 0.15347273 | L3: =AVERAGE(L4,L21,L55,L89,L72,L38,L106,L123,L140,L157,L174) -> 0.0072727273 | M3: =AVERAGE(M4,M21,M55,M89,M72,M38,M106,M123,M140,M157,M174) -> 0.7 | N3: =AVERAGE(N4,N21,N55,N89,N72,N38,N106,N123,N140,N157,N174) -> 1 | O3: =AVERAGE(O4,O21,O55,O89,O72,O38,O106,O123,O140,O157,O174) -> 0.2 | P3: =AVERAGE(P4,P21,P55,P89,P72,P38,P106,P123,P140,P157,P174) -> 0.71818182 | Q3: =SUMPRODUCT(E3:P3, E$2:P$2)*1.04759 -> 0.68548812
C4: Floor 1 | E4: =AVERAGE(E6:E20) -> 1 | F4: =AVERAGE(F6:F20) -> 1 | G4: =AVERAGE(G6:G20) -> 1 | H4: =AVERAGE(H6:H20) -> 0.7 | I4: =AVERAGE(I6:I20) -> 0.91133333 | J4: =AVERAGE(J6:J20) -> 0.97366667 | K4: =AVERAGE(K6:K20) -> 0.72 | L4: =AVERAGE(L6:L20) -> 0.03 | ... P4: =AVERAGE(P6:P20) -> 0.9 | Q4: =SUMPRODUCT(E4:P4, E$2:P$2) -> 0.91046667
B5: I | C5: 1 | D5: 101 | E5: ='Work Progress (%)'!G14 -> 1 | F5: ='Work Progress (%)'!L14 -> 1 | G5: ='Work Progress (%)'!Y14 -> 1 | H5: ='Work Progress (%)'!AD14 -> 0.7 | I5: ='Work Progress (%)'!AI14 -> 0.55 | J5: ='Work Progress (%)'!AQ14 -> 0.8325 | K5: ='Work Progress (%)'!AV14 -> 0.7 | L5: ='Work Progress (%)'!BD14 -> 0 | M5: 0.7 | N5: 1 | O5: 0.2 | P5: 0.9 | Q5: =SUMPRODUCT(E5:P5, E$2:P$2) -> 0.8445
B6: I | C6: 1 | D6: 102 | E6: ='Work Progress (%)'!G15 -> 1 | F6: ='Work Progress (%)'!L15 -> 1 | G6: ='Work Progress (%)'!Y15 -> 1 | H6: ='Work Progress (%)'!AD15 -> 0.7 | I6: ='Work Progress (%)'!AI15 -> 0.685 | J6: ='Work Progress (%)'!AQ15 -> 0.9825 | K6: ='Work Progress (%)'!AV15 -> 0.7 | L6: ='Work Progress (%)'!BD15 -> 0 | M6: 0.7 | N6: 1 | O6: 0.2 | P6: 0.9 | Q6: =SUMPRODUCT(E6:P6, E$2:P$2) -> 0.888
B7: I | C7: 1 | D7: 103 | E7: ='Work Progress (%)'!G16 -> 1 | F7: ='Work Progress (%)'!L16 -> 1 | G7: ='Work Progress (%)'!Y16 -> 1 | H7: ='Work Progress (%)'!AD16 -> 0.7 | I7: ='Work Progress (%)'!AI16 -> 1 | J7: ='Work Progress (%)'!AQ16 -> 0.9825 | K7: ='Work Progress (%)'!AV16 -> 0.7 | L7: ='Work Progress (%)'!BD16 -> 0 | M7: 0.7 | N7: 1 | O7: 0.2 | P7: 0.9 | Q7: =SUMPRODUCT(E7:P7, E$2:P$2) -> 0.9195
B8: I | C8: 1 | D8: 104 | E8: ='Work Progress (%)'!G17 -> 1 | F8: ='Work Progress (%)'!L17 -> 1 | G8: ='Work Progress (%)'!Y17 -> 1 | H8: ='Work Progress (%)'!AD17 -> 0.5 | I8: ='Work Progress (%)'!AI17 -> 0.695 | J8: ='Work Progress (%)'!AQ17 -> 0.9825 | K8: ='Work Progress (%)'!AV17 -> 0.7 | L8: ='Work Progress (%)'!BD17 -> 0 | M8: 0.7 | N8: 1 | O8: 0.2 | P8: 0.9 | Q8: =SUMPRODUCT(E8:P8, E$2:P$2) -> 0.869
B9: I | C9: 1 | D9: 105 | E9: ='Work Progress (%)'!G18 -> 1 | F9: ='Work Progress (%)'!L18 -> 1 | G9: ='Work Progress (%)'!Y18 -> 1 | H9: ='Work Progress (%)'!AD18 -> 0.7 | I9: ='Work Progress (%)'!AI18 -> 0.785 | J9: ='Work Progress (%)'!AQ18 -> 0.9825 | K9: ='Work Progress (%)'!AV18 -> 0.7 | L9: ='Work Progress (%)'!BD18 -> 0 | M9: 0.7 | N9: 1 | O9: 0.2 | P9: 0.9 | Q9: =SUMPRODUCT(E9:P9, E$2:P$2) -> 0.898
B10: I | C10: 1 | D10: 106 | E10: ='Work Progress (%)'!G19 -> 1 | F10: ='Work Progress (%)'!L19 -> 1 | G10: ='Work Progress (%)'!Y19 -> 1 | H10: ='Work Progress (%)'!AD19 -> 0.7 | I10: ='Work Progress (%)'!AI19 -> 1 | J10: ='Work Progress (%)'!AQ19 -> 0.9825 | K10: ='Work Progress (%)'!AV19 -> 0.85 | L10: ='Work Progress (%)'!BD19 -> 0 | M10: 0.7 | N10: 1 | O10: 0.2 | P10: 0.9 | Q10: =SUMPRODUCT(E10:P10, E$2:P$2) -> 0.927
B11: I | C11: 1 | D11: 107 | E11: ='Work Progress (%)'!G20 -> 1 | F11: ='Work Progress (%)'!L20 -> 1 | G11: ='Work Progress (%)'!Y20 -> 1 | H11: ='Work Progress (%)'!AD20 -> 0.7 | I11: ='Work Progress (%)'!AI20 -> 1 | J11: ='Work Progress (%)'!AQ20 -> 0.9825 | K11: ='Work Progress (%)'!AV20 -> 0.7 | L11: ='Work Progress (%)'!BD20 -> 0 | M11: 0.7 | N11: 1 | O11: 0.2 | P11: 0.9 | Q11: =SUMPRODUCT(E11:P11, E$2:P$2) -> 0.9195
B12: I | C12: 1 | D12: 108 | E12: ='Work Progress (%)'!G21 -> 1 | F12: ='Work Progress (%)'!L21 -> 1 | G12: ='Work Progress (%)'!Y21 -> 1 | H12: ='Work Progress (%)'!AD21 -> 0.8 | I12: ='Work Progress (%)'!AI21 -> 1 | J12: ='Work Progress (%)'!AQ21 -> 0.9825 | K12: ='Work Progress (%)'!AV21 -> 0.85 | L12: ='Work Progress (%)'!BD21 -> 0 | M12: 0.7 | N12: 1 | O12: 0.2 | P12: 0.9 | Q12: =SUMPRODUCT(E12:P12, E$2:P$2) -> 0.937
B13: I | C13: 1 | D13: 109 | E13: ='Work Progress (%)'!G22 -> 1 | F13: ='Work Progress (%)'!L22 -> 1 | G13: ='Work Progress (%)'!Y22 -> 1 | H13: ='Work Progress (%)'!AD22 -> 0.7 | I13: ='Work Progress (%)'!AI22 -> 1 | J13: ='Work Progress (%)'!AQ22 -> 0.9825 | K13: ='Work Progress (%)'!AV22 -> 0.7 | L13: ='Work Progress (%)'!BD22 -> 0 | M13: 0.7 | N13: 1 | O13: 0.2 | P13: 0.9 | Q13: =SUMPRODUCT(E13:P13, E$2:P$2) -> 0.9195
B14: I | C14: 1 | D14: 110 | E14: ='Work Progress (%)'!G23 -> 1 | F14: ='Work Progress (%)'!L23 -> 1 | G14: ='Work Progress (%)'!Y23 -> 1 | H14: ='Work Progress (%)'!AD23 -> 0.8 | I14: ='Work Progress (%)'!AI23 -> 0.91 | J14: ='Work Progress (%)'!AQ23 -> 0.9825 | K14: ='Work Progress (%)'!AV23 -> 0.7 | L14: ='Work Progress (%)'!BD23 -> 0.45 | M14: 0.7 | N14: 1 | O14: 0.2 | P14: 0.9 | Q14: =SUMPRODUCT(E14:P14, E$2:P$2) -> 0.9295
B15: I | C15: 1 | D15: 111 | E15: ='Work Progress (%)'!G24 -> 1 | F15: ='Work Progress (%)'!L24 -> 1 | G15: ='Work Progress (%)'!Y24 -> 1 | H15: ='Work Progress (%)'!AD24 -> 0.7 | I15: ='Work Progress (%)'!AI24 -> 0.91 | J15: ='Work Progress (%)'!AQ24 -> 0.9825 | K15: ='Work Progress (%)'!AV24 -> 0.7 | L15: ='Work Progress (%)'!BD24 -> 0 | M15: 0.7 | N15: 1 | O15: 0.2 | P15: 0.9 | Q15: =SUMPRODUCT(E15:P15, E$2:P$2) -> 0.9105
B16: I | C16: 1 | D16: 112 | E16: ='Work Progress (%)'!G25 -> 1 | F16: ='Work Progress (%)'!L25 -> 1 | G16: ='Work Progress (%)'!Y25 -> 1 | H16: ='Work Progress (%)'!AD25 -> 0.8 | I16: ='Work Progress (%)'!AI25 -> 1 | J16: ='Work Progress (%)'!AQ25 -> 1 | K16: ='Work Progress (%)'!AV25 -> 0.7 | L16: ='Work Progress (%)'!BD25 -> 0 | M16: 0.7 | N16: 1 | O16: 0.2 | P16: 0.9 | Q16: =SUMPRODUCT(E16:P16, E$2:P$2) -> 0.933
... B20: I | C20: 1 | D20: 116 | E20: ='Work Progress (%)'!G29 -> 1 | F20: ='Work Progress (%)'!L29 -> 1 | G20: ='Work Progress (%)'!Y29 -> 1 | H20: ='Work Progress (%)'!AD29 -> 0.7 | I20: ='Work Progress (%)'!AI29 -> 1 | J20: ='Work Progress (%)'!AQ29 -> 0.9825 | K20: ='Work Progress (%)'!AV29 -> 0.7 | L20: ='Work Progress (%)'!BD29 -> 0 | M20: 0.7 | N20: 1 | O20: 0.2 | P20: 0.9 | Q20: =SUMPRODUCT(E20:P20, E$2:P$2) -> 0.9195
B21: I | D21: Floor 2 | E21: =AVERAGE(E23:E37) -> 1 | F21: =AVERAGE(F23:F37) -> 1 | G21: =AVERAGE(G23:G37) -> 1 | H21: =AVERAGE(H23:H37) -> 0.5 | I21: =AVERAGE(I23:I37) -> 0.86166667 | J21: =AVERAGE(J23:J37) -> 0.9725 | K21: =AVERAGE(K23:K37) -> 0.55 | L21: =AVERAGE(L23:L37) -> 0 | ... P21: =AVERAGE(P23:P37) -> 0.7 | Q21: =SUMPRODUCT(E21:P21, E$2:P$2) -> 0.87416667
B22: I | C22: 2 | D22: 201 | E22: ='Work Progress (%)'!G31 -> 1 | F22: ='Work Progress (%)'!L31 -> 1 | G22: ='Work Progress (%)'!Y31 -> 1 | H22: ='Work Progress (%)'!AD31 -> 0.5 | I22: ='Work Progress (%)'!AI31 -> 0.375 | J22: ='Work Progress (%)'!AQ31 -> 0.8325 | K22: ='Work Progress (%)'!AV31 -> 0.55 | L22: ='Work Progress (%)'!BD31 -> 0 | M22: 0.7 | N22: 1 | O22: 0.2 | P22: 0.7 | Q22: =SUMPRODUCT(E22:P22, E$2:P$2) -> 0.7975
B23: I | C23: 2 | D23: 202 | E23: ='Work Progress (%)'!G32 -> 1 | F23: ='Work Progress (%)'!L32 -> 1 | G23: ='Work Progress (%)'!Y32 -> 1 | H23: ='Work Progress (%)'!AD32 -> 0.5 | I23: ='Work Progress (%)'!AI32 -> 0.55 | J23: ='Work Progress (%)'!AQ32 -> 0.9825 | K23: ='Work Progress (%)'!AV32 -> 0.55 | L23: ='Work Progress (%)'!BD32 -> 0 | M23: 0.7 | N23: 1 | O23: 0.2 | P23: 0.7 | Q23: =SUMPRODUCT(E23:P23, E$2:P$2) -> 0.845
B24: I | C24: 2 | D24: 203 | E24: ='Work Progress (%)'!G33 -> 1 | F24: ='Work Progress (%)'!L33 -> 1 | G24: ='Work Progress (%)'!Y33 -> 1 | H24: ='Work Progress (%)'!AD33 -> 0.5 | I24: ='Work Progress (%)'!AI33 -> 0.595 | J24: ='Work Progress (%)'!AQ33 -> 0.9825 | K24: ='Work Progress (%)'!AV33 -> 0.55 | L24: ='Work Progress (%)'!BD33 -> 0 | M24: 0.7 | N24: 1 | O24: 0.2 | P24: 0.7 | Q24: =SUMPRODUCT(E24:P24, E$2:P$2) -> 0.8495
B25: I | C25: 2 | D25: 204 | E25: ='Work Progress (%)'!G34 -> 1 | F25: ='Work Progress (%)'!L34 -> 1 | G25: ='Work Progress (%)'!Y34 -> 1 | H25: ='Work Progress (%)'!AD34 -> 0.5 | I25: ='Work Progress (%)'!AI34 -> 0.7 | J25: ='Work Progress (%)'!AQ34 -> 0.9825 | K25: ='Work Progress (%)'!AV34 -> 0.55 | L25: ='Work Progress (%)'!BD34 -> 0 | M25: 0.7 | N25: 1 | O25: 0.2 | P25: 0.7 | Q25: =SUMPRODUCT(E25:P25, E$2:P$2) -> 0.86
B26: I | C26: 2 | D26: 205 | E26: ='Work Progress (%)'!G35 -> 1 | F26: ='Work Progress (%)'!L35 -> 1 | G26: ='Work Progress (%)'!Y35 -> 1 | H26: ='Work Progress (%)'!AD35 -> 0.5 | I26: ='Work Progress (%)'!AI35 -> 0.85 | J26: ='Work Progress (%)'!AQ35 -> 0.9825 | K26: ='Work Progress (%)'!AV35 -> 0.55 | L26: ='Work Progress (%)'!BD35 -> 0 | M26: 0.7 | N26: 1 | O26: 0.2 | P26: 0.7 | Q26: =SUMPRODUCT(E26:P26, E$2:P$2) -> 0.875
B27: I | C27: 2 | D27: 206 | E27: ='Work Progress (%)'!G36 -> 1 | F27: ='Work Progress (%)'!L36 -> 1 | G27: ='Work Progress (%)'!Y36 -> 1 | H27: ='Work Progress (%)'!AD36 -> 0.5 | I27: ='Work Progress (%)'!AI36 -> 1 | J27: ='Work Progress (%)'!AQ36 -> 0.9825 | K27: ='Work Progress (%)'!AV36 -> 0.55 | L27: ='Work Progress (%)'!BD36 -> 0 | M27: 0.7 | N27: 1 | O27: 0.2 | P27: 0.7 | Q27: =SUMPRODUCT(E27:P27, E$2:P$2) -> 0.89
B28: I | C28: 2 | D28: 207 | E28: ='Work Progress (%)'!G37 -> 1 | F28: ='Work Progress (%)'!L37 -> 1 | G28: ='Work Progress (%)'!Y37 -> 1 | H28: ='Work Progress (%)'!AD37 -> 0.5 | I28: ='Work Progress (%)'!AI37 -> 0.905 | J28: ='Work Progress (%)'!AQ37 -> 0.9825 | K28: ='Work Progress (%)'!AV37 -> 0.55 | L28: ='Work Progress (%)'!BD37 -> 0 | M28: 0.7 | N28: 1 | O28: 0.2 | P28: 0.7 | Q28: =SUMPRODUCT(E28:P28, E$2:P$2) -> 0.8805
B29: I | C29: 2 | D29: 208 | E29: ='Work Progress (%)'!G38 -> 1 | F29: ='Work Progress (%)'!L38 -> 1 | G29: ='Work Progress (%)'!Y38 -> 1 | H29: ='Work Progress (%)'!AD38 -> 0.5 | I29: ='Work Progress (%)'!AI38 -> 1 | J29: ='Work Progress (%)'!AQ38 -> 0.9825 | K29: ='Work Progress (%)'!AV38 -> 0.55 | L29: ='Work Progress (%)'!BD38 -> 0 | M29: 0.7 | N29: 1 | O29: 0.2 | P29: 0.7 | Q29: =SUMPRODUCT(E29:P29, E$2:P$2) -> 0.89
B30: I | C30: 2 | D30: 209 | E30: ='Work Progress (%)'!G39 -> 1 | F30: ='Work Progress (%)'!L39 -> 1 | G30: ='Work Progress (%)'!Y39 -> 1 | H30: ='Work Progress (%)'!AD39 -> 0.5 | I30: ='Work Progress (%)'!AI39 -> 0.91 | J30: ='Work Progress (%)'!AQ39 -> 0.9825 | K30: ='Work Progress (%)'!AV39 -> 0.55 | L30: ='Work Progress (%)'!BD39 -> 0 | M30: 0.7 | N30: 1 | O30: 0.2 | P30: 0.7 | Q30: =SUMPRODUCT(E30:P30, E$2:P$2) -> 0.881
B31: I | C31: 2 | D31: 210 | E31: ='Work Progress (%)'!G40 -> 1 | F31: ='Work Progress (%)'!L40 -> 1 | G31: ='Work Progress (%)'!Y40 -> 1 | H31: ='Work Progress (%)'!AD40 -> 0.5 | I31: ='Work Progress (%)'!AI40 -> 1 | J31: ='Work Progress (%)'!AQ40 -> 0.9825 | K31: ='Work Progress (%)'!AV40 -> 0.55 | L31: ='Work Progress (%)'!BD40 -> 0 | M31: 0.7 | N31: 1 | O31: 0.2 | P31: 0.7 | Q31: =SUMPRODUCT(E31:P31, E$2:P$2) -> 0.89
B32: I | C32: 2 | D32: 211 | E32: ='Work Progress (%)'!G41 -> 1 | F32: ='Work Progress (%)'!L41 -> 1 | G32: ='Work Progress (%)'!Y41 -> 1 | H32: ='Work Progress (%)'!AD41 -> 0.5 | I32: ='Work Progress (%)'!AI41 -> 0.82 | J32: ='Work Progress (%)'!AQ41 -> 0.9825 | K32: ='Work Progress (%)'!AV41 -> 0.55 | L32: ='Work Progress (%)'!BD41 -> 0 | M32: 0.7 | N32: 1 | O32: 0.2 | P32: 0.7 | Q32: =SUMPRODUCT(E32:P32, E$2:P$2) -> 0.872
B33: I | C33: 2 | D33: 212 | E33: ='Work Progress (%)'!G42 -> 1 | F33: ='Work Progress (%)'!L42 -> 1 | G33: ='Work Progress (%)'!Y42 -> 1 | H33: ='Work Progress (%)'!AD42 -> 0.5 | I33: ='Work Progress (%)'!AI42 -> 1 | J33: ='Work Progress (%)'!AQ42 -> 0.9825 | K33: ='Work Progress (%)'!AV42 -> 0.55 | L33: ='Work Progress (%)'!BD42 -> 0 | M33: 0.7 | N33: 1 | O33: 0.2 | P33: 0.7 | Q33: =SUMPRODUCT(E33:P33, E$2:P$2) -> 0.89
... B37: I | C37: 2 | D37: 216 | E37: ='Work Progress (%)'!G46 -> 1 | F37: ='Work Progress (%)'!L46 -> 1 | G37: ='Work Progress (%)'!Y46 -> 1 | H37: ='Work Progress (%)'!AD46 -> 0.5 | I37: ='Work Progress (%)'!AI46 -> 0.91 | J37: ='Work Progress (%)'!AQ46 -> 0.9825 | K37: ='Work Progress (%)'!AV46 -> 0.55 | L37: ='Work Progress (%)'!BD46 -> 0 | M37: 0.7 | N37: 1 | O37: 0.2 | P37: 0.7 | Q37: =SUMPRODUCT(E37:P37, E$2:P$2) -> 0.881
B38: I | D38: Floor 3 | E38: =AVERAGE(E40:E54) -> 1 | F38: =AVERAGE(F40:F54) -> 0.962 | G38: =AVERAGE(G40:G54) -> 0.99083333 | H38: =AVERAGE(H40:H54) -> 0.5 | I38: =AVERAGE(I40:I54) -> 0.87866667 | J38: =AVERAGE(J40:J54) -> 0.9635 | K38: =AVERAGE(K40:K54) -> 0.198 | L38: =AVERAGE(L40:L54) -> 0.05 | ... P38: =AVERAGE(P40:P54) -> 0.7 | Q38: =SUMPRODUCT(E38:P38, E$2:P$2) -> 0.84975
B39: I | C39: 3 | D39: 301 | E39: ='Work Progress (%)'!G48 -> 1 | F39: ='Work Progress (%)'!L48 -> 1 | G39: ='Work Progress (%)'!Y48 -> 0.9975 | H39: ='Work Progress (%)'!AD48 -> 0.5 | I39: ='Work Progress (%)'!AI48 -> 0.715 | J39: ='Work Progress (%)'!AQ48 -> 0.7275 | K39: ='Work Progress (%)'!AV48 -> 0.21 | L39: ='Work Progress (%)'!BD48 -> 0 | M39: 0.7 | N39: 1 | O39: 0.2 | P39: 0.7 | Q39: =SUMPRODUCT(E39:P39, E$2:P$2) -> 0.79295
B40: I | C40: 3 | D40: 302 | E40: ='Work Progress (%)'!G49 -> 1 | F40: ='Work Progress (%)'!L49 -> 1 | G40: ='Work Progress (%)'!Y49 -> 0.9975 | H40: ='Work Progress (%)'!AD49 -> 0.5 | I40: ='Work Progress (%)'!AI49 -> 0.61 | J40: ='Work Progress (%)'!AQ49 -> 0.9825 | K40: ='Work Progress (%)'!AV49 -> 0.21 | L40: ='Work Progress (%)'!BD49 -> 0 | M40: 0.7 | N40: 1 | O40: 0.2 | P40: 0.7 | Q40: =SUMPRODUCT(E40:P40, E$2:P$2) -> 0.83345
B41: I | C41: 3 | D41: 303 | E41: ='Work Progress (%)'!G50 -> 1 | F41: ='Work Progress (%)'!L50 -> 1 | G41: ='Work Progress (%)'!Y50 -> 0.9975 | H41: ='Work Progress (%)'!AD50 -> 0.5 | I41: ='Work Progress (%)'!AI50 -> 0.82 | J41: ='Work Progress (%)'!AQ50 -> 0.9825 | K41: ='Work Progress (%)'!AV50 -> 0.21 | L41: ='Work Progress (%)'!BD50 -> 0 | M41: 0.7 | N41: 1 | O41: 0.2 | P41: 0.7 | Q41: =SUMPRODUCT(E41:P41, E$2:P$2) -> 0.85445
B42: I | C42: 3 | D42: 304 | E42: ='Work Progress (%)'!G51 -> 1 | F42: ='Work Progress (%)'!L51 -> 1 | G42: ='Work Progress (%)'!Y51 -> 0.8975 | H42: ='Work Progress (%)'!AD51 -> 0.5 | I42: ='Work Progress (%)'!AI51 -> 0.685 | J42: ='Work Progress (%)'!AQ51 -> 0.9525 | K42: ='Work Progress (%)'!AV51 -> 0.3 | L42: ='Work Progress (%)'!BD51 -> 0 | M42: 0.7 | N42: 1 | O42: 0.2 | P42: 0.7 | Q42: =SUMPRODUCT(E42:P42, E$2:P$2) -> 0.81745
B43: I | C43: 3 | D43: 305 | E43: ='Work Progress (%)'!G52 -> 1 | F43: ='Work Progress (%)'!L52 -> 1 | G43: ='Work Progress (%)'!Y52 -> 0.9975 | H43: ='Work Progress (%)'!AD52 -> 0.5 | I43: ='Work Progress (%)'!AI52 -> 0.995 | J43: ='Work Progress (%)'!AQ52 -> 0.9825 | K43: ='Work Progress (%)'!AV52 -> 0.21 | L43: ='Work Progress (%)'!BD52 -> 0 | M43: 0.7 | N43: 1 | O43: 0.2 | P43: 0.7 | Q43: =SUMPRODUCT(E43:P43, E$2:P$2) -> 0.87195
B44: I | C44: 3 | D44: 306 | E44: ='Work Progress (%)'!G53 -> 1 | F44: ='Work Progress (%)'!L53 -> 1 | G44: ='Work Progress (%)'!Y53 -> 0.9975 | H44: ='Work Progress (%)'!AD53 -> 0.5 | I44: ='Work Progress (%)'!AI53 -> 0.85 | J44: ='Work Progress (%)'!AQ53 -> 0.9825 | K44: ='Work Progress (%)'!AV53 -> 0.3 | L44: ='Work Progress (%)'!BD53 -> 0 | M44: 0.7 | N44: 1 | O44: 0.2 | P44: 0.7 | Q44: =SUMPRODUCT(E44:P44, E$2:P$2) -> 0.86195
B45: I | C45: 3 | D45: 307 | E45: ='Work Progress (%)'!G54 -> 1 | F45: ='Work Progress (%)'!L54 -> 1 | G45: ='Work Progress (%)'!Y54 -> 0.9975 | H45: ='Work Progress (%)'!AD54 -> 0.5 | I45: ='Work Progress (%)'!AI54 -> 1 | J45: ='Work Progress (%)'!AQ54 -> 0.9825 | K45: ='Work Progress (%)'!AV54 -> 0.21 | L45: ='Work Progress (%)'!BD54 -> 0 | M45: 0.7 | N45: 1 | O45: 0.2 | P45: 0.7 | Q45: =SUMPRODUCT(E45:P45, E$2:P$2) -> 0.87245
B46: I | C46: 3 | D46: 308 | E46: ='Work Progress (%)'!G55 -> 1 | F46: ='Work Progress (%)'!L55 -> 1 | G46: ='Work Progress (%)'!Y55 -> 0.9975 | H46: ='Work Progress (%)'!AD55 -> 0.5 | I46: ='Work Progress (%)'!AI55 -> 1 | J46: ='Work Progress (%)'!AQ55 -> 0.9825 | K46: ='Work Progress (%)'!AV55 -> 0.3 | L46: ='Work Progress (%)'!BD55 -> 0 | M46: 0.7 | N46: 1 | O46: 0.2 | P46: 0.7 | Q46: =SUMPRODUCT(E46:P46, E$2:P$2) -> 0.87695
...

Sheet Ground Floor
B1: Tower | C1: Area | D1: MEP Work | E1: Ceiling | F1: Tile Work | G1: Paint Work | H1: Aluminum Work | I1: Wood Work | J1: MEP Fixtures | K1: MS Work | L1: External Plaster | M1: External Paint | N1: Cleaning | O1: Progress %
D2: 0.12 | E2: 0.15 | F2: 0.22 | G2: 0.1 | H2: 0.11 | I2: 0.2 | J2: 0.05 | K2: 0.02 | L2: 0.01 | M2: 0.01 | N2: 0.01
C3: I tower | D3: =D4 -> 1 | E3: =E4 -> 0.025 | F3: =F4 -> 0.44 | G3: =G4 -> 0.15 | H3: =H4 -> 0.13 | I3: =I4 -> 0.44 | J3: =J4 -> 0 | K3: =K4 -> 0.2 | ... N3: =N4 -> 0.8 | O3: =SUMPRODUCT(D3:N3, D$2:N$2) -> 0.3605
B4: I | C4: Ground Floor-I | D4: =SUM((D5*40%)+(D6*25%)+(D7*20%)+(D8*15%)) -> 1 | E4: =SUM((E5*40%)+(E6*25%)+(E7*20%)+(E8*15%)) -> 0.025 | F4: =SUM((F5*40%)+(F6*25%)+(F7*20%)+(F8*15%)) -> 0.44 | G4: =SUM((G5*40%)+(G6*25%)+(G7*20%)+(G8*15%)) -> 0.15 | H4: =SUM((H5*40%)+(H6*25%)+(H7*20%)+(H8*15%)) -> 0.13 | I4: =SUM((I5*40%)+(I6*25%)+(I7*20%)+(I8*15%)) -> 0.44 | J4: =SUM((J5*40%)+(J6*25%)+(J7*20%)+(J8*15%)) -> 0 | K4: =SUM((K5*40%)+(K6*25%)+(K7*20%)+(K8*15%)) -> 0.2 | ... O4: =SUM((O5*40%)+(O6*25%)+(O7*20%)+(O8*15%)) -> 0.3605
B5: I | C5: Lobby | D5: 1 | E5: 0 | F5: 0.8 | G5: 0.15 | H5: 0.2 | I5: 0.5 | J5: 0 | K5: 0.2 | L5: 1 | M5: 0.2 | N5: 0.8 | O5: =SUMPRODUCT(D5:N5, D$2:N$2) -> 0.457
B6: I | C6: Gym | D6: 1 | E6: 0.1 | F6: 0.2 | G6: 0.15 | H6: 0.2 | I6: 0.4 | J6: 0 | K6: 0.2 | L6: 1 | M6: 0.2 | N6: 0.8 | O6: =SUMPRODUCT(D6:N6, D$2:N$2) -> 0.32
B7: I | C7: Business Center | D7: 1 | E7: 0 | F7: 0.2 | G7: 0.15 | H7: 0 | I7: 0.4 | J7: 0 | K7: 0.2 | L7: 1 | M7: 0.2 | N7: 0.8 | O7: =SUMPRODUCT(D7:N7, D$2:N$2) -> 0.283
B8: I | C8: Game Room | D8: 1 | E8: 0 | F8: 0.2 | G8: 0.15 | H8: 0 | I8: 0.4 | J8: 0 | K8: 0.2 | L8: 0.1 | M8: 0.2 | N8: 0.8 | O8: =SUMPRODUCT(D8:N8, D$2:N$2) -> 0.274
C9: L1 tower | D9: =D10 -> 0 | E9: =E10 -> 0 | F9: =F10 -> 0 | G9: =G10 -> 0 | H9: =H10 -> 0 | I9: =I10 -> 0 | J9: =J10 -> 0 | K9: =K10 -> 0 | ... N9: =N10 -> 0 | O9: =SUMPRODUCT(D9:N9, D$2:N$2) -> 0
B10: L1 | C10: Ground Floor-L1 | D10: =SUM((D11*40%)+(D12*25%)+(D13*20%)+(D14*15%)) -> 0 | E10: =SUM((E11*40%)+(E12*25%)+(E13*20%)+(E14*15%)) -> 0 | F10: =SUM((F11*40%)+(F12*25%)+(F13*20%)+(F14*15%)) -> 0 | G10: =SUM((G11*40%)+(G12*25%)+(G13*20%)+(G14*15%)) -> 0 | H10: =SUM((H11*40%)+(H12*25%)+(H13*20%)+(H14*15%)) -> 0 | I10: =SUM((I11*40%)+(I12*25%)+(I13*20%)+(I14*15%)) -> 0 | J10: =SUM((J11*40%)+(J12*25%)+(J13*20%)+(J14*15%)) -> 0 | K10: =SUM((K11*40%)+(K12*25%)+(K13*20%)+(K14*15%)) -> 0 | ... O10: =SUM((O11*40%)+(O12*25%)+(O13*20%)+(O14*15%)) -> 0
B11: L1 | C11: Lobby | D11: 0 | E11: 0 | F11: 0 | G11: 0 | H11: 0 | I11: 0 | J11: 0 | K11: 0 | L11: 0 | M11: 0 | N11: 0 | O11: =SUMPRODUCT(D11:N11, D$2:N$2) -> 0
B12: L1 | C12: Ammenties | D12: 0 | E12: 0 | F12: 0 | G12: 0 | H12: 0 | I12: 0 | J12: 0 | K12: 0 | L12: 0 | M12: 0 | N12: 0 | O12: =SUMPRODUCT(D12:N12, D$2:N$2) -> 0
B13: L1 | C13: Shops | D13: 0 | E13: 0 | F13: 0 | G13: 0 | H13: 0 | I13: 0 | J13: 0 | K13: 0 | L13: 0 | M13: 0 | N13: 0 | O13: =SUMPRODUCT(D13:N13, D$2:N$2) -> 0
B14: L1 | C14: Café | D14: 0 | E14: 0 | F14: 0 | G14: 0 | H14: 0 | I14: 0 | J14: 0 | K14: 0 | L14: 0 | M14: 0 | N14: 0 | O14: =SUMPRODUCT(D14:N14, D$2:N$2) -> 0
C15: L2 tower | D15: =D16 -> 0 | E15: =E16 -> 0 | F15: =F16 -> 0 | G15: =G16 -> 0 | H15: =H16 -> 0 | I15: =I16 -> 0 | J15: =J16 -> 0 | K15: =K16 -> 0 | ... N15: =N16 -> 0 | O15: =SUMPRODUCT(D15:N15, D$2:N$2) -> 0
B16: L2 | C16: Ground Floor-L2 | D16: =SUM((D17*40%)+(D18*25%)+(D19*20%)+(D20*15%)) -> 0 | E16: =SUM((E17*40%)+(E18*25%)+(E19*20%)+(E20*15%)) -> 0 | F16: =SUM((F17*40%)+(F18*25%)+(F19*20%)+(F20*15%)) -> 0 | G16: =SUM((G17*40%)+(G18*25%)+(G19*20%)+(G20*15%)) -> 0 | H16: =SUM((H17*40%)+(H18*25%)+(H19*20%)+(H20*15%)) -> 0 | I16: =SUM((I17*40%)+(I18*25%)+(I19*20%)+(I20*15%)) -> 0 | J16: =SUM((J17*40%)+(J18*25%)+(J19*20%)+(J20*15%)) -> 0 | K16: =SUM((K17*40%)+(K18*25%)+(K19*20%)+(K20*15%)) -> 0 | ... O16: =SUM((O17*40%)+(O18*25%)+(O19*20%)+(O20*15%)) -> 0
B17: L2 | C17: Lobby | D17: 0 | E17: 0 | F17: 0 | G17: 0 | H17: 0 | I17: 0 | J17: 0 | K17: 0 | L17: 0 | M17: 0 | N17: 0 | O17: =SUMPRODUCT(D17:N17, D$2:N$2) -> 0
B18: L2 | C18: Ammenties | D18: 0 | E18: 0 | F18: 0 | G18: 0 | H18: 0 | I18: 0 | J18: 0 | K18: 0 | L18: 0 | M18: 0 | N18: 0 | O18: =SUMPRODUCT(D18:N18, D$2:N$2) -> 0
B19: L2 | C19: Shops | D19: 0 | E19: 0 | F19: 0 | G19: 0 | H19: 0 | I19: 0 | J19: 0 | K19: 0 | L19: 0 | M19: 0 | N19: 0 | O19: =SUMPRODUCT(D19:N19, D$2:N$2) -> 0
B20: L2 | C20: Café | D20: 0 | E20: 0 | F20: 0 | G20: 0 | H20: 0 | I20: 0 | J20: 0 | K20: 0 | L20: 0 | M20: 0 | N20: 0 | O20: =SUMPRODUCT(D20:N20, D$2:N$2) -> 0

Sheet External Development
B1: Tower | C1: Area | D1: MEP Work | E1: Civil Finishes Work | F1: MS/MEP Fixtures | G1: Finishes | H1: cleaning | I1: Progress %
C2: weightge | D2: 0.1 | E2: 0.5 | F2: 0.25 | G2: 0.1 | H2: 0.05
B3: I | C3: External Development-I | D3: =AVERAGE(D4:D12) -> 0.48888889 | E3: =AVERAGE(E4:E12) -> 0.44444444 | F3: =AVERAGE(F4:F12) -> 0.41111111 | G3: =AVERAGE(G4:G12) -> 0.33333333 | H3: =AVERAGE(H4:H12) -> 0.44444444 | I3: =SUMPRODUCT(D3:H3, D$2:H$2) -> 0.42944444
B4: I | C4: Courtyard Preparations | D4: 0.8 | E4: 0.6 | F4: 0.6 | G4: 0 | H4: 0.5 | I4: =SUMPRODUCT(D4:H4, D$2:H$2) -> 0.555
B5: I | C5: Courtyard Finishes | D5: 0.6 | E5: 0.4 | F5: 0.1 | G5: 0 | H5: 0.5 | I5: =SUMPRODUCT(D5:H5, D$2:H$2) -> 0.31
B6: I | C6: Sewer & Rainwater Line | D6: 0.8 | E6: 0.8 | F6: 0.8 | G6: 0.8 | H6: 0.8 | I6: =SUMPRODUCT(D6:H6, D$2:H$2) -> 0.8
B7: I | C7: Road Works | D7: 0.75 | E7: 0.75 | F7: 0.75 | G7: 0.75 | H7: 0.75 | I7: =SUMPRODUCT(D7:H7, D$2:H$2) -> 0.75
B8: I | C8: Boundary Wall | D8: 1 | E8: 1 | F8: 1 | G8: 1 | H8: 1 | I8: =SUMPRODUCT(D8:H8, D$2:H$2) -> 1
B9: I | C9: Basement Flooring Works | D9: 0.25 | E9: 0.25 | F9: 0.25 | G9: 0.25 | H9: 0.25 | I9: =SUMPRODUCT(D9:H9, D$2:H$2) -> 0.25
B10: I | C10: Basement Finishes | D10: 0 | E10: 0 | F10: 0 | G10: 0 | H10: 0 | I10: =SUMPRODUCT(D10:H10, D$2:H$2) -> 0
B11: I | C11: Boundary Wall Louvers | D11: 0.15 | E11: 0.15 | F11: 0.15 | G11: 0.15 | H11: 0.15 | I11: =SUMPRODUCT(D11:H11, D$2:H$2) -> 0.15
B12: I | C12: Paver Works | D12: 0.05 | E12: 0.05 | F12: 0.05 | G12: 0.05 | H12: 0.05 | I12: =SUMPRODUCT(D12:H12, D$2:H$2) -> 0.05
B13: L1 | C13: External Development-L1 | D13: =AVERAGE(D14:D22) -> 0.48888889 | E13: =AVERAGE(E14:E22) -> 0.44444444 | F13: =AVERAGE(F14:F22) -> 0.41111111 | G13: =AVERAGE(G14:G22) -> 0.33333333 | H13: =AVERAGE(H14:H22) -> 0.44444444 | I13: =SUMPRODUCT(D13:H13, D$2:H$2) -> 0.42944444
B14: L1 | C14: Courtyard Preparations | D14: 0.8 | E14: 0.6 | F14: 0.6 | G14: 0 | H14: 0.5 | I14: =SUMPRODUCT(D14:H14, D$2:H$2) -> 0.555
B15: L1 | C15: Courtyard Finishes | D15: 0.6 | E15: 0.4 | F15: 0.1 | G15: 0 | H15: 0.5 | I15: =SUMPRODUCT(D15:H15, D$2:H$2) -> 0.31
B16: L1 | C16: Sewer & Rainwater Line | D16: 0.8 | E16: 0.8 | F16: 0.8 | G16: 0.8 | H16: 0.8 | I16: =SUMPRODUCT(D16:H16, D$2:H$2) -> 0.8
B17: L1 | C17: Road Works | D17: 0.75 | E17: 0.75 | F17: 0.75 | G17: 0.75 | H17: 0.75 | I17: =SUMPRODUCT(D17:H17, D$2:H$2) -> 0.75
B18: L1 | C18: Boundary Wall | D18: 1 | E18: 1 | F18: 1 | G18: 1 | H18: 1 | I18: =SUMPRODUCT(D18:H18, D$2:H$2) -> 1
B19: L1 | C19: Basement Flooring Works | D19: 0.25 | E19: 0.25 | F19: 0.25 | G19: 0.25 | H19: 0.25 | I19: =SUMPRODUCT(D19:H19, D$2:H$2) -> 0.25
B20: L1 | C20: Basement Finishes | D20: 0 | E20: 0 | F20: 0 | G20: 0 | H20: 0 | I20: =SUMPRODUCT(D20:H20, D$2:H$2) -> 0
B21: L1 | C21: Boundary Wall Louvers | D21: 0.15 | E21: 0.15 | F21: 0.15 | G21: 0.15 | H21: 0.15 | I21: =SUMPRODUCT(D21:H21, D$2:H$2) -> 0.15
B22: L1 | C22: Paver Works | D22: 0.05 | E22: 0.05 | F22: 0.05 | G22: 0.05 | H22: 0.05 | I22: =SUMPRODUCT(D22:H22, D$2:H$2) -> 0.05
B23: L2 | C23: External Development-L2 | D23: =AVERAGE(D24:D32) -> 0.48888889 | E23: =AVERAGE(E24:E32) -> 0.44444444 | F23: =AVERAGE(F24:F32) -> 0.41111111 | G23: =AVERAGE(G24:G32) -> 0.33333333 | H23: =AVERAGE(H24:H32) -> 0.44444444 | I23: =SUMPRODUCT(D23:H23, D$2:H$2) -> 0.42944444
B24: L2 | C24: Courtyard Preparations | D24: 0.8 | E24: 0.6 | F24: 0.6 | G24: 0 | H24: 0.5 | I24: =SUMPRODUCT(D24:H24, D$2:H$2) -> 0.555
B25: L2 | C25: Courtyard Finishes | D25: 0.6 | E25: 0.4 | F25: 0.1 | G25: 0 | H25: 0.5 | I25: =SUMPRODUCT(D25:H25, D$2:H$2) -> 0.31
B26: L2 | C26: Sewer & Rainwater Line | D26: 0.8 | E26: 0.8 | F26: 0.8 | G26: 0.8 | H26: 0.8 | I26: =SUMPRODUCT(D26:H26, D$2:H$2) -> 0.8
B27: L2 | C27: Road Works | D27: 0.75 | E27: 0.75 | F27: 0.75 | G27: 0.75 | H27: 0.75 | I27: =SUMPRODUCT(D27:H27, D$2:H$2) -> 0.75
B28: L2 | C28: Boundary Wall | D28: 1 | E28: 1 | F28: 1 | G28: 1 | H28: 1 | I28: =SUMPRODUCT(D28:H28, D$2:H$2) -> 1
B29: L2 | C29: Basement Flooring Works | D29: 0.25 | E29: 0.25 | F29: 0.25 | G29: 0.25 | H29: 0.25 | I29: =SUMPRODUCT(D29:H29, D$2:H$2) -> 0.25
B30: L2 | C30: Basement Finishes | D30: 0 | E30: 0 | F30: 0 | G30: 0 | H30: 0 | I30: =SUMPRODUCT(D30:H30, D$2:H$2) -> 0
B31: L2 | C31: Boundary Wall Louvers | D31: 0.15 | E31: 0.15 | F31: 0.15 | G31: 0.15 | H31: 0.15 | I31: =SUMPRODUCT(D31:H31, D$2:H$2) -> 0.15
B32: L2 | C32: Paver Works | D32: 0.05 | E32: 0.05 | F32: 0.05 | G32: 0.05 | H32: 0.05 | I32: =SUMPRODUCT(D32:H32, D$2:H$2) -> 0.05

Sheet Roof top
B1: Tower | C1: Area | D1: MEP Work | E1: Ceiling | F1: Tile Work | G1: Paint Work | H1: Civil Finishes | I1: Pool Works | J1: MEP Fixtures | K1: MS Work | L1: Wood works | M1: Plantation | N1: Furniture | O1: Cleaning | P1: Progress %
C2: weightage | D2: 0.15 | E2: 0.02 | F2: 0.04 | G2: 0.04 | H2: 0.17 | I2: 0.2 | J2: 0.05 | K2: 0.08 | L2: 0.05 | M2: 0.05 | N2: 0.14 | O2: 0.01
B3: I | C3: I Tower Progress | D3: =D4*D2 -> 0.075 | E3: =E4*E2 -> 0 | F3: =F4*F2 -> 0 | G3: =G4*G2 -> 0 | H3: =H4*H2 -> 0.017 | I3: =I4*I2 -> 0.1 | J3: =J4*J2 -> 0 | K3: =K4*K2 -> 0 | ... O3: =O4*O2 -> 0.005 | P3: =SUM(D3:O3) -> 0.197
B4: I | C4: Roof Top-I | D4: 0.5 | E4: 0 | F4: 0 | G4: 0 | H4: 0.1 | I4: 0.5 | J4: 0 | K4: 0 | L4: 0 | M4: 0 | N4: 0 | O4: 0.5 | P4: =SUMPRODUCT(D4:O4, D$2:O$2) -> 0.197
B5: L1 | C5: L1 Tower Progress | D5: =D6*D2 -> 0 | E5: =E6*E2 -> 0 | F5: =F6*F2 -> 0 | G5: =G6*G2 -> 0 | H5: =H6*H2 -> 0 | I5: =I6*I2 -> 0 | J5: =J6*J2 -> 0 | K5: =K6*K2 -> 0 | ... O5: =O6*O2 -> 0 | P5: =SUM(D5:O5) -> 0
B6: L1 | C6: Roof Top-L1 | D6: 0 | E6: 0 | F6: 0 | G6: 0 | H6: 0 | I6: 0 | J6: 0 | K6: 0 | L6: 0 | M6: 0 | N6: 0 | O6: 0 | P6: =SUMPRODUCT(D6:O6, D$2:O$2) -> 0
B7: L2 | C7: L2 Tower Progress | D7: =D8*D2 -> 0 | E7: =E8*E2 -> 0 | F7: =F8*F2 -> 0 | G7: =G8*G2 -> 0 | H7: =H8*H2 -> 0 | I7: =I8*I2 -> 0 | J7: =J8*J2 -> 0 | K7: =K8*K2 -> 0 | ... O7: =O8*O2 -> 0 | P7: =SUM(D7:O7) -> 0
B8: L2 | C8: Roof top-L2 | D8: 0 | E8: 0 | F8: 0 | G8: 0 | H8: 0 | I8: 0 | J8: 0 | K8: 0 | L8: 0 | M8: 0 | N8: 0 | O8: 0 | P8: =SUMPRODUCT(D8:O8, D$2:O$2) -> 0

Sheet Common Area
B1: Tower | C1: Area | D1: Floor | E1: Civil Works | F1: MEP | G1: Finishes | H1: Cleaning | I1: Progress %
C2: weightage | E2: 0.2 | F2: 0.55 | G2: 0.2 | H2: 0.05
C3: Common Area-LCRG | E3: =((E4*0.4%)+(E18*0.3%)+(E31*0.3%))*100 -> 0.16336667 | F3: =((F4*0.4%)+(F18*0.3%)+(F31*0.3%))*100 -> 0.69106667 | G3: =((G4*0.4%)+(G18*0.3%)+(G31*0.3%))*100 -> 0.13255238 | H3: =((H4*0.4%)+(H18*0.3%)+(H31*0.3%))*100 -> 0.18512381 | I3: =((I4*0.4%)+(I18*0.3%)+(I31*0.3%))*100 -> 0.44852667
B4: I | C4: Common Area-I | E4: =(E5*65%+E9*35%) -> 0.34466667 | F4: =(F5*35%+F9*65%) -> 0.75266667 | G4: =(G5*40%+G9*60%) -> 0.22209524 | H4: =(H5*40%+H9*60%) -> 0.35352381 | I4: =SUMPRODUCT(E4:H4, E$2:H$2) -> 0.54499524
B5: I | C5: Civil Works-I | E5: =AVERAGE(E6:E8) -> 0.29333333 | F5: =AVERAGE(F6:F8) -> 0.29333333 | G5: =AVERAGE(G6:G8) -> 0.066666667 | H5: =AVERAGE(H6:H8) -> 0.26666667 | I5: =SUMPRODUCT(E5:H5, E$2:H$2) -> 0.24666667
B6: I | C6: Stairs Marble | D6: 1 | E6: 0.7 | F6: 0.7 | G6: 0.1 | H6: 0.7 | I6: =SUMPRODUCT(E6:H6, E$2:H$2) -> 0.58
B7: I | C7: Stairs Railing | D7: 1 | E7: 0 | F7: 0 | G7: 0 | H7: 0 | I7: =SUMPRODUCT(E7:H7, E$2:H$2) -> 0
B8: I | C8: Corridor | D8: 1 | E8: 0.18 | F8: 0.18 | G8: 0.1 | H8: 0.1 | I8: =SUMPRODUCT(E8:H8, E$2:H$2) -> 0.16
B9: I | C9: MEP Work-I | E9: =AVERAGE(E10:E16) -> 0.44 | F9: 1 | G9: =AVERAGE(G10:G16) -> 0.32571429 | H9: =AVERAGE(H10:H16) -> 0.41142857 | I9: =SUM(E9:H9)/400% -> 0.54428571
B10: I | C10: Lifts | D10: 1 | E10: 1 | F10: 0.35 | G10: 0.2 | H10: 0.8 | I10: =SUMPRODUCT(E10:H10, E$2:H$2) -> 0.4725
B11: I | C11: Corridor fixtures | D11: 1 | E11: 0.18 | F11: 0.18 | G11: 0.18 | H11: 0.18 | I11: =SUMPRODUCT(E11:H11, E$2:H$2) -> 0.18
B12: I | C12: MEP infrastructure | D12: 1 | E12: 1 | F12: 1 | G12: 1 | H12: 1 | I12: =SUMPRODUCT(E12:H12, E$2:H$2) -> 1
B13: I | C13: Generators | D13: 1 | E13: 0 | F13: 0 | G13: 0 | H13: 0 | I13: =SUMPRODUCT(E13:H13, E$2:H$2) -> 0
B14: I | C14: Transformers | D14: 1 | E14: 0.3 | F14: 0.3 | G14: 0.3 | H14: 0.3 | I14: =SUMPRODUCT(E14:H14, E$2:H$2) -> 0.3
B15: I | C15: BTD | D15: 1 | E15: 0.3 | F15: 0.3 | G15: 0.3 | H15: 0.3 | I15: =SUMPRODUCT(E15:H15, E$2:H$2) -> 0.3
B16: I | C16: Panels | D16: 1 | E16: 0.3 | F16: 0.3 | G16: 0.3 | H16: 0.3 | I16: =SUMPRODUCT(E16:H16, E$2:H$2) -> 0.3
B18: L1 | C18: Common Area-L1 | E18: =(E19*65%+E23*35%) -> 0.055 | F18: =(F19*35%+F23*65%) -> 0.65 | G18: =(G19*40%+G23*60%) -> 0.094285714 | H18: =(H19*40%+H23*60%) -> 0.094285714 | I18: =SUMPRODUCT(E18:H18, E$2:H$2) -> 0.39207143
B19: L1 | C19: Civil Work-L1 | E19: =AVERAGE(E20:E22) -> 0 | F19: =AVERAGE(F20:F22) -> 0 | G19: =AVERAGE(G20:G22) -> 0 | H19: =AVERAGE(H20:H22) -> 0 | I19: =SUMPRODUCT(E19:H19, E$2:H$2) -> 0
B20: L1 | C20: Stairs Marble | D20: 1 | E20: 0 | F20: 0 | G20: 0 | H20: 0 | I20: =SUMPRODUCT(E20:H20, E$2:H$2) -> 0
B21: L1 | C21: Stairs Railing | D21: 1 | E21: 0 | F21: 0 | G21: 0 | H21: 0 | I21: =SUMPRODUCT(E21:H21, E$2:H$2) -> 0
B22: L1 | C22: Corridor | D22: 1 | E22: 0 | F22: 0 | G22: 0 | H22: 0 | I22: =SUMPRODUCT(E22:H22, E$2:H$2) -> 0
B23: L1 | C23: MEP Work-L1 | E23: =AVERAGE(E24:E30) -> 0.15714286 | F23: 1 | G23: =AVERAGE(G24:G30) -> 0.15714286 | H23: =AVERAGE(H24:H30) -> 0.15714286 | I23: =SUM(E23:H23)/400% -> 0.36785714
B24: L1 | C24: Lifts | D24: 1 | E24: 0 | F24: 0 | G24: 0 | H24: 0 | I24: =SUMPRODUCT(E24:H24, E$2:H$2) -> 0
B25: L1 | C25: Corridor fixtures | D25: 1 | E25: 0 | F25: 0 | G25: 0 | H25: 0 | I25: =SUMPRODUCT(E25:H25, E$2:H$2) -> 0
B26: L1 | C26: MEP infrastructure | D26: 1 | E26: 0.5 | F26: 0.5 | G26: 0.5 | H26: 0.5 | I26: =SUMPRODUCT(E26:H26, E$2:H$2) -> 0.5
B27: L1 | C27: Generators | D27: 1 | E27: 0 | F27: 0 | G27: 0 | H27: 0 | I27: =SUMPRODUCT(E27:H27, E$2:H$2) -> 0
B28: L1 | C28: Transformers | D28: 1 | E28: 0.3 | F28: 0.3 | G28: 0.3 | H28: 0.3 | I28: =SUMPRODUCT(E28:H28, E$2:H$2) -> 0.3
B29: L1 | C29: BTD | D29: 1 | E29: 0 | F29: 0 | G29: 0 | H29: 0 | I29: =SUMPRODUCT(E29:H29, E$2:H$2) -> 0
B30: L1 | C30: Panels | D30: 1 | E30: 0.3 | F30: 0.3 | G30: 0.3 | H30: 0.3 | I30: =SUMPRODUCT(E30:H30, E$2:H$2) -> 0.3
B31: L2 | C31: Common Area-L2 | E31: =(E32*65%+E36*35%) -> 0.03 | F31: =(F32*35%+F36*65%) -> 0.65 | G31: =(G32*40%+G36*60%) -> 0.051428571 | H31: =(H32*40%+H36*60%) -> 0.051428571 | I31: =SUMPRODUCT(E31:H31, E$2:H$2) -> 0.37635714
B32: L2 | C32: Civil Works -L2 | E32: =AVERAGE(E33:E35) -> 0 | F32: =AVERAGE(F33:F35) -> 0 | G32: =AVERAGE(G33:G35) -> 0 | H32: =AVERAGE(H33:H35) -> 0 | I32: =SUMPRODUCT(E32:H32, E$2:H$2) -> 0
B33: L2 | C33: Stairs Marble | D33: 1 | E33: 0 | F33: 0 | G33: 0 | H33: 0 | I33: =SUMPRODUCT(E33:H33, E$2:H$2) -> 0
B34: L2 | C34: Stairs Railing | D34: 1 | E34: 0 | F34: 0 | G34: 0 | H34: 0 | I34: =SUMPRODUCT(E34:H34, E$2:H$2) -> 0
B35: L2 | C35: Corridor | D35: 1 | E35: 0 | F35: 0 | G35: 0 | H35: 0 | I35: =SUMPRODUCT(E35:H35, E$2:H$2) -> 0
B36: L2 | C36: MEP Work-L2 | E36: =AVERAGE(E37:E43) -> 0.085714286 | F36: 1 | G36: =AVERAGE(G37:G43) -> 0.085714286 | H36: =AVERAGE(H37:H43) -> 0.085714286 | I36: =SUM(E36:H36)/400% -> 0.31428571
B37: L2 | C37: Lifts | D37: 1 | E37: 0 | F37: 0 | G37: 0 | H37: 0 | I37: =SUMPRODUCT(E37:H37, E$2:H$2) -> 0
B38: L2 | C38: Corridor fixtures | D38: 1 | E38: 0 | F38: 0 | G38: 0 | H38: 0 | I38: =SUMPRODUCT(E38:H38, E$2:H$2) -> 0
B39: L2 | C39: MEP infrastructure | D39: 1 | E39: 0 | F39: 0 | G39: 0 | H39: 0 | I39: =SUMPRODUCT(E39:H39, E$2:H$2) -> 0
B40: L2 | C40: Generators | D40: 1 | E40: 0 | F40: 0 | G40: 0 | H40: 0 | I40: =SUMPRODUCT(E40:H40, E$2:H$2) -> 0
B41: L2 | C41: Transformers | D41: 1 | E41: 0.3 | F41: 0.3 | G41: 0.3 | H41: 0.3 | I41: =SUMPRODUCT(E41:H41, E$2:H$2) -> 0.3
...

Sheet Work Progress (%)
I1: 12
C2: MEP Work | H2: Celing | M2: Tiles Works | Q2: Bath Floors Tiles | U2: Bath Walls Tiles | Z2: Paint Works | AE2: Alluminium Window Work | AJ2: Balcony | AM2: Wood Works | AR2: Fi0%tures | AW2: Corridor Works
C3: Elec Work | D3: Plumb Works | E3: Plasterworks | F3: AC Copper | H3: BED 1+Bath | I3: Lounge | J3: Kitchen | K3: BED 2+Bath | M3: BED LEFT | N3: LOUNGE | O3: KITCHEN | P3: BED 2+Bath | Q3: 1 | R3: 2 | S3: 3 | T3: 4 | U3: 1 | V3: 2 | W3: 3 | X3: 4 | Z3: BED 1+Bath | AA3: LOUNGE | AB3: KITCHEN | AC3: BED 2+Bath | AE3: Marble Sills | AF3: BED 1+Bath | AG3: LOUNGE | AH3: BED 2+Bath | AJ3: Tiles | AK3: Celing +Paint | AM3: LEFT BED | AN3: KITCHEN | AO3: BED 2+BATH | AP3: DOORS | AR3: Lighting | AS3: Plumbing | AT3: Kitchen | AU3: Switch Socket | AW3: Tiles | AX3: Ceiling | AY3: Finishes | BA3: Railing | BB3: Louvers | BC3: Fi0%tures+Paints
C4: 2 | D4: 4 | E4: 1 | F4: 2 | H4: =I1*0.16 -> 1.92 | I4: =I1*0.28 -> 3.36 | J4: =I1*0.14 -> 1.68 | K4: =I1*0.16 -> 1.92 | AK4: =I1*0.07 -> 0.84 | AX4: =I1*0.12 -> 1.44
AM8: =NOW() -> 46010.869
B9: Work Status For I Tower
B10: First Floor
C11: Approved Items | BG11: Target Time passed.
C12: MEP Work | H12: Celing | L12: Ceiling % | M12: Tiles Works | Q12: Bath Floors Tiles | U12: Bath Walls Tiles | Y12: Tile Work % | Z12: Paint Works | AD12: Paint % | AE12: Alluminium Window Work | AI12: Alumin % | AJ12: Balcony | AM12: Wood Works | AQ12: Wood % | AR12: Fixtures | AV12: Fixture % | AW12: Corridor Works | AZ12: Over All % | BA12: MS Works | BD12: Overall %
B13: Appartment Number | C13: Elec Work | D13: Plumb Works | E13: Plasterworks | F13: LPG works | H13: BED 1+Bath | I13: Lounge | J13: Kitchen | K13: BED 2+Bath | M13: BED LEFT | N13: LOUNGE | O13: KITCHEN | P13: BED 2+Bath | Q13: 1 | R13: 2 | S13: 3 | T13: 4 | U13: 1 | V13: 2 | W13: 3 | X13: 4 | Z13: BED 1+Bath | AA13: LOUNGE | AB13: KITCHEN | AC13: BED 2+Bath | AE13: Marble Sills | AF13: BED 1+Bath | AG13: LOUNGE | AH13: BED 2+Bath | AJ13: Tiles | AK13: Celing +Paint | AM13: LEFT BED | AN13: KITCHEN | AO13: BED 2+BATH | AP13: DOORS | AR13: Lighting | AS13: Plumbing | AT13: Kitchen | AU13: Switch Socket | AW13: Tiles | AX13: Ceiling | AY13: Finishes | BA13: Railing | BB13: Louvers | BC13: Fixtures+Paints | BF13: Readiness % | BG13: REMARKS
B14: 101 | C14: 1 | D14: 1 | E14: 1 | F14: 1 | G14: =C14*45% + D14*45% + E14*5% + F14*5% -> 1 | H14: 1 | I14: 1 | J14: 1 | K14: 1 | L14: =H14*30% + I14*30% + J14*10% + K14*30% -> 1 | M14: 1 | N14: 1 | O14: 1 | P14: 1 | Q14: 1 | R14: 1 | S14: 1 | T14: 0 | U14: 1 | V14: 1 | W14: 1 | X14: 0 | Y14: =(U14*10% + V14*10% + W14*10% + X14*10%+ Q14*5% + R14*5% + S14*5% + T14*5%+M14*10% + N14*15% + O14*5% + P14*10%)/0.85 -> 1 | Z14: 0.7 | AA14: 0.7 | AB14: 0.7 | AC14: 0.7 | AD14: =Z14*45% + AA14*45% + AB14*5% + AC14*5% -> 0.7 | AE14: 1 | AF14: 0.5 | AG14: 1 | AH14: 0 | AI14: =AE14*5% + AF14*30% + AG14*35% + AH14*30% -> 0.55 | AJ14: 1 | AK14: 1 | AM14: 1 | AN14: 1 | AO14: 0 | AP14: 0.95 | AQ14: =AM14*15% + AN14*35% + AO14*15% + AP14*35% -> 0.8325 | AR14: 1 | AS14: 0.5 | AT14: 0 | AU14: 1 | AV14: =AR14*30% + AS14*30% + AT14*15% + AU14*25% -> 0.7 | AW14: 1 | AX14: 0.8 | AY14: 0 | AZ14: =AW14*30% + AX14*45% + AY14*25% -> 0.66 | BA14: 0 | BB14: 0 | BC14: 0 | BD14: =BA14*30% + BB14*45% + BC14*25% -> 0 | BF14: =( (COUNTIF(B14:E14,"✓")/(COUNTIF(B14:E14,"✓")+COUNTIF(B14:E14,"x")))*0.2 + (COUNTIF(F14:J14,"✓")/(COUNTIF(F14:J14,"✓")+COUNTIF(F14:J14,"x")))*0.15+ (COUNTIF(K14:O14,"✓")/(COUNTIF(K14:O14,"✓")+COUNTIF(K14:O14,"x")))*0.05 + (COUNTIF(P14:S14,"✓")/(COUNTIF(P14:S14,"✓")+COUNTIF(P14:S14,"x")))*0.1 + (COUNTIF(T14:W14,"✓")/(COUNTIF(T14:W14,"✓")+COUNTIF(T14:W14,"x")))*0.1 + (COUNTIF(X14:AB14,"✓")/(COUNTIF(X14:AB14,"✓")+COUNTIF(X14:AB14,"x")))*0.1 + (COUNTIF(AC14:AO14,"✓")/(COUNTIF(AC14:AO14,"✓")+COUNTIF(AC14:AO14,"x")))*0.1 + (COUNTIF(AP14:AT14,"✓")/(COUNTIF(AP14:AT14,"✓")+COUNTIF(AP14:AT14,"x")))*0.05 + (COUNTIF(AU14:BB14,"✓")/(COUNTIF(AU14:BB14,"✓")+COUNTIF(AU14:BB14,"x")))*0.1 + (COUNTIF(BC14:BC14,"✓")/(COUNTIF(BC14:BC14,"✓")+COUNTIF(BC14:BC14,"x")))*0.05 ) -> #DIV/0!
B15: 102 | C15: 1 | D15: 1 | E15: 1 | F15: 1 | G15: =C15*45% + D15*45% + E15*5% + F15*5% -> 1 | H15: 1 | I15: 1 | J15: 1 | K15: 1 | L15: =H15*30% + I15*30% + J15*10% + K15*30% -> 1 | M15: 1 | N15: 1 | O15: 1 | P15: 1 | Q15: 1 | R15: 1 | S15: 1 | T15: 1 | U15: 1 | V15: 1 | W15: 1 | X15: 1 | Y15: =(U15*10% + V15*10% + W15*10% + X15*10%+ Q15*5% + R15*5% + S15*5% + T15*5%+M15*10% + N15*15% + O15*5% + P15*10%) -> 1 | Z15: 0.7 | AA15: 0.7 | AB15: 0.7 | AC15: 0.7 | AD15: =Z15*45% + AA15*45% + AB15*5% + AC15*5% -> 0.7 | AE15: 0.7 | AF15: 1 | AG15: 1 | AH15: 0 | AI15: =AE15*5% + AF15*30% + AG15*35% + AH15*30% -> 0.685 | AJ15: 1 | AK15: 1 | AM15: 1 | AN15: 1 | AO15: 1 | AP15: 0.95 | AQ15: =AM15*15% + AN15*35% + AO15*15% + AP15*35% -> 0.9825 | AR15: 1 | AS15: 0.5 | AT15: 0 | AU15: 1 | AV15: =AR15*30% + AS15*30% + AT15*15% + AU15*25% -> 0.7 | AW15: 1 | AX15: 0.8 | AY15: 0 | AZ15: =AW15*30% + AX15*45% + AY15*25% -> 0.66 | BA15: 0 | BB15: 0 | BC15: 0 | BD15: =BA15*30% + BB15*45% + BC15*25% -> 0 | BF15: =( (COUNTIF(B15:E15,"✓")/(COUNTIF(B15:E15,"✓")+COUNTIF(B15:E15,"x")))*0.2 + (COUNTIF(F15:J15,"✓")/(COUNTIF(F15:J15,"✓")+COUNTIF(F15:J15,"x")))*0.15+ (COUNTIF(K15:O15,"✓")/(COUNTIF(K15:O15,"✓")+COUNTIF(K15:O15,"x")))*0.05 + (COUNTIF(P15:S15,"✓")/(COUNTIF(P15:S15,"✓")+COUNTIF(P15:S15,"x")))*0.1 + (COUNTIF(T15:W15,"✓")/(COUNTIF(T15:W15,"✓")+COUNTIF(T15:W15,"x")))*0.1 + (COUNTIF(X15:AB15,"✓")/(COUNTIF(X15:AB15,"✓")+COUNTIF(X15:AB15,"x")))*0.1 + (COUNTIF(AC15:AO15,"✓")/(COUNTIF(AC15:AO15,"✓")+COUNTIF(AC15:AO15,"x")))*0.1 + (COUNTIF(AP15:AT15,"✓")/(COUNTIF(AP15:AT15,"✓")+COUNTIF(AP15:AT15,"x")))*0.05 + (COUNTIF(AU15:BB15,"✓")/(COUNTIF(AU15:BB15,"✓")+COUNTIF(AU15:BB15,"x")))*0.1 + (COUNTIF(BC15:BC15,"✓")/(COUNTIF(BC15:BC15,"✓")+COUNTIF(BC15:BC15,"x")))*0.05 ) -> #DIV/0!
B16: 103 | C16: 1 | D16: 1 | E16: 1 | F16: 1 | G16: =C16*45% + D16*45% + E16*5% + F16*5% -> 1 | H16: 1 | I16: 1 | J16: 1 | K16: 1 | L16: =H16*30% + I16*30% + J16*10% + K16*30% -> 1 | M16: 1 | N16: 1 | O16: 1 | P16: 1 | Q16: 1 | R16: 1 | S16: 1 | T16: 1 | U16: 1 | V16: 1 | W16: 1 | X16: 1 | Y16: =(U16*10% + V16*10% + W16*10% + X16*10%+ Q16*5% + R16*5% + S16*5% + T16*5%+M16*10% + N16*15% + O16*5% + P16*10%) -> 1 | Z16: 0.7 | AA16: 0.7 | AB16: 0.7 | AC16: 0.7 | AD16: =Z16*45% + AA16*45% + AB16*5% + AC16*5% -> 0.7 | AE16: 1 | AF16: 1 | AG16: 1 | AH16: 1 | AI16: =AE16*5% + AF16*30% + AG16*35% + AH16*30% -> 1 | AJ16: 1 | AK16: 1 | AM16: 1 | AN16: 1 | AO16: 1 | AP16: 0.95 | AQ16: =AM16*15% + AN16*35% + AO16*15% + AP16*35% -> 0.9825 | AR16: 1 | AS16: 0.5 | AT16: 0 | AU16: 1 | AV16: =AR16*30% + AS16*30% + AT16*15% + AU16*25% -> 0.7 | AW16: 1 | AX16: 0.8 | AY16: 0 | AZ16: =AW16*30% + AX16*45% + AY16*25% -> 0.66 | BA16: 0 | BB16: 0 | BC16: 0 | BD16: =BA16*30% + BB16*45% + BC16*25% -> 0 | BF16: =( (COUNTIF(B16:E16,"✓")/(COUNTIF(B16:E16,"✓")+COUNTIF(B16:E16,"x")))*0.2 + (COUNTIF(F16:J16,"✓")/(COUNTIF(F16:J16,"✓")+COUNTIF(F16:J16,"x")))*0.15+ (COUNTIF(K16:O16,"✓")/(COUNTIF(K16:O16,"✓")+COUNTIF(K16:O16,"x")))*0.05 + (COUNTIF(P16:S16,"✓")/(COUNTIF(P16:S16,"✓")+COUNTIF(P16:S16,"x")))*0.1 + (COUNTIF(T16:W16,"✓")/(COUNTIF(T16:W16,"✓")+COUNTIF(T16:W16,"x")))*0.1 + (COUNTIF(X16:AB16,"✓")/(COUNTIF(X16:AB16,"✓")+COUNTIF(X16:AB16,"x")))*0.1 + (COUNTIF(AC16:AO16,"✓")/(COUNTIF(AC16:AO16,"✓")+COUNTIF(AC16:AO16,"x")))*0.1 + (COUNTIF(AP16:AT16,"✓")/(COUNTIF(AP16:AT16,"✓")+COUNTIF(AP16:AT16,"x")))*0.05 + (COUNTIF(AU16:BB16,"✓")/(COUNTIF(AU16:BB16,"✓")+COUNTIF(AU16:BB16,"x")))*0.1 + (COUNTIF(BC16:BC16,"✓")/(COUNTIF(BC16:BC16,"✓")+COUNTIF(BC16:BC16,"x")))*0.05 ) -> #DIV/0!
B17: 104 | C17: 1 | D17: 1 | E17: 1 | F17: 1 | G17: =C17*45% + D17*45% + E17*5% + F17*5% -> 1 | H17: 1 | I17: 1 | J17: 1 | K17: 1 | L17: =H17*30% + I17*30% + J17*10% + K17*30% -> 1 | M17: 1 | N17: 1 | O17: 1 | P17: 1 | Q17: 1 | R17: 1 | S17: 1 | T17: 1 | U17: 1 | V17: 1 | W17: 1 | X17: 1 | Y17: =(U17*10% + V17*10% + W17*10% + X17*10%+ Q17*5% + R17*5% + S17*5% + T17*5%+M17*10% + N17*15% + O17*5% + P17*10%) -> 1 | Z17: 0.5 | AA17: 0.5 | AB17: 0.5 | AC17: 0.5 | AD17: =Z17*45% + AA17*45% + AB17*5% + AC17*5% -> 0.5 | AE17: 0.9 | AF17: 1 | AG17: 1 | AH17: 0 | AI17: =AE17*5% + AF17*30% + AG17*35% + AH17*30% -> 0.695 | AJ17: 1 | AK17: 1 | AM17: 1 | AN17: 1 | AO17: 1 | AP17: 0.95 | AQ17: =AM17*15% + AN17*35% + AO17*15% + AP17*35% -> 0.9825 | AR17: 1 | AS17: 0.5 | AT17: 0 | AU17: 1 | AV17: =AR17*30% + AS17*30% + AT17*15% + AU17*25% -> 0.7 | AW17: 1 | AX17: 0.8 | AY17: 0 | AZ17: =AW17*30% + AX17*45% + AY17*25% -> 0.66 | BA17: 0 | BB17: 0 | BC17: 0 | BD17: =BA17*30% + BB17*45% + BC17*25% -> 0 | BF17: =( (COUNTIF(B17:E17,"✓")/(COUNTIF(B17:E17,"✓")+COUNTIF(B17:E17,"x")))*0.2 + (COUNTIF(F17:J17,"✓")/(COUNTIF(F17:J17,"✓")+COUNTIF(F17:J17,"x")))*0.15+ (COUNTIF(K17:O17,"✓")/(COUNTIF(K17:O17,"✓")+COUNTIF(K17:O17,"x")))*0.05 + (COUNTIF(P17:S17,"✓")/(COUNTIF(P17:S17,"✓")+COUNTIF(P17:S17,"x")))*0.1 + (COUNTIF(T17:W17,"✓")/(COUNTIF(T17:W17,"✓")+COUNTIF(T17:W17,"x")))*0.1 + (COUNTIF(X17:AB17,"✓")/(COUNTIF(X17:AB17,"✓")+COUNTIF(X17:AB17,"x")))*0.1 + (COUNTIF(AC17:AO17,"✓")/(COUNTIF(AC17:AO17,"✓")+COUNTIF(AC17:AO17,"x")))*0.1 + (COUNTIF(AP17:AT17,"✓")/(COUNTIF(AP17:AT17,"✓")+COUNTIF(AP17:AT17,"x")))*0.05 + (COUNTIF(AU17:BB17,"✓")/(COUNTIF(AU17:BB17,"✓")+COUNTIF(AU17:BB17,"x")))*0.1 + (COUNTIF(BC17:BC17,"✓")/(COUNTIF(BC17:BC17,"✓")+COUNTIF(BC17:BC17,"x")))*0.05 ) -> #DIV/0!
B18: 105 | C18: 1 | D18: 1 | E18: 1 | F18: 1 | G18: =C18*45% + D18*45% + E18*5% + F18*5% -> 1 | H18: 1 | I18: 1 | J18: 1 | K18: 1 | L18: =H18*30% + I18*30% + J18*10% + K18*30% -> 1 | M18: 1 | N18: 1 | O18: 1 | P18: 1 | Q18: 1 | R18: 1 | S18: 1 | T18: 1 | U18: 1 | V18: 1 | W18: 1 | X18: 1 | Y18: =(U18*10% + V18*10% + W18*10% + X18*10%+ Q18*5% + R18*5% + S18*5% + T18*5%+M18*10% + N18*15% + O18*5% + P18*10%) -> 1 | Z18: 0.7 | AA18: 0.7 | AB18: 0.7 | AC18: 0.7 | AD18: =Z18*45% + AA18*45% + AB18*5% + AC18*5% -> 0.7 | AE18: 1 | AF18: 0.7 | AG18: 0.9 | AH18: 0.7 | AI18: =AE18*5% + AF18*30% + AG18*35% + AH18*30% -> 0.785 | AJ18: 1 | AK18: 1 | AM18: 1 | AN18: 1 | AO18: 1 | AP18: 0.95 | AQ18: =AM18*15% + AN18*35% + AO18*15% + AP18*35% -> 0.9825 | AR18: 1 | AS18: 0.5 | AT18: 0 | AU18: 1 | AV18: =AR18*30% + AS18*30% + AT18*15% + AU18*25% -> 0.7 | AW18: 1 | AX18: 0.8 | AY18: 0 | AZ18: =AW18*30% + AX18*45% + AY18*25% -> 0.66 | BA18: 0 | BB18: 0 | BC18: 0 | BD18: =BA18*30% + BB18*45% + BC18*25% -> 0 | BF18: =( (COUNTIF(B18:E18,"✓")/(COUNTIF(B18:E18,"✓")+COUNTIF(B18:E18,"x")))*0.2 + (COUNTIF(F18:J18,"✓")/(COUNTIF(F18:J18,"✓")+COUNTIF(F18:J18,"x")))*0.15+ (COUNTIF(K18:O18,"✓")/(COUNTIF(K18:O18,"✓")+COUNTIF(K18:O18,"x")))*0.05 + (COUNTIF(P18:S18,"✓")/(COUNTIF(P18:S18,"✓")+COUNTIF(P18:S18,"x")))*0.1 + (COUNTIF(T18:W18,"✓")/(COUNTIF(T18:W18,"✓")+COUNTIF(T18:W18,"x")))*0.1 + (COUNTIF(X18:AB18,"✓")/(COUNTIF(X18:AB18,"✓")+COUNTIF(X18:AB18,"x")))*0.1 + (COUNTIF(AC18:AO18,"✓")/(COUNTIF(AC18:AO18,"✓")+COUNTIF(AC18:AO18,"x")))*0.1 + (COUNTIF(AP18:AT18,"✓")/(COUNTIF(AP18:AT18,"✓")+COUNTIF(AP18:AT18,"x")))*0.05 + (COUNTIF(AU18:BB18,"✓")/(COUNTIF(AU18:BB18,"✓")+COUNTIF(AU18:BB18,"x")))*0.1 + (COUNTIF(BC18:BC18,"✓")/(COUNTIF(BC18:BC18,"✓")+COUNTIF(BC18:BC18,"x")))*0.05 ) -> #DIV/0!
B19: 106 | C19: 1 | D19: 1 | E19: 1 | F19: 1 | G19: =C19*45% + D19*45% + E19*5% + F19*5% -> 1 | H19: 1 | I19: 1 | J19: 1 | K19: 1 | L19: =H19*30% + I19*30% + J19*10% + K19*30% -> 1 | M19: 1 | N19: 1 | O19: 1 | P19: 1 | Q19: 1 | R19: 1 | S19: 1 | T19: 1 | U19: 1 | V19: 1 | W19: 1 | X19: 1 | Y19: =(U19*10% + V19*10% + W19*10% + X19*10%+ Q19*5% + R19*5% + S19*5% + T19*5%+M19*10% + N19*15% + O19*5% + P19*10%) -> 1 | Z19: 0.7 | AA19: 0.7 | AB19: 0.7 | AC19: 0.7 | AD19: =Z19*45% + AA19*45% + AB19*5% + AC19*5% -> 0.7 | AE19: 1 | AF19: 1 | AG19: 1 | AH19: 1 | AI19: =AE19*5% + AF19*30% + AG19*35% + AH19*30% -> 1 | AJ19: 1 | AK19: 1 | AM19: 1 | AN19: 1 | AO19: 1 | AP19: 0.95 | AQ19: =AM19*15% + AN19*35% + AO19*15% + AP19*35% -> 0.9825 | AR19: 1 | AS19: 0.5 | AT19: 1 | AU19: 1 | AV19: =AR19*30% + AS19*30% + AT19*15% + AU19*25% -> 0.85 | AW19: 1 | AX19: 0.8 | AY19: 0 | AZ19: =AW19*30% + AX19*45% + AY19*25% -> 0.66 | BA19: 0 | BB19: 0 | BC19: 0 | BD19: =BA19*30% + BB19*45% + BC19*25% -> 0 | BF19: =( (COUNTIF(B19:E19,"✓")/(COUNTIF(B19:E19,"✓")+COUNTIF(B19:E19,"x")))*0.2 + (COUNTIF(F19:J19,"✓")/(COUNTIF(F19:J19,"✓")+COUNTIF(F19:J19,"x")))*0.15+ (COUNTIF(K19:O19,"✓")/(COUNTIF(K19:O19,"✓")+COUNTIF(K19:O19,"x")))*0.05 + (COUNTIF(P19:S19,"✓")/(COUNTIF(P19:S19,"✓")+COUNTIF(P19:S19,"x")))*0.1 + (COUNTIF(T19:W19,"✓")/(COUNTIF(T19:W19,"✓")+COUNTIF(T19:W19,"x")))*0.1 + (COUNTIF(X19:AB19,"✓")/(COUNTIF(X19:AB19,"✓")+COUNTIF(X19:AB19,"x")))*0.1 + (COUNTIF(AC19:AO19,"✓")/(COUNTIF(AC19:AO19,"✓")+COUNTIF(AC19:AO19,"x")))*0.1 + (COUNTIF(AP19:AT19,"✓")/(COUNTIF(AP19:AT19,"✓")+COUNTIF(AP19:AT19,"x")))*0.05 + (COUNTIF(AU19:BB19,"✓")/(COUNTIF(AU19:BB19,"✓")+COUNTIF(AU19:BB19,"x")))*0.1 + (COUNTIF(BC19:BC19,"✓")/(COUNTIF(BC19:BC19,"✓")+COUNTIF(BC19:BC19,"x")))*0.05 ) -> #DIV/0!
B20: 107 | C20: 1 | D20: 1 | E20: 1 | F20: 1 | G20: =C20*45% + D20*45% + E20*5% + F20*5% -> 1 | H20: 1 | I20: 1 | J20: 1 | K20: 1 | L20: =H20*30% + I20*30% + J20*10% + K20*30% -> 1 | M20: 1 | N20: 1 | O20: 1 | P20: 1 | Q20: 1 | R20: 1 | S20: 1 | T20: 1 | U20: 1 | V20: 1 | W20: 1 | X20: 1 | Y20: =(U20*10% + V20*10% + W20*10% + X20*10%+ Q20*5% + R20*5% + S20*5% + T20*5%+M20*10% + N20*15% + O20*5% + P20*10%) -> 1 | Z20: 0.7 | AA20: 0.7 | AB20: 0.7 | AC20: 0.7 | AD20: =Z20*45% + AA20*45% + AB20*5% + AC20*5% -> 0.7 | AE20: 1 | AF20: 1 | AG20: 1 | AH20: 1 | AI20: =AE20*5% + AF20*30% + AG20*35% + AH20*30% -> 1 | AJ20: 1 | AK20: 0 | AM20: 1 | AN20: 1 | AO20: 1 | AP20: 0.95 | AQ20: =AM20*15% + AN20*35% + AO20*15% + AP20*35% -> 0.9825 | AR20: 1 | AS20: 0.5 | AT20: 0 | AU20: 1 | AV20: =AR20*30% + AS20*30% + AT20*15% + AU20*25% -> 0.7 | AW20: 1 | AX20: 0.35 | AY20: 0 | AZ20: =AW20*30% + AX20*45% + AY20*25% -> 0.4575 | BA20: 0 | BB20: 0 | BC20: 0 | BD20: =BA20*30% + BB20*45% + BC20*25% -> 0 | BF20: =( (COUNTIF(B20:E20,"✓")/(COUNTIF(B20:E20,"✓")+COUNTIF(B20:E20,"x")))*0.2 + (COUNTIF(F20:J20,"✓")/(COUNTIF(F20:J20,"✓")+COUNTIF(F20:J20,"x")))*0.15+ (COUNTIF(K20:O20,"✓")/(COUNTIF(K20:O20,"✓")+COUNTIF(K20:O20,"x")))*0.05 + (COUNTIF(P20:S20,"✓")/(COUNTIF(P20:S20,"✓")+COUNTIF(P20:S20,"x")))*0.1 + (COUNTIF(T20:W20,"✓")/(COUNTIF(T20:W20,"✓")+COUNTIF(T20:W20,"x")))*0.1 + (COUNTIF(X20:AB20,"✓")/(COUNTIF(X20:AB20,"✓")+COUNTIF(X20:AB20,"x")))*0.1 + (COUNTIF(AC20:AO20,"✓")/(COUNTIF(AC20:AO20,"✓")+COUNTIF(AC20:AO20,"x")))*0.1 + (COUNTIF(AP20:AT20,"✓")/(COUNTIF(AP20:AT20,"✓")+COUNTIF(AP20:AT20,"x")))*0.05 + (COUNTIF(AU20:BB20,"✓")/(COUNTIF(AU20:BB20,"✓")+COUNTIF(AU20:BB20,"x")))*0.1 + (COUNTIF(BC20:BC20,"✓")/(COUNTIF(BC20:BC20,"✓")+COUNTIF(BC20:BC20,"x")))*0.05 ) -> #DIV/0!
B21: 108 | C21: 1 | D21: 1 | E21: 1 | F21: 1 | G21: =C21*45% + D21*45% + E21*5% + F21*5% -> 1 | H21: 1 | I21: 1 | J21: 1 | K21: 1 | L21: =H21*30% + I21*30% + J21*10% + K21*30% -> 1 | M21: 1 | N21: 1 | O21: 1 | P21: 1 | Q21: 1 | R21: 1 | S21: 1 | T21: 1 | U21: 1 | V21: 1 | W21: 1 | X21: 1 | Y21: =(U21*10% + V21*10% + W21*10% + X21*10%+ Q21*5% + R21*5% + S21*5% + T21*5%+M21*10% + N21*15% + O21*5% + P21*10%) -> 1 | Z21: 0.8 | AA21: 0.8 | AB21: 0.8 | AC21: 0.8 | AD21: =Z21*45% + AA21*45% + AB21*5% + AC21*5% -> 0.8 | AE21: 1 | AF21: 1 | AG21: 1 | AH21: 1 | AI21: =AE21*5% + AF21*30% + AG21*35% + AH21*30% -> 1 | AJ21: 1 | AK21: 1 | AM21: 1 | AN21: 1 | AO21: 1 | AP21: 0.95 | AQ21: =AM21*15% + AN21*35% + AO21*15% + AP21*35% -> 0.9825 | AR21: 1 | AS21: 0.5 | AT21: 1 | AU21: 1 | AV21: =AR21*30% + AS21*30% + AT21*15% + AU21*25% -> 0.85 | AW21: 1 | AX21: 0.35 | AY21: 0 | AZ21: =AW21*30% + AX21*45% + AY21*25% -> 0.4575 | BA21: 0 | BB21: 0 | BC21: 0 | BD21: =BA21*30% + BB21*45% + BC21*25% -> 0 | BF21: =( (COUNTIF(B21:E21,"✓")/(COUNTIF(B21:E21,"✓")+COUNTIF(B21:E21,"x")))*0.2 + (COUNTIF(F21:J21,"✓")/(COUNTIF(F21:J21,"✓")+COUNTIF(F21:J21,"x")))*0.15+ (COUNTIF(K21:O21,"✓")/(COUNTIF(K21:O21,"✓")+COUNTIF(K21:O21,"x")))*0.05 + (COUNTIF(P21:S21,"✓")/(COUNTIF(P21:S21,"✓")+COUNTIF(P21:S21,"x")))*0.1 + (COUNTIF(T21:W21,"✓")/(COUNTIF(T21:W21,"✓")+COUNTIF(T21:W21,"x")))*0.1 + (COUNTIF(X21:AB21,"✓")/(COUNTIF(X21:AB21,"✓")+COUNTIF(X21:AB21,"x")))*0.1 + (COUNTIF(AC21:AO21,"✓")/(COUNTIF(AC21:AO21,"✓")+COUNTIF(AC21:AO21,"x")))*0.1 + (COUNTIF(AP21:AT21,"✓")/(COUNTIF(AP21:AT21,"✓")+COUNTIF(AP21:AT21,"x")))*0.05 + (COUNTIF(AU21:BB21,"✓")/(COUNTIF(AU21:BB21,"✓")+COUNTIF(AU21:BB21,"x")))*0.1 + (COUNTIF(BC21:BC21,"✓")/(COUNTIF(BC21:BC21,"✓")+COUNTIF(BC21:BC21,"x")))*0.05 ) -> #DIV/0!
B22: 109 | C22: 1 | D22: 1 | E22: 1 | F22: 1 | G22: =C22*45% + D22*45% + E22*5% + F22*5% -> 1 | H22: 1 | I22: 1 | J22: 1 | K22: 1 | L22: =H22*30% + I22*30% + J22*10% + K22*30% -> 1 | M22: 1 | N22: 1 | O22: 1 | P22: 1 | Q22: 1 | R22: 1 | S22: 1 | T22: 1 | U22: 1 | V22: 1 | W22: 1 | X22: 1 | Y22: =(U22*10% + V22*10% + W22*10% + X22*10%+ Q22*5% + R22*5% + S22*5% + T22*5%+M22*10% + N22*15% + O22*5% + P22*10%) -> 1 | Z22: 0.7 | AA22: 0.7 | AB22: 0.7 | AC22: 0.7 | AD22: =Z22*45% + AA22*45% + AB22*5% + AC22*5% -> 0.7 | AE22: 1 | AF22: 1 | AG22: 1 | AH22: 1 | AI22: =AE22*5% + AF22*30% + AG22*35% + AH22*30% -> 1 | AJ22: 1 | AK22: 1 | AM22: 1 | AN22: 1 | AO22: 1 | AP22: 0.95 | AQ22: =AM22*15% + AN22*35% + AO22*15% + AP22*35% -> 0.9825 | AR22: 1 | AS22: 0.5 | AT22: 0 | AU22: 1 | AV22: =AR22*30% + AS22*30% + AT22*15% + AU22*25% -> 0.7 | AW22: 1 | AX22: 0.35 | AY22: 0 | AZ22: =AW22*30% + AX22*45% + AY22*25% -> 0.4575 | BA22: 0 | BB22: 0 | BC22: 0 | BD22: =BA22*30% + BB22*45% + BC22*25% -> 0 | BF22: =( (COUNTIF(B22:E22,"✓")/(COUNTIF(B22:E22,"✓")+COUNTIF(B22:E22,"x")))*0.2 + (COUNTIF(F22:J22,"✓")/(COUNTIF(F22:J22,"✓")+COUNTIF(F22:J22,"x")))*0.15+ (COUNTIF(K22:O22,"✓")/(COUNTIF(K22:O22,"✓")+COUNTIF(K22:O22,"x")))*0.05 + (COUNTIF(P22:S22,"✓")/(COUNTIF(P22:S22,"✓")+COUNTIF(P22:S22,"x")))*0.1 + (COUNTIF(T22:W22,"✓")/(COUNTIF(T22:W22,"✓")+COUNTIF(T22:W22,"x")))*0.1 + (COUNTIF(X22:AB22,"✓")/(COUNTIF(X22:AB22,"✓")+COUNTIF(X22:AB22,"x")))*0.1 + (COUNTIF(AC22:AO22,"✓")/(COUNTIF(AC22:AO22,"✓")+COUNTIF(AC22:AO22,"x")))*0.1 + (COUNTIF(AP22:AT22,"✓")/(COUNTIF(AP22:AT22,"✓")+COUNTIF(AP22:AT22,"x")))*0.05 + (COUNTIF(AU22:BB22,"✓")/(COUNTIF(AU22:BB22,"✓")+COUNTIF(AU22:BB22,"x")))*0.1 + (COUNTIF(BC22:BC22,"✓")/(COUNTIF(BC22:BC22,"✓")+COUNTIF(BC22:BC22,"x")))*0.05 ) -> #DIV/0!
B23: 110 | C23: 1 | D23: 1 | E23: 1 | F23: 1 | G23: =C23*45% + D23*45% + E23*5% + F23*5% -> 1 | H23: 1 | I23: 1 | J23: 1 | K23: 1 | L23: =H23*30% + I23*30% + J23*10% + K23*30% -> 1 | M23: 1 | N23: 1 | O23: 1 | P23: 1 | Q23: 1 | R23: 1 | S23: 1 | T23: 1 | U23: 1 | V23: 1 | W23: 1 | X23: 1 | Y23: =(U23*10% + V23*10% + W23*10% + X23*10%+ Q23*5% + R23*5% + S23*5% + T23*5%+M23*10% + N23*15% + O23*5% + P23*10%) -> 1 | Z23: 0.8 | AA23: 0.8 | AB23: 0.8 | AC23: 0.8 | AD23: =Z23*45% + AA23*45% + AB23*5% + AC23*5% -> 0.8 | AE23: 1 | AF23: 0.7 | AG23: 1 | AH23: 1 | AI23: =AE23*5% + AF23*30% + AG23*35% + AH23*30% -> 0.91 | AJ23: 1 | AK23: 1 | AM23: 1 | AN23: 1 | AO23: 1 | AP23: 0.95 | AQ23: =AM23*15% + AN23*35% + AO23*15% + AP23*35% -> 0.9825 | AR23: 1 | AS23: 0.5 | AT23: 0 | AU23: 1 | AV23: =AR23*30% + AS23*30% + AT23*15% + AU23*25% -> 0.7 | AW23: 1 | AX23: 0.35 | AY23: 0 | AZ23: =AW23*30% + AX23*45% + AY23*25% -> 0.4575 | BA23: 0 | BB23: 1 | BC23: 0 | BD23: =BA23*30% + BB23*45% + BC23*25% -> 0.45 | BF23: =( (COUNTIF(B23:E23,"✓")/(COUNTIF(B23:E23,"✓")+COUNTIF(B23:E23,"x")))*0.2 + (COUNTIF(F23:J23,"✓")/(COUNTIF(F23:J23,"✓")+COUNTIF(F23:J23,"x")))*0.15+ (COUNTIF(K23:O23,"✓")/(COUNTIF(K23:O23,"✓")+COUNTIF(K23:O23,"x")))*0.05 + (COUNTIF(P23:S23,"✓")/(COUNTIF(P23:S23,"✓")+COUNTIF(P23:S23,"x")))*0.1 + (COUNTIF(T23:W23,"✓")/(COUNTIF(T23:W23,"✓")+COUNTIF(T23:W23,"x")))*0.1 + (COUNTIF(X23:AB23,"✓")/(COUNTIF(X23:AB23,"✓")+COUNTIF(X23:AB23,"x")))*0.1 + (COUNTIF(AC23:AO23,"✓")/(COUNTIF(AC23:AO23,"✓")+COUNTIF(AC23:AO23,"x")))*0.1 + (COUNTIF(AP23:AT23,"✓")/(COUNTIF(AP23:AT23,"✓")+COUNTIF(AP23:AT23,"x")))*0.05 + (COUNTIF(AU23:BB23,"✓")/(COUNTIF(AU23:BB23,"✓")+COUNTIF(AU23:BB23,"x")))*0.1 + (COUNTIF(BC23:BC23,"✓")/(COUNTIF(BC23:BC23,"✓")+COUNTIF(BC23:BC23,"x")))*0.05 ) -> #DIV/0!
B24: 111 | C24: 1 | D24: 1 | E24: 1 | F24: 1 | G24: =C24*45% + D24*45% + E24*5% + F24*5% -> 1 | H24: 1 | I24: 1 | J24: 1 | K24: 1 | L24: =H24*30% + I24*30% + J24*10% + K24*30% -> 1 | M24: 1 | N24: 1 | O24: 1 | P24: 1 | Q24: 1 | R24: 1 | S24: 1 | T24: 1 | U24: 1 | V24: 1 | W24: 1 | X24: 1 | Y24: =(U24*10% + V24*10% + W24*10% + X24*10%+ Q24*5% + R24*5% + S24*5% + T24*5%+M24*10% + N24*15% + O24*5% + P24*10%) -> 1 | Z24: 0.7 | AA24: 0.7 | AB24: 0.7 | AC24: 0.7 | AD24: =Z24*45% + AA24*45% + AB24*5% + AC24*5% -> 0.7 | AE24: 1 | AF24: 0.7 | AG24: 1 | AH24: 1 | AI24: =AE24*5% + AF24*30% + AG24*35% + AH24*30% -> 0.91 | AJ24: 1 | AK24: 1 | AM24: 1 | AN24: 1 | AO24: 1 | AP24: 0.95 | AQ24: =AM24*15% + AN24*35% + AO24*15% + AP24*35% -> 0.9825 | AR24: 1 | AS24: 0.5 | AT24: 0 | AU24: 1 | AV24: =AR24*30% + AS24*30% + AT24*15% + AU24*25% -> 0.7 | AW24: 1 | AX24: 0.35 | AY24: 0 | AZ24: =AW24*30% + AX24*45% + AY24*25% -> 0.4575 | BA24: 0 | BB24: 0 | BC24: 0 | BD24: =BA24*30% + BB24*45% + BC24*25% -> 0 | BF24: =( (COUNTIF(B24:E24,"✓")/(COUNTIF(B24:E24,"✓")+COUNTIF(B24:E24,"x")))*0.2 + (COUNTIF(F24:J24,"✓")/(COUNTIF(F24:J24,"✓")+COUNTIF(F24:J24,"x")))*0.15+ (COUNTIF(K24:O24,"✓")/(COUNTIF(K24:O24,"✓")+COUNTIF(K24:O24,"x")))*0.05 + (COUNTIF(P24:S24,"✓")/(COUNTIF(P24:S24,"✓")+COUNTIF(P24:S24,"x")))*0.1 + (COUNTIF(T24:W24,"✓")/(COUNTIF(T24:W24,"✓")+COUNTIF(T24:W24,"x")))*0.1 + (COUNTIF(X24:AB24,"✓")/(COUNTIF(X24:AB24,"✓")+COUNTIF(X24:AB24,"x")))*0.1 + (COUNTIF(AC24:AO24,"✓")/(COUNTIF(AC24:AO24,"✓")+COUNTIF(AC24:AO24,"x")))*0.1 + (COUNTIF(AP24:AT24,"✓")/(COUNTIF(AP24:AT24,"✓")+COUNTIF(AP24:AT24,"x")))*0.05 + (COUNTIF(AU24:BB24,"✓")/(COUNTIF(AU24:BB24,"✓")+COUNTIF(AU24:BB24,"x")))*0.1 + (COUNTIF(BC24:BC24,"✓")/(COUNTIF(BC24:BC24,"✓")+COUNTIF(BC24:BC24,"x")))*0.05 ) -> #DIV/0!
