Workbook

Sheet Overall IR Status
A1: Overall IR Status
A3: Sr. No | B3: Contractor Name | C3: IR Status | D3: I Tower | E3: L1 Tower | F3: L2 Tower | G3: External Development
A4: 1 | B4: ICPL | C4: 1. Fully Approved | D4: ='I Tower ICPL IR log'!L3 -> 956 | E4: ='ICPL L1 Tower IR'!L4 -> 689 | F4: ='L2 Tower ICPL'!L3 -> 799
C5: 2. Approved with comments (B) | D5: ='I Tower ICPL IR log'!L4 -> 2 | E5: ='ICPL L1 Tower IR'!L5 -> 3 | F5: ='L2 Tower ICPL'!L4 -> 5
C6: 3. Rejected (R) | D6: ='I Tower ICPL IR log'!L5 -> 2 | E6: ='ICPL L1 Tower IR'!L6 -> 1 | F6: ='L2 Tower ICPL'!L5 -> 0
C7: 4. Open/Pending (OP) | D7: ='I Tower ICPL IR log'!L6 -> 0 | E7: ='ICPL L1 Tower IR'!L7 -> 0 | F7: ='L2 Tower ICPL'!L6 -> 3
C8: 5. Total | D8: ='I Tower ICPL IR log'!L7 -> 960 | E8: ='ICPL L1 Tower IR'!L8 -> 693 | F8: ='L2 Tower ICPL'!L7 -> 807
A9: 2 | B9: IIL | C9: 1. Fully Approved | D9: ='ICPL L1 Tower IR'!L4 -> 689 | E9: ='IIL L1 Tower IR'!L3 -> 119
C10: 2. Approved with comments (B) | D10: ='ICPL L1 Tower IR'!L5 -> 3 | E10: ='IIL L1 Tower IR'!L4 -> 54
C11: 3. Rejected (R) | D11: ='ICPL L1 Tower IR'!L6 -> 1 | E11: ='IIL L1 Tower IR'!L5 -> 1
C12: 4. Open/Pending (OP) | D12: ='ICPL L1 Tower IR'!L7 -> 0 | E12: ='IIL L1 Tower IR'!L6 -> 2
C13: 5. Total | D13: ='ICPL L1 Tower IR'!L8 -> 693 | E13: ='IIL L1 Tower IR'!L7 -> 176
A14: 3 | B14: GE | C14: 1. Fully Approved | D14: 0 | E14: ='GE L1 Tower'!L3 -> 636 | F14: ='GE L2 Tower '!L3 -> 663 | G14: ='GE SOG'!L3 -> 13
C15: 2. Approved with comments (B) | D15: ='GE I Tower'!L4 -> 333 | E15: ='GE L1 Tower'!L4 -> 43 | F15: ='GE L2 Tower '!L4 -> 73 | G15: ='GE SOG'!L4 -> 0
C16: 3. Rejected (R) | D16: ='GE I Tower'!L5 -> 82 | E16: ='GE L1 Tower'!L5 -> 55 | F16: ='GE L2 Tower '!L5 -> 19 | G16: ='GE SOG'!L5 -> 0
C17: 4. Open/Pending (OP) | D17: ='GE I Tower'!L6 -> 32 | E17: ='GE L1 Tower'!L6 -> 32 | F17: ='GE L2 Tower '!L6 -> 19 | G17: ='GE SOG'!L6 -> 0
C18: 5. Total | D18: ='GE I Tower'!L7 -> 1401 | E18: ='GE L1 Tower'!L7 -> 766 | F18: ='GE L2 Tower '!L7 -> 774 | G18: ='GE SOG'!L7 -> 13
A19: 4 | B19: Ezy Mix | C19: 1. Fully Approved | D19: ='Ezymix I Tower'!L3 -> 163 | G19: ='Ezymix I Tower'!L3 -> 163
C20: 2. Approved with comments (B) | D20: ='Ezymix I Tower'!L4 -> 37 | G20: ='Ezymix I Tower'!L4 -> 37
C21: 3. Rejected (R) | D21: ='Ezymix I Tower'!L5 -> 20 | G21: ='Ezymix I Tower'!L5 -> 20
C22: 4. Open/Pending (OP) | D22: ='Ezymix I Tower'!L6 -> 16 | G22: ='Ezymix I Tower'!L6 -> 16
C23: 5. Total | D23: ='Ezymix I Tower'!L7 -> 236 | G23: ='Ezymix I Tower'!L7 -> 236
A24: 5 | B24: QE | C24: 1. Fully Approved | D24: ='QE I Tower'!L3 -> 222 | G24: ='QE I Tower'!L3 -> 222
C25: 2. Approved with comments (B) | D25: ='QE I Tower'!L4 -> 164 | G25: ='QE I Tower'!L4 -> 164
C26: 3. Rejected (R) | D26: ='QE I Tower'!L5 -> 4 | G26: ='QE I Tower'!L5 -> 4
C27: 4. Open/Pending (OP) | D27: ='QE I Tower'!L6 -> 14 | G27: ='QE I Tower'!L6 -> 14
C28: 5. Total | D28: ='QE I Tower'!L7 -> 404 | G28: ='QE I Tower'!L7 -> 404
A29: 6 | B29: Captive Aire | C29: 1. Fully Approved | D29: ='Captive Air I Tower'!L3 -> 25
C30: 2. Approved with comments (B) | D30: ='Captive Air I Tower'!L4 -> 7
C31: 3. Rejected (R) | D31: ='Captive Air I Tower'!L5 -> 3
C32: 4. Open/Pending (OP) | D32: ='Captive Air I Tower'!L6 -> 0
C33: 5. Total | D33: ='Captive Air I Tower'!L7 -> 35
A34: 7 | B34: Al Hamd | C34: 1. Fully Approved | D34: ='Al Hamd'!L3 -> 48
C35: 2. Approved with comments (B) | D35: ='Al Hamd'!L4 -> 0
C36: 3. Rejected (R) | D36: ='Al Hamd'!L5 -> 2
C37: 4. Open/Pending (OP) | D37: ='Al Hamd'!L6 -> 1
C38: 5. Total | D38: ='Al Hamd'!L7 -> 51
A39: 8 | B39: Rayyan Associates | C39: 1. Fully Approved | D39: ='Rayyan I tower'!L3 -> 121
C40: 2. Approved with comments (B) | D40: ='Rayyan I tower'!L4 -> 1
C41: 3. Rejected (R) | D41: ='Rayyan I tower'!L5 -> 1
...

Sheet GE L1 Tower
C1: PROJECT: CONSTRUCTION OF LAKE CITY ROOF GARDEN APARTMENTS
J2: IR STATUS
D3: INSPECTION REQUEST LOG (L1 Tower) | J3: Fully Approved (A) | L3: =COUNTIFS(K:K,"A") -> 636
J4: Approved with comments (B) | L4: =COUNTIFS(K:K, "B") -> 43
J5: Rejected ( R) | L5: =COUNTIFS(K:K, "R") -> 55
J6: Open/Pending (OP) | L6: =COUNTIFS(K:K, "OP") -> 32
J7: Total | L7: =SUM(L3:L6) -> 766
A9: Sr. | B9: Work Package | C9: Floor | D9: IR No. | E9: Submission date | F9: Inspection Date | G9: Element | H9: Activity Description | I9: Level | J9: Location/ Grid Ref | K9: IR Status | L9: IR Closing date | M9: Pour Card No. | N9: Concrete Qty (m3) | O9: Remarks
B10: I TOWER
A11: 1 | B11: Sub Structure | C11: basement | D11: LT-1-001 | E11: 45486 | F11: 45486 | G11: formwork | H11: Check internal walls formwork of rain water tank Zone 4 | I11: (-11.75) | J11: Grid L-S/26-26 | K11: B | L11: 45491
A12: 2 | B12: Sub Structure | C12: basement | D12: LT-1-002 | E12: 45493 | F12: 45493 | G12: formwork | H12: Check internal walls of septic tank formwork Zone 3 & 4 | I12: (-11.75) | J12: Grid F-L/26-26 | K12: B | L12: 45496
A13: 3 | B13: Sub Structure | C13: basement | D13: LT-1-003 | E13: 45495 | F13: 45495 | G13: formwork | H13: Check internal walls of rain water harvesting tank formwork Zone 4 | I13: (-11.75) | J13: Grid A-T/26-26 | K13: B | L13: 45496
A14: 4 | B14: Sub Structure | C14: Basement | D14: LT-1-004 | E14: 45509 | F14: 45509 | G14: formwork | H14: Check SOG & slab formwork of rain water harvesting tank Zone 4 | I14: (+0.0) | J14: Grid L-T/26-26 | K14: B | L14: 45511
A15: 5 | B15: Sub Structure | C15: Basement | D15: LT-1-005 | E15: 45523 | F15: 45523 | G15: formwork | H15: Check formwork for SOG & slab of septic tank Zone 4 | I15: (+0.0) | J15: Grid G-L/26-26 | K15: A | L15: 45525
A16: 6 | B16: Sub Structure | C16: 1st floor | D16: LT-1-006 | E16: 45526 | F16: 45526 | G16: layout | H16: Check layout & allow to start brick work on external sides Zone 5 | I16: (+19.0) | J16: Grid N-U/14-20 | K16: A | L16: 45528
A17: 7 | B17: Sub Structure | C17: 1st floor | D17: LT-1-007 | E17: 45528 | F17: 45528 | G17: layout | H17: Check layout & allow to start brick work on external sides of building Zone 4 | I17: (+19.0) | J17: Grid G-U/20-26 | K17: OP
A18: 8 | B18: Sub Structure | C18: 2nd floor | D18: LT-1-008 | E18: 45538 | F18: 45538 | G18: layout | H18: Check layout & allow to start brick work on external sides Zone 4 & 5 | I18: (+30.0) | J18: Grid N-U/14-26 | K18: A | L18: 45544
A19: 9 | B19: Sub Structure | C19: 2nd floor | D19: LT-1-009 | E19: 45539 | F19: 45539 | G19: layout | H19: Check layout & allow to start brick work on external sides Zone 4 & 5 | I19: (+30.0) | J19: Grid G-U/20-26 | K19: A | L19: 45544
A20: 10 | B20: Sub Structure | C20: 3rd floor | D20: LT-1-010 | E20: 45543 | F20: 45543 | G20: layout | H20: Check layout and allow to start brick work Zone 5 | I20: (+41.0) | J20: Grid N-U/14-20 | K20: B | L20: 45545
A21: 11 | B21: Sub Structure | C21: 3rd floor | D21: LT-1-011 | E21: 45546 | F21: 45547 | G21: layout | H21: Check layout & allow to start brick work | I21: (+41.0) | J21: Grid G-U/20-26 | K21: A | L21: 45551
A22: 12 | B22: Sub Structure | C22: 4th floor | D22: LT-1-012 | E22: 45546 | F22: 45547 | G22: layout | H22: Check layout and allow to start brick work Zone 4 & 5 | I22: (+52.0) | J22: Grid G-U/14-26 | K22: A | L22: 45551
A23: 13 | B23: Sub Structure | C23: 1st floor | D23: LT-1-013 | E23: 45547 | F23: 45547 | G23: brick work | H23: Check brick work on external sides of building in Zone 4 & 5 | I23: (+19.0) | J23: Grid G-U/14-26 | K23: B | L23: 45559
A24: 14 | B24: Sub Structure | C24: 3rd Floor | D24: LT-1-014 | E24: 45549 | F24: 45549 | G24: formwork | H24: Check formwork for slab & beam of balcony zone 5 | I24: (+18.75) | J24: Grid U/16-17, U/18-19 | K24: A | L24: 45553
A25: 15 | B25: Sub Structure | C25: 1st floor | D25: LT-1-015 | E25: 45549 | F25: 45549 | G25: reinforcement | H25: Check slab & beam reinforcement & allow to start concrete | I25: (+18.75) | J25: Grid U/16-17, U/18-19 | K25: A | L25: 45553
A26: 16 | B26: Sub Structure | C26: 5th floor | D26: LT-1-016 | E26: 45551 | F26: 45551 | G26: layout | H26: Check layout & allow to start brick work on external sides of building Zone 5 | I26: (+63.0) | J26: Grid N-U/14-20 | K26: A | L26: 45555
A27: 17 | B27: Sub Structure | C27: 5th floor | D27: LT-1-017 | E27: 45551 | F27: 45551 | G27: layout | H27: Check layout & allow to start brick work zone 4 | I27: (+63.0) | J27: Grid G-U/20-26 | K27: A | L27: 45559
A28: 18 | B28: Sub Structure | C28: 7th floor | D28: LT-1-018 | E28: 45558 | F28: 45558 | G28: layout | H28: Check layout and allow to start brick work zone 4 & 5 | I28: (+85.0) | J28: Grid G-U/15-26 | K28: A | L28: 45561
A29: 19 | B29: Sub Structure | C29: 8th floor | D29: LT-1-019 | E29: 45558 | F29: 45558 | G29: layout | H29: Check layout & allow to start brick work zone 5 | I29: (+96.0) | J29: Grid M-U/15-19 | K29: A | L29: 45561
... A54: 44 | B54: Sub Structure | C54: 2nd floor | D54: LT-1-044 | E54: 45584 | F54: 45584 | G54: brick work | H54: Check layout & allow to start brick work of building zone 4 | I54: (+30.0) | J54: Grid K-R/20-26 | K54: A | L54: 45589
B55: Sub Structure | C55: 2nd floor | D55: LT-1-044 A | E55: 45587 | F55: 45587 | G55: layout | H55: Check layout and allow to start brick work Zone 4 | I55: (+30.0) | J55: Grid R-U/14-20, G-R/23-26 | K55: A | L55: 45589
A56: 45 | B56: Sub Structure | C56: 1st floor | D56: LT-1-045 | E56: 45586 | F56: 45586 | G56: formwork | H56: Check slab/beam formwork in balcony zone 4 | I56: (+18.75) | J56: Grid U/21-23 | K56: A | L56: 45596
A57: 46 | B57: Sub Structure | C57: 1st floor | D57: LT-1-046 | E57: 45586 | F57: 45586 | G57: reinforcement | H57: Check slab/beam reinforcement of balcony & allow to start concrete work zone 4 | I57: (+18.75) | J57: Grid U/21-23 | K57: A | L57: 45596
A58: 47 | B58: Sub Structure | C58: 1st floor | D58: LT-1-047 | E58: 22-Oct*-24 | F58: 22-Oct*-24 | G58: reinforcement | H58: Check slab & beam reinforcement and allow to start concrete work | I58: (+18.75) | J58: Grid U/24-26 | K58: A | L58: 45589
A59: 48 | B59: Sub Structure | C59: 1st floor | D59: LT-1-048 | E59: 22-Oct*-24 | F59: 22-Oct*-24 | G59: formwork | H59: Check slab & beam formwork zone 4 | I59: (+18.75) | J59: Grid U/24-26 | K59: A | L59: 45589
A60: 49 | B60: Sub Structure | C60: 3rd floor | D60: LT-1-049 | E60: 45588 | F60: 45589 | G60: formwork | H60: Check leftover formwork of balcony zone 5 | I60: (+40.75) | J60: Grid U/18-19, U/16-17 | K60: A | L60: 45596
A61: 50 | B61: Sub Structure | C61: 3rd floor | D61: LT-1-050 | E61: 45588 | F61: 45589 | G61: reinforcement | H61: Check slab and beam reinforcement and allow to start concrete zone 5 | I61: (+40.75) | J61: Grid U/18-19, U/16-17 | K61: A | L61: 45596
A62: 51 | B62: Sub Structure | C62: 2nd floor | D62: LT-1-051 | E62: 45588 | F62: 45588 | G62: reinforcement | H62: Check RCC Lintel reinforcement and allow to start concrete work | I62: (+30.0) | K62: A | L62: 45589
A63: 52 | B63: Sub Structure | C63: GF | D63: LT-1-052 | E63: 45589 | F63: 45589 | G63: layout | H63: Check layout and allow to start brick work zone 5 | I63: (+2.0) | J63: Grid N-S/15-20 | K63: A | L63: 45596
A64: 53 | B64: Sub Structure | C64: 1st floor | D64: LT-1-053 | E64: 45590 | F64: 45590 | G64: reinforcement | H64: Check vertical band reinforcement & allow to start formwork | I64: (+18.75) | J64: Grid U/21-23, U/24-26 | K64: A | L64: 45593
A65: 54 | B65: Sub Structure | C65: 1st floor | D65: LT-1-054 | E65: 45591 | F65: 45591 | G65: formwork | H65: Check vertical band formwork & allow to start concrete work | I65: (+18.75 to +29.75) | J65: Grid U/21-23 | K65: A | L65: 45602
...

Sheet I Tower ICPL IR log
C1: PROJECT: CONSTRUCTION OF LAKE CITY ROOF GARDEN APARTMENTS
J2: IR STATUS
D3: INSPECTION REQUEST LOG (I Tower) | J3: Fully Approved (A) | L3: =COUNTIFS(K:K,"A") -> 956
J4: Approved with comments (B) | L4: =COUNTIFS(K:K, "B") -> 2
J5: Rejected ( R) | L5: =COUNTIFS(K:K, "R") -> 2
J6: Open/Pending (OP) | L6: =COUNTIFS(K:K, "OP") -> 0
J7: Total | L7: =SUM(L3:L6) -> 960
A9: Sr. | B9: Work Package | C9: Floor | D9: IR No. | E9: Submission date | F9: Inspection Date | G9: Element | H9: Activity Description | I9: Level | J9: Location/ Grid Ref | K9: IR Status | L9: IR Closing date | M9: Pour Card No. | N9: Concrete Qty (m3) | O9: Remarks
B10: I TOWER
A11: 1 | B11: Sub Structure | C11: Basement | D11: IT/1 | E11: 44721 | G11: Survey | H11: Checking of control points and shifting of BM | J11: I & L Tower | K11: A | L11: 44721
A12: 2 | B12: Sub Structure | C12: Basement | D12: IT/2 | E12: 44722 | G12: Survey | H12: Layout & level before excavation | J12: I & L Tower | K12: A | L12: 44722
A13: 3 | B13: Sub Structure | C13: Basement | D13: IT/3 | E13: 44738 | G13: Excavation | H13: Excavation level, surface preparation & final bed level before PCC | I13: (-17'-3'') | J13: A~F/1~10 | K13: A | L13: 44740
A14: =1+A13 -> 4 | B14: Sub Structure | C14: Basement | D14: IT/4 | E14: 44740 | G14: Termite Proofing | H14: Termite proofing of Zone-1 | J14: A~F/1~10 | K14: A | L14: 45063
A15: =1+A14 -> 5 | B15: Sub Structure | C15: Basement | D15: IT/5 | E15: 44740 | G15: PCC | H15: Laying of PCC 3" thick (1st layer) Zone-1 | J15: A~F/1~10 | K15: A | L15: 44741 | M15: PC-1 | N15: 38
A16: =1+A15 -> 6 | B16: Sub Structure | C16: Basement | D16: IT/6 | E16: 44741 | G16: Excavation | H16: Excavation level, surface preparation & final bed level before PCC Zone-3 | J16: A~F/17~26 | K16: A | L16: 44742
A17: =1+A16 -> 7 | B17: Sub Structure | C17: Basement | D17: IT/7 | E17: 44742 | G17: Termite Proofing | H17: Termite proofing oF Zone-3 | J17: A~F/17~26 | K17: A | L17: 45063
A18: =1+A17 -> 8 | B18: Sub Structure | C18: Basement | D18: IT/8 | E18: 44742 | G18: PCC | H18: Laying of PCC 3" thick (1st layer) Zone-3 | J18: A~F/17~26 | K18: A | L18: 44742 | M18: PC-2 | N18: 54
A19: =1+A18 -> 9 | B19: Sub Structure | C19: Basement | D19: IT/9 | E19: 44744 | G19: Excavation | H19: Excavation level, surface preparation & final bed level before PCC Zone-2 | J19: A~F/11~16 | K19: A | L19: 44744
A20: =1+A19 -> 10 | B20: Sub Structure | C20: Basement | D20: IT/10 | E20: 44742 | G20: Termite Proofing | H20: Termite proofing of Zone-2 | J20: A~F/11~16 | K20: A | L20: 45063
A21: =1+A20 -> 11 | B21: Sub Structure | C21: Basement | D21: IT/11 | E21: 44742 | G21: PCC | H21: Laying of PCC 3" thick (1st layer) Zone-2 | J21: A~F/11~16 | K21: A | L21: 45013 | M21: PC-3 | N21: 50
B22: Sub Structure | C22: Basement | D22: IT/11a | E22: 44744 | G22: PCC | H22: 1st layer PCC of I Tower (Zone 2) | J22: Grid D-F/11-14 | K22: A | L22: 29--Aug-22 | M22: PC-5 | N22: 62
A23: =1+A21 -> 12 | B23: Sub Structure | C23: Basement | D23: IT/12 | E23: 44738 | G23: Excavation | H23: Excavation level, surface preparation & final bed level of lift well Zone1 & 3 | J23: A~B/9~10, A~B/17~18 | K23: A | L23: 44739
A24: =1+A23 -> 13 | B24: Sub Structure | C24: Basement | D24: IT/13 | E24: 44738 | G24: Termite Proofing | H24: Termite proofing at lifet wells Zone-1 & 3 | J24: A~B/9~10, A~B/17~18 | K24: A | L24: 45063
A25: =1+A24 -> 14 | B25: Sub Structure | C25: Basement | D25: IT/14 | E25: 44738 | G25: PCC | H25: Laying of PCC 3" thick (1st layer) Zone-1 & 3 | J25: A~B/9~10, A~B/17~18 | K25: A | L25: 44743 | M25: PC-4 | N25: 60
A26: =1+A25 -> 15 | B26: Sub Structure | C26: Basement | D26: IT/15 | E26: 44748 | G26: Brick Work | H26: Brick work of Lift Wells IT Tower (Zone 1 & 3) | J26: Grid-A-B/9-10, A-B/17-18 | K26: A | L26: 44777
A27: =1+A26 -> 16 | B27: Sub Structure | C27: Basement | D27: IT/16 | E27: 44776 | G27: Brick Work | H27: Brick work (th 9" and ht 4') for Raft external face protection I Tower (Zone 1 & 3) | J27: Grid A-F/1, Grid A-F/26 | K27: A | L27: 44777
A28: =1+A27 -> 17 | B28: Sub Structure | C28: Basement | D28: IT/17 | E28: 44776 | G28: Brick Work | H28: Brick work (Th 13" and ht 4') for Raft external face protection I Tower (Zone 1 & 3) | J28: Grid A-/01-10, Grid A/12-24 | K28: A | L28: 44777
A29: =1+A28 -> 18 | B29: Sub Structure | C29: Basement | D29: IT/18 | E29: 44776 | G29: Brick Work | H29: Brick work (Th 18" and ht 10') for Raft external face protection I Tower (Zone 2) | J29: Grid A-/10-12, | K29: A | L29: 44777
A30: =1+A29 -> 19 | B30: Sub Structure | C30: Basement | D30: IT/19 | E30: 44776 | G30: Brick Work | H30: Brick work (Th 18" and ht 4') for Raft external face protection I Tower (Zone 3) | J30: Grid A/24-26 | K30: A | L30: 44777
A31: =1+A30 -> 20 | B31: Sub Structure | C31: Basement | D31: IT/20 | E31: 44776 | G31: Excavation | H31: Layout excavation surface preparation and final bed level before laying of PCC I Tower (Zone 1, 2 & 3) | J31: Grid F/1-26 | K31: A | L31: 44777
A32: =1+A31 -> 21 | B32: Sub Structure | C32: Basement | D32: IT/21 | E32: 44776 | G32: Termitte | H32: Termitte proofing (Fiprokill) before laying of PCC | J32: Grid F/1-26 | K32: A | L32: 44777
A33: =1+A32 -> 22 | B33: Sub Structure | C33: Basement | D33: IT/22 | E33: 44778 | G33: PCC | H33: First layer of PCC I Tower Zone 1, 2 and 3 as per revised drawing | J33: Grid F/1-26 | K33: A | L33: 44778 | M33: PC-6 | N33: 15
A34: =1+A33 -> 23 | B34: Sub Structure | C34: Basement | D34: IT/23 | E34: 44778 | G34: Brick work | H34: Layout, surface preparation, brick work, backfilling and PCC | J34: Backside of ICPL office | K34: A | L34: 44779 | M34: PC-7 | N34: 5
A35: =1+A34 -> 24 | B35: Sub Structure | C35: Basement | D35: IT/24 | E35: 44778 | G35: Brick work | H35: Work of Brickwall (Th 9" and ht 4') raft external face protection I Towr (Zone 1 and 3) | J35: Grid A-F/1, A-F/26 | K35: A | L35: 44779
A36: =1+A35 -> 25 | B36: Sub Structure | C36: Basement | D36: IT/25 | E36: 44778 | G36: Plaster work | H36: Plaster work of Brick wall (Th 13" and ht 4') raft external face protection I Tower Zone (1 and 3) | J36: Grid A/1-10, Grid A/12-24 | K36: A | L36: 44789
A37: =1+A36 -> 26 | B37: Sub Structure | C37: Basement | D37: IT/26 | E37: 44778 | G37: Plaster work | H37: Plaster work of Brick wall (Th 18" and ht 10') raft external face protection I Tower Zone (2) | J37: Grid A/10-12 | K37: A | L37: 44789
A38: =1+A37 -> 27 | B38: Sub Structure | C38: Basement | D38: IT/27 | E38: 44778 | G38: Plaster work | H38: Plaster work of Brick wall (Th 18" and ht 4') raft external face protection I Tower Zone (3) | J38: Grid A/24-26 | K38: A | L38: 44779
A39: =1+A38 -> 28 | B39: Sub Structure | C39: Basement | D39: IT/28 | E39: 44778 | G39: Dismental | H39: Dismental of 1sty layer PCC for pits excavation (14' 6" x 14' -6") as per revised drawing I Tower Zone (1 & 3) | J39: Grid AB/8-9, AB/18-19 | K39: A | L39: 44778
A40: =1+A39 -> 29 | B40: Sub Structure | C40: Basement | D40: IT/29 | E40: 44779 | G40: Dismental | H40: Dismental additional 1sty layer PCC and excavation b/w pits and lift well (14' -6 x 2' -9") as per revised drawing I Tower Zone (1 & 3) | J40: Grid AB/8-9, AB/18-19 | K40: A | L40: 44779
A41: =1+A40 -> 30 | B41: Sub Structure | C41: Basement | D41: IT/30 | E41: 44779 | G41: Gen foundation | H41: Layout, surface preparation, brick work, backfilling and PCC of Generator foundation as per approved drawing | J41: Steel yard area | K41: A | L41: 44795
...

Sheet Elements
A1: inputs: Don’t delete the highlighted cells | E1: TOT | G1: Sub Str | J1: I-Tower | Y1: L-Tower
E2: QTY | G2: Qty | I2: Qty | J2: Ground | K2: 1st | L2: 2nd | M2: 3rd | N2: 4th | O2: 5th | P2: 6th | Q2: 7th | R2: 8th | S2: 9th | T2: 10th | U2: 11th | V2: mumty | X2: Qty | Y2: Ground | Z2: 1st | AA2: 2nd | AB2: 3rd | AC2: 4th | AD2: 5th | AE2: 6th | AF2: 7th | AG2: 8th | AH2: 9th | AI2: 10th | AJ2: 11th | AK2: mumty
A3: 1 | B3: PCC | C3: 1500 | E3: =G3 -> 1581.5475 | G3: =B!E18 -> 1581.5475
A4: 2 | B4: Raft | C4: 4000 | E4: =G4 -> 8836.5357 | G4: =B!E22 -> 8836.5357
A5: 3 | B5: Foundation | C5: 4000
A6: 4 | B6: Column | C6: 5000 | E6: =G6+I6+X6 -> 2879.6849 | G6: =B!E28 -> 476.50276 | I6: =SUM(J6:U6) -> 1029.3083 | J6: =I!E8 -> 162.9396 | K6: =I!E9 -> 83.522469 | L6: =I!E10 -> 85.221231 | M6: =I!E11 -> 73.896151 | N6: =I!E12 -> 73.896151 | O6: =I!E13 -> 73.896151 | P6: =I!E14 -> 73.896151 | Q6: =I!E15 -> 73.896151 | R6: =I!E16 -> 73.896151 | S6: =I!E17 -> 73.896151 | T6: =I!E18 -> 81.965271 | U6: =I!E19 -> 98.386637 | X6: =SUM(Y6:AK6) -> 1373.8738 | Y6: =L!$E8 -> 215.88435 | Z6: =L!$E9 -> 110.5611 | AA6: =L!$E10 -> 112.96768 | AB6: =L!$E11 -> 97.67882 | AC6: =L!$E12 -> 97.67882 | AD6: =L!$E13 -> 97.67882 | AE6: =L!$E14 -> 97.67882 | AF6: =L!$E15 -> 97.67882 | AG6: =L!$E16 -> 97.67882 | AH6: =L!$E17 -> 97.67882 | AI6: =L!$E18 -> 108.57921 | AJ6: =L!$E19 -> 130.23843 | AK6: =L!$E20 -> 11.891335 | XEE6: =I!XET18 -> 0
A7: 5 | B7: Ret Wall | C7: 4000 | E7: =G7+I7+X7 -> 525.20061 | G7: =B!E38 -> 525.20061
A8: 6 | B8: Lift Well | C8: 5000 | E8: =G8+I8+X8 -> 3240.2471 | G8: =B!E31 -> 259.06122 | I8: =SUM(J8:V8) -> 1341.5974 | J8: =I!$E23 -> 154.58735 | K8: =I!$E24 -> 93.715042 | L8: =I!$E25 -> 93.715042 | M8: =I!$E26 -> 93.715042 | N8: =I!$E27 -> 93.715042 | O8: =I!$E28 -> 93.715042 | P8: =I!$E29 -> 93.715042 | Q8: =I!$E30 -> 93.715042 | R8: =I!$E31 -> 93.715042 | S8: =I!$E32 -> 93.715042 | T8: =I!$E33 -> 102.63354 | U8: =I!$E34 -> 120.47054 | V8: =I!$E35 -> 120.47054 | X8: =SUM(Y8:AK8) -> 1639.5885 | Y8: =L!$E23 -> 188.98728 | Z8: =L!$E24 -> 114.52488 | AA8: =L!$E25 -> 114.52488 | AB8: =L!$E26 -> 114.52488 | AC8: =L!$E27 -> 114.52488 | AD8: =L!$E28 -> 114.52488 | AE8: =L!$E29 -> 114.52488 | AF8: =L!$E30 -> 114.52488 | AG8: =L!$E31 -> 114.52488 | AH8: =L!$E32 -> 114.52488 | AI8: =L!$E33 -> 125.42527 | AJ8: =L!$E34 -> 147.22605 | AK8: =L!$E35 -> 147.22605
A9: 7 | B9: Shear Wall | C9: 5000
A10: 8 | B10: Beam | C10: 4000
A11: 9 | B11: Slab | C11: 4000 | E11: =G11+I11+X11 -> 19035.62 | G11: =B!E34 -> 2477.9276 | I11: =SUM(J11:V11) -> 7105.6387 | J11: =I!$E40 -> 592.30171 | K11: =I!$E41 -> 590.46139 | L11: =I!$E42 -> 590.46139 | M11: =I!$E43 -> 590.46139 | N11: =I!$E44 -> 590.46139 | O11: =I!$E45 -> 590.46139 | P11: =I!$E46 -> 590.46139 | Q11: =I!$E47 -> 590.46139 | R11: =I!$E48 -> 590.46139 | S11: =I!$E49 -> 590.46139 | T11: =I!$E50 -> 590.46139 | U11: =I!$E51 -> 574.18158 | V11: =I!$E52 -> 34.541496 | X11: =SUM(Y11:AK11) -> 9452.0538 | Y11: =L!$E40 -> 785.25277 | Z11: =L!$E41 -> 782.70463 | AA11: =L!$E42 -> 782.70463 | AB11: =L!$E43 -> 782.70463 | AC11: =L!$E44 -> 782.70463 | AD11: =L!$E45 -> 782.70463 | AE11: =L!$E46 -> 782.70463 | AF11: =L!$E47 -> 782.70463 | AG11: =L!$E48 -> 782.70463 | AH11: =L!$E49 -> 782.70463 | AI11: =L!$E50 -> 782.70463 | AJ11: =L!$E51 -> 761.04541 | AK11: =L!$E52 -> 78.70931
A12: 10 | B12: Lintel | C12: 3000 | E12: =G12+I12+X12 -> 426.10616 | I12: =I!E37 -> 184.03256 | X12: =L!E37 -> 242.0736
A13: 11 | B13: Stair | C13: 4000 | E13: =G13+I13+X13 -> 353.90857 | G13: =B!E36 -> 27.18 | I13: =I!E56 -> 163.36429 | X13: =L!E56 -> 163.36429
A14: 12 | B14: Ramp Slab | C14: 4000 | E14: =G14+I14+X14 -> 91.874716 | G14: =B!E25 -> 91.874716
A15: 13 | B15: UGWT Base Slab | C15: 4000 | E15: =G15+I15+X15 -> 97.67882 | G15: =B!E41 -> 97.67882
A16: 14 | B16: UGWT Walls | C16: 4000 | E16: =G16+I16+X16 -> 230.18226 | G16: =B!E42 -> 230.18226
A17: 15 | B17: UGWT Top Slab | C17: 4000 | E17: =G17+I17+X17 -> 62.57107 | G17: =B!E43 -> 62.57107
A18: 16 | B18: Harvest Tank Base Slab | C18: 4000 | E18: =G18+I18+X18 -> 46.291267 | G18: =B!E46 -> 46.291267
A19: 17 | B19: Harvest Tank Walls | C19: 4000 | E19: =G19+I19+X19 -> 102.77511 | G19: =B!E47 -> 102.77511
A20: 18 | B20: Harvest Tank Top Slab | C20: 4000 | E20: =G20+I20+X20 -> 13.476846 | G20: =B!E48 -> 13.476846
A21: 19 | B21: OHWT Base Slab | C21: 4000 | E21: =G21+I21+X21 -> 56.625403 | I21: =I!E59 -> 26.755503 | X21: =L!E59 -> 29.8699
A22: 20 | B22: OHWT Walls | C22: 4000 | E22: =G22+I22+X22 -> 58.041038 | I22: =I!E60 -> 26.897066 | X22: =L!E60 -> 31.143972
A23: 21 | B23: OHWT Top Slab | C23: 4000 | E23: =G23+I23+X23 -> 34.683059 | I23: =I!E61 -> 16.13824 | X23: =L!E61 -> 18.544819
A24: 22 | B24: Pool Base Slab | C24: 4000 | E24: =G24+I24+X24 -> 32.559607 | I24: =I!E64 -> 32.559607
A25: 23 | B25: Pool Walls | C25: 4000 | E25: =G25+I25+X25 -> 16.987621 | I25: =I!E65 -> 16.987621
A26: 24 | B26: Parapet Wall | C26: 3000 | E26: =G26+I26+X26 -> 266.70565 | I26: =I!E54 -> 114.66644 | X26: =L!E54 -> 152.03921
A27: 26
A28: 27
A29: 28
A30: 29
A31: 30
A32: 31
A33: 32
A34: 33 | E34: =SUM(E3:E33) -> 37989.303

Sheet B
B1: LAKE CITY ROOF GARDEN LAHORE APPARTMENTS-PHASE 2 STRUCTURAL WORKS
C4: BILL OF QUANTITIES (STRUCTURAL WORKS)
B5: ITEM NO. | C5: SHORT DESCRIPTION OF WORK TO BE READ IN CONJUNCTION WITH GENERAL SPECIFICATIONS | D5: UNIT | E5: TOTAL QTY | F5: RATE | G5: AMOUNT
B6: 1 | C6: Earth Works
C7: Excavation for basements, raft foundations in existing soil including cost of dressing, leveling and compaction in approved manners and disposal of surplus excavated soil away from site, all excavated area will be proof rolled as directed by the Consultant/Engineer incharge.
B8: a | C8: Excavation | D8: m3 | E8: =705000/(3.281)^3 -> 19960.454 | G8: =E8*F8 -> 0
B10: b | C10: Backfilling using local sand with layer thickness 6" in loose state and compacted upto 95% MDD. | D10: m3 | E10: =55180/(3.281)^3 -> 1562.2949 | G10: =E10*F10 -> 0
B12: 2 | C12: Termite Proofing | G12: =E12*F12 -> 0
C13: Providing and carrying out termite proofing on excavation sides only using "Biflex/ Fiprokill/ Mirage" or an approved equivalent as per manufacturers specification. The work shall be carried out by an approved specialist subcontractor who will provide 10 years warranty stating that in case of infestation during the period of warranty, he will carry out the remedial work without charge to the Employer. complete in all respect and as directed by the Consultants. | G13: =E13*F13 -> 0
B14: a | C14: Excavation bed and sides -7.75 ft from EGL | D14: m3 | E14: =121265/(3.281)^2 -> 11264.788 | G14: =E14*F14 -> 0
B16: 3 | C16: Plain Cement Concrete | F16: 0 | G16: =E16*F16 -> 0
C17: Laying owner supplied concrete from point of delivery, compacting and finishing blinding concrete (1:4:8) in layers and providing proper curing upto the required time as per drawings/ specifications/ directed by the Consultant. | F17: 0 | G17: =E17*F17 -> 0
B18: a | C18: 3" thick two layers of PCC 1:4:8 under Raft/Mat foundations. | D18: m3 | E18: =55860/(3.281)^3 -> 1581.5475 | F18: 10666.591 | G18: =E18*F18 -> 16869720
F19: 0
B20: 4 | C20: Reinforced Cement Concrete Work | F20: 0 | G20: =E20*F20 -> 0
C21: Laying owner supplied concrete from point of delivery, vibrating, compacting, finishing and curing etc. straight or curved, cast in situ reinforced cement concrete at any floor/height/depth, pumped ready mix concrete, 4000 psi and 5000 Psi (mentioned in parenthesis ) minimum cylinder crushing strength at 28 days, mix using Ordinary Portland Grey Cement, fine aggregate Lawrence pur good quality clean sand free from impurities and Sargodha crushed course aggregate 3/4 '' & 1/2" down well-graded, including vibrations through electro mechanical vibrators, steel form work, moulds, false work and their removal, placing of all pipes and embedded items before concreting curing finishing complete but excluding the cost of steel reinforcement complete in all respect as per drawings and as directed by the Consultant/Engineer incharge. | F21: 0 | G21: =E21*F21 -> 0
B22: i | C22: Mat foundations (4000 psi) | D22: m3 | E22: =312105/(3.281)^3 -> 8836.5357 | F22: 14881.069 | G22: =E22*F22 -> 1.3149709e+08
F23: 0
B24: ii | C24: Ramp slab and beams (4000 psi) | F24: 0 | G24: =E24*F24 -> 0
C25: Foundations to GF | D25: m3 | E25: =3245/(3.281)^3 -> 91.874716 | F25: 13856.793 | G25: =E25*F25 -> 1273089
F26: 0
B27: iii | C27: Columns (5000 psi) | F27: 0 | G27: =E27*F27 -> 0
C28: Foundation to Ground Floor | D28: m3 | E28: =16830/(3.281)^3 -> 476.50276 | F28: 24005.356 | G28: =E28*F28 -> 11438619
F29: 0 | G29: =E29*F29 -> 0
B30: iv | C30: Lift wells/shearwalls(5000 psi) | F30: 0 | G30: =E30*F30 -> 0
C31: Foundation to Ground Floor | D31: m3 | E31: =9150/3.281^3 -> 259.06122 | F31: 15881.793 | G31: =E31*F31 -> 4114356.8
F32: 0 | G32: =E32*F32 -> 0
B33: v | C33: Floor slabs and beams (4000 psi) | F33: 0 | G33: =E33*F33 -> 0
C34: GF (7"Th slab+18"drop beams) | D34: m3 | E34: 2477.9276 | F34: 13856.793 | G34: =E34*F34 -> 34336131
F35: 0
B36: vi | C36: Stairs (4000 psi) | D36: m3 | E36: 27.18 | F36: 22262.915 | G36: =E36*F36 -> 605106.02
F37: 0
B38: vii | C38: Retaining walls(4000 psi) | D38: m3 | E38: 525.20061 | F38: 13856.793 | G38: =E38*F38 -> 7277596.4
F39: 0
B40: viii | C40: Under Ground water tank (4000 psi) | F40: 0 | G40: =E40*F40 -> 0
C41: Base slab | D41: m3 | E41: 97.67882 | F41: 16081.943 | G41: =E41*F41 -> 1570865.2
C42: Walls | D42: m3 | E42: 230.18226 | F42: 26854.494 | G42: =E42*F42 -> 6181428.1
C43: Top slab | D43: m3 | E43: 62.57107 | F43: 25865.538 | G43: =E43*F43 -> 1618434.4
F44: 0
B45: ix | C45: Rain harvesting tank (4000 psi) | F45: 0 | G45: =E45*F45 -> 0
...

Sheet I
B1: LAKE CITY ROOF GARDEN LAHORE APPARTMENTS-PHASE 2 STRUCTURAL WORKS I-TOWERS (MATERIAL ONLY)
B3: SR. | C3: ITEM DESCRIPTION | D3: UNIT | E3: TOTAL QTY | F3: RATE | G3: AMOUNT
B4: 1 | C4: Reinforced Cement Concrete Work
C5: Laying owner supplied concrete from point of delivery, vibrating, compacting, finishing and curing etc. straight or curved, cast in situ reinforced cement concrete at any floor/height/depth, pumped ready mix concrete, 4000 psi and 5000 Psi (mentioned in parenthesis ) minimum cylinder crushing strength at 28 days, mix using Ordinary Portland Grey Cement, fine aggregate Lawrence pur good quality clean sand free from impurities and Sargodha crushed course aggregate 3/4 '' & 1/2" down well-graded, including vibrations through electro mechanical vibrators, steel form work, moulds, false work and their removal, placing of all pipes and embedded items before concreting curing finishing complete but excluding the cost of steel reinforcement complete in all respect as per drawings and as directed by the Consultant/Engineer incharge. | G5: =E5*F5 -> 0
B7: i | C7: Columns (5000 psi) | G7: =E7*F7 -> 0
C8: Ground to First Floor | D8: m3 | E8: =5755/3.281^3 -> 162.9396 | F8: 16918.202 | G8: =E8*F8 -> 2756645
C9: 1st to 2nd Floor | D9: m3 | E9: =2950/3.281^3 -> 83.522469 | F9: 16918.202 | G9: =E9*F9 -> 1413050
C10: 2nd to 3rd Floor | D10: m3 | E10: =3010/3.281^3 -> 85.221231 | F10: 16918.202 | G10: =E10*F10 -> 1441790
C11: 3rd to 4th Floor | D11: m3 | E11: =2610/3.281^3 -> 73.896151 | F11: 16918.202 | G11: =E11*F11 -> 1250190
C12: 4th to 5th Floor | D12: m3 | E12: =2610/3.281^3 -> 73.896151 | F12: 16918.202 | G12: =E12*F12 -> 1250190
C13: 5th to 6th Floor | D13: m3 | E13: =2610/3.281^3 -> 73.896151 | F13: 16918.202 | G13: =E13*F13 -> 1250190
C14: 6th to 7th Floor | D14: m3 | E14: =2610/3.281^3 -> 73.896151 | F14: 16918.202 | G14: =E14*F14 -> 1250190
C15: 7th to 8th Floor | D15: m3 | E15: =2610/3.281^3 -> 73.896151 | F15: 16918.202 | G15: =E15*F15 -> 1250190
C16: 8th to 9th Floor | D16: m3 | E16: =2610/3.281^3 -> 73.896151 | F16: 16918.202 | G16: =E16*F16 -> 1250190
C17: 9th to 10th Floor | D17: m3 | E17: =2610/3.281^3 -> 73.896151 | F17: 16918.202 | G17: =E17*F17 -> 1250190
C18: 10th to 11th Floor | D18: m3 | E18: =2895/3.281^3 -> 81.965271 | F18: 16918.202 | G18: =E18*F18 -> 1386705
C19: 11th to Roof | D19: m3 | E19: =3475/3.281^3 -> 98.386637 | F19: 16918.202 | G19: =E19*F19 -> 1664525
B22: ii | C22: Lift wells/shearwalls(5000 psi) | G22: =E22*F22 -> 0
C23: Ground to First Floor | D23: m3 | E23: =5460/3.281^3 -> 154.58735 | F23: 16918.202 | G23: =E23*F23 -> 2615340
C24: 1st to 2nd Floor | D24: m3 | E24: =3310/3.281^3 -> 93.715042 | F24: 16918.202 | G24: =E24*F24 -> 1585490
C25: 2nd to 3rd Floor | D25: m3 | E25: =3310/3.281^3 -> 93.715042 | F25: 16918.202 | G25: =E25*F25 -> 1585490
C26: 3rd to 4th Floor | D26: m3 | E26: =3310/3.281^3 -> 93.715042 | F26: 16918.202 | G26: =E26*F26 -> 1585490
C27: 4th to 5th Floor | D27: m3 | E27: =3310/3.281^3 -> 93.715042 | F27: 16918.202 | G27: =E27*F27 -> 1585490
C28: 5th to 6th Floor | D28: m3 | E28: =3310/3.281^3 -> 93.715042 | F28: 16918.202 | G28: =E28*F28 -> 1585490
C29: 6th to 7th Floor | D29: m3 | E29: =3310/3.281^3 -> 93.715042 | F29: 16918.202 | G29: =E29*F29 -> 1585490
C30: 7th to 8th Floor | D30: m3 | E30: =3310/3.281^3 -> 93.715042 | F30: 16918.202 | G30: =E30*F30 -> 1585490
C31: 8th to 9th Floor | D31: m3 | E31: =3310/3.281^3 -> 93.715042 | F31: 16918.202 | G31: =E31*F31 -> 1585490
C32: 9th to 10th Floor | D32: m3 | E32: =3310/3.281^3 -> 93.715042 | F32: 16918.202 | G32: =E32*F32 -> 1585490
C33: 10th to 11th Floor | D33: m3 | E33: =3625/3.281^3 -> 102.63354 | F33: 16918.202 | G33: =E33*F33 -> 1736375
C34: 11th to Roof | D34: m3 | E34: =4255/3.281^3 -> 120.47054 | F34: 16918.202 | G34: =E34*F34 -> 2038145
C35: Roof to Mummty | D35: m3 | E35: =4255/3.281^3 -> 120.47054 | F35: 16918.202 | G35: =E35*F35 -> 2038145
B37: iii | C37: Lintels (3000 psi) | D37: m3 | E37: =6500/(3.281)^3 -> 184.03256 | F37: 14445.813 | G37: =E37*F37 -> 2658500
B39: iv | C39: Floor slabs and beams (4000 psi) | G39: =E39*F39 -> 0
C40: FF (7"Th slab + 18"drop beams) | D40: m3 | E40: =20920/(3.281)^3 -> 592.30171 | F40: 15258.17 | G40: =E40*F40 -> 9037440
C41: 2nd Floor (7"Th slab+18" beams) | D41: m3 | E41: =20855/(3.281)^3 -> 590.46139 | F41: 15258.17 | G41: =E41*F41 -> 9009360
C42: 3rd Floor (7"Th slab+ 18" drop beams) | D42: m3 | E42: =20855/(3.281)^3 -> 590.46139 | F42: 15258.17 | G42: =E42*F42 -> 9009360
C43: 4th Floor (7"Th slab+18" drop beams) | D43: m3 | E43: =20855/(3.281)^3 -> 590.46139 | F43: 15258.17 | G43: =E43*F43 -> 9009360
C44: 5th Floor (7" TH slab with 18" drop beams) | D44: m3 | E44: =20855/(3.281)^3 -> 590.46139 | F44: 15258.17 | G44: =E44*F44 -> 9009360
C45: 6th Floor (7" TH slab with 18" drop beams) | D45: m3 | E45: =20855/(3.281)^3 -> 590.46139 | F45: 15258.17 | G45: =E45*F45 -> 9009360
C46: 7th Floor (7" TH slab with 18" drop beams) | D46: m3 | E46: =20855/(3.281)^3 -> 590.46139 | F46: 15258.17 | G46: =E46*F46 -> 9009360
...

Sheet L
B1: LAKE CITY ROOF GARDEN LAHORE APPARTMENTS-PHASE 2 STRUCTURAL WORKS L-TOWERS (MATERIAL ONLY)
B3: SR. | C3: ITEM DESCRIPTION | D3: UNIT | E3: TOTAL QTY | F3: RATE | G3: AMOUNT
B4: 1 | C4: Reinforced Cement Concrete Work
C5: Laying owner supplied concrete from point of delivery, vibrating, compacting, finishing and curing etc. straight or curved, cast in situ reinforced cement concrete at any floor/height/depth, pumped ready mix concrete, 4000 psi and 5000 Psi (mentioned in parenthesis ) minimum cylinder crushing strength at 28 days, mix using Ordinary Portland Grey Cement, fine aggregate Lawrence pur good quality clean sand free from impurities and Sargodha crushed course aggregate 3/4 '' & 1/2" down well-graded, including vibrations through electro mechanical vibrators, steel form work, moulds, false work and their removal, placing of all pipes and embedded items before concreting curing finishing complete but excluding the cost of steel reinforcement complete in all respect as per drawings and as directed by the Consultant/Engineer incharge. | G5: =E5*F5 -> 0
B7: i | C7: Columns (5000 psi)
C8: Ground to First Floor | D8: m3 | E8: =7625/3.281^3 -> 215.88435 | F8: 16918.202 | G8: =E8*F8 -> 3652375
C9: 1st to 2nd Floor | D9: m3 | E9: =3905/3.281^3 -> 110.5611 | F9: 16918.202 | G9: =E9*F9 -> 1870495
C10: 2nd to 3rd Floor | D10: m3 | E10: =3990/3.281^3 -> 112.96768 | F10: 16918.202 | G10: =E10*F10 -> 1911210
C11: 3rd to 4th Floor | D11: m3 | E11: =3450/3.281^3 -> 97.67882 | F11: 16918.202 | G11: =E11*F11 -> 1652550
C12: 4th to 5th Floor | D12: m3 | E12: =3450/3.281^3 -> 97.67882 | F12: 16918.202 | G12: =E12*F12 -> 1652550
C13: 5th to 6th Floor | D13: m3 | E13: =3450/3.281^3 -> 97.67882 | F13: 16918.202 | G13: =E13*F13 -> 1652550
C14: 6th to 7th Floor | D14: m3 | E14: =3450/3.281^3 -> 97.67882 | F14: 16918.202 | G14: =E14*F14 -> 1652550
C15: 7th to 8th Floor | D15: m3 | E15: =3450/3.281^3 -> 97.67882 | F15: 16918.202 | G15: =E15*F15 -> 1652550
C16: 8th to 9th Floor | D16: m3 | E16: =3450/3.281^3 -> 97.67882 | F16: 16918.202 | G16: =E16*F16 -> 1652550
C17: 9th to 10th Floor | D17: m3 | E17: =3450/3.281^3 -> 97.67882 | F17: 16918.202 | G17: =E17*F17 -> 1652550
C18: 10th to 11th Floor | D18: m3 | E18: =3835/3.281^3 -> 108.57921 | F18: 16918.202 | G18: =E18*F18 -> 1836965
C19: 11th to Roof | D19: m3 | E19: =4600/3.281^3 -> 130.23843 | F19: 16918.202 | G19: =E19*F19 -> 2203400
C20: Roof to Mummty | D20: m3 | E20: =420/3.281^3 -> 11.891335 | F20: 16918.202 | G20: =E20*F20 -> 201180
B22: ii | C22: Lift wells/shearwalls(5000 psi) | G22: =E22*F22 -> 0
C23: Ground to First Floor | D23: m3 | E23: =6675/3.281^3 -> 188.98728 | F23: 16918.202 | G23: =E23*F23 -> 3197325
C24: 1st to 2nd Floor | D24: m3 | E24: =4045/3.281^3 -> 114.52488 | F24: 16918.202 | G24: =E24*F24 -> 1937555
C25: 2nd to 3rd Floor | D25: m3 | E25: =4045/3.281^3 -> 114.52488 | F25: 16918.202 | G25: =E25*F25 -> 1937555
C26: 3rd to 4th Floor | D26: m3 | E26: =4045/3.281^3 -> 114.52488 | F26: 16918.202 | G26: =E26*F26 -> 1937555
C27: 4th to 5th Floor | D27: m3 | E27: =4045/3.281^3 -> 114.52488 | F27: 16918.202 | G27: =E27*F27 -> 1937555
C28: 5th to 6th Floor | D28: m3 | E28: =4045/3.281^3 -> 114.52488 | F28: 16918.202 | G28: =E28*F28 -> 1937555
C29: 6th to 7th Floor | D29: m3 | E29: =4045/3.281^3 -> 114.52488 | F29: 16918.202 | G29: =E29*F29 -> 1937555
C30: 7th to 8th Floor | D30: m3 | E30: =4045/3.281^3 -> 114.52488 | F30: 16918.202 | G30: =E30*F30 -> 1937555
C31: 8th to 9th Floor | D31: m3 | E31: =4045/3.281^3 -> 114.52488 | F31: 16918.202 | G31: =E31*F31 -> 1937555
C32: 9th to 10th Floor | D32: m3 | E32: =4045/3.281^3 -> 114.52488 | F32: 16918.202 | G32: =E32*F32 -> 1937555
C33: 10th to 11th Floor | D33: m3 | E33: =4430/3.281^3 -> 125.42527 | F33: 16918.202 | G33: =E33*F33 -> 2121970
C34: 11th to Roof | D34: m3 | E34: =5200/3.281^3 -> 147.22605 | F34: 16918.202 | G34: =E34*F34 -> 2490800
C35: Roof to Mummty | D35: m3 | E35: =5200/3.281^3 -> 147.22605 | F35: 16918.202 | G35: =E35*F35 -> 2490800
B37: iii | C37: Lintels (3000 psi) | D37: m3 | E37: =8550/(3.281)^3 -> 242.0736 | F37: 14445.813 | G37: =E37*F37 -> 3496950
B39: iv | C39: Floor slabs and beams (4000 psi) | G39: =E39*F39 -> 0
C40: FF (7"Th slab + 18"drop beams) | D40: m3 | E40: =27735/(3.281)^3 -> 785.25277 | F40: 15258.17 | G40: =E40*F40 -> 11981520
C41: 2nd Floor (7"Th slab+18" beams) | D41: m3 | E41: =27645/(3.281)^3 -> 782.70463 | F41: 15258.17 | G41: =E41*F41 -> 11942640
C42: 3rd Floor (7"Th slab+ 18" drop beams) | D42: m3 | E42: =27645/(3.281)^3 -> 782.70463 | F42: 15258.17 | G42: =E42*F42 -> 11942640
C43: 4th Floor (7"Th slab+18" drop beams) | D43: m3 | E43: =27645/(3.281)^3 -> 782.70463 | F43: 15258.17 | G43: =E43*F43 -> 11942640
C44: 5th Floor (7" TH slab with 18" drop beams) | D44: m3 | E44: =27645/(3.281)^3 -> 782.70463 | F44: 15258.17 | G44: =E44*F44 -> 11942640
C45: 6th Floor (7" TH slab with 18" drop beams) | D45: m3 | E45: =27645/(3.281)^3 -> 782.70463 | F45: 15258.17 | G45: =E45*F45 -> 11942640
...

Sheet Quotations for Mobile crane
E8: As of: | F8: =TODAY() -> 46010
A10: Quotations for Mobile Crane
A13: S.no | B13: Contractor Ref No. | C13: Submittal Ref | D13: Description | E13: Submission date | F13: Receiving date | G13: Status
A15: 1 | B15: 17 | C15: ICPL/LCD/22/0901 | D15: Quotation for Monthly Rental Mobile Crane | E15: 44805 | F15: 44805 | G15: R
A16: 2 | B16: 20 | C16: ICPL/LCD/22/0902 | D16: Quotation daily rental cost for 25 Ton capacity Mobile crane | E16: 44807 | F16: 44807 | G16: 575000 Approved
A17: 3
A18: 4
A19: 5
A20: 6
A21: 7
A22: 8
A23: 9
A24: 10

Sheet Inventory list
D8: As of: | E8: =TODAY() -> 46010
A11: Lake City Roof Gardens (Inventory List)
A13: S.no | B13: Description | C13: Receiving date | D13: Qty | E13: Size | F13: Remarks
A16: 1 | B16: Office Table (CM Office) | D16: 2 | E16: 2x4 | F16: UNISON
A17: 2 | B17: Executive Revolving Chairs (CM office) | C17: 44810 | D17: 4 | F17: UNISON
A18: 3 | B18: Revolving Chairs net black Low back (CM office) | C18: 44810 | D18: 6 | F18: UNISON
A19: 4 | B19: Visitors steel Chairs (CM Office) | D19: 4 | F19: UNISON
A20: 5 | B20: Bracket Fan (CM Office) | D20: 3 | F20: UNISON
A21: 6 | B21: Exhaust Fan Installed in CM Containers | D21: 3 | F21: UNISON
A22: 7 | B22: Container | D22: 1 | E22: 18x10 | F22: Client
A23: 8 | B23: Container | C23: 13 June and 17 August-22 | D23: 2 | E23: 40x18 | F23: UNISON
A24: 9 | B24: Executive Revolving chair | C24: 44810 | D24: 1 | F24: Client
A25: 10 | B25: Printer CM Office | C25: 44810 | D25: 1 | E25: A4 size | F25: UNISON
A26: 11 | B26: Haier Fridge CM Office | C26: 44814 | D26: 1 | E26: Medium | F26: UNISON
A27: 12 | B27: Haier AC Inverter CM Office | C27: 44814 | D27: 1 | E27: 1.5 Ton | F27: UNISON
A28: 13 | B28: Haier AC Inverter CM Office | C28: 44814 | D28: 1 | E28: 1 Ton | F28: UNISON
A29: 14 | B29: Oven CM Office | C29: 44814 | D29: 1 | F29: UNISON
A30: 15 | B30: Work station CM Office | C30: 44817 | D30: 8 | F30: UNISON
A31: 16 | B31: File Rack CM Office | C31: 44817 | D31: 5 | F31: UNISON
A32: 17 | B32: Executive Table with side rack and Drawer | C32: 44821 | D32: 1 | F32: Client
A33: 18 | B33: Electric Cattle CM Office | C33: 44823 | D33: 1 | F33: UNISON
A34: 19 | B34: Executive Chairs | C34: 44825 | D34: 2 | F34: Client
A35: 20 | B35: Containers for Client | C35: 44833 | D35: 1 | E35: 40x18 | F35: Client
A36: 21 | B36: Water Dispenser Enviro CM Office | C36: 44833 | D36: 1 | F36: UNISON
A37: 22 | B37: Office Table CM Office | C37: 44855 | D37: 4 | E37: 2x4 | F37: 2 client
A38: 23 | B38: Meeting Table | C38: 44854 | D38: 2 | E38: 16x4 | F38: Client
A39: 24 | B39: Revolving Chairs (Net Black) Low back | C39: 44854 | D39: 14 | F39: Client
A40: 25 | B40: Visitors chairs (Stainless Steel) | C40: 44854 | D40: 8 | F40: Client
A41: 26 | B41: File Rack | C41: 44856 | D41: 8 | F41: 3 Client
A42: 27 | B42: DB | C42: 44859 | D42: 4

Sheet UET Test Reports
A10: UET Steel Test Reports
A13: S.no | B13: Description | C13: Submission date | D13: Test Date | E13: Payment date | F13: Status | G13: Normal Fee | H13: Urgent Fee | I13: Total Payment
A15: 44771
A16: 1 | B16: Deformed steel Dia 6 | C16: 44769 | D16: 44771 | E16: 44771 | F16: Ok | G16: 13100 | I16: =SUM(G16+H16) -> 13100
A17: 2 | B17: Deformed steel Dia 8 | C17: 44769 | D17: 44771 | F17: Ok
A18: 44806
A19: 3 | B19: Deformed steel Dia 8 | C19: 44806 | D19: 44806 | E19: 44806 | F19: Ok | G19: 10500 | I19: =G19+H20 -> 21000
A20: 4 | B20: Deformed steel Dia 6 | C20: 44806 | D20: 44806 | E20: 44809 | F20: Ok | H20: 10500
A21: 44809
A22: 5 | B22: Deformed steel Dia 4 | C22: 44809 | D22: 44809 | E22: 44809 | F22: Not ok | H22: 6000 | I22: =G22+H22 -> 6000
A23: 6 | B23: Deformed steel Dia 3 | C23: 44806 | D23: 44809 | E23: 44809 | G23: 4600 | H23: 1150 | I23: =G23+H23 -> 5750
A24: 7 | B24: Total Payment | I24: =SUM(I16:I23) -> 45850

Sheet ICPL L1 Tower IR
C1: PROJECT: CONSTRUCTION OF LAKE CITY ROOF GARDEN APARTMENTS
D3: INSPECTION REQUEST LOG (L1 Tower) | J3: IR STATUS
J4: Fully Approved (A) | L4: =COUNTIFS(K:K,"A") -> 689
J5: Approved with comments (B) | L5: =COUNTIFS(K:K, "B") -> 3
J6: Rejected ( R) | L6: =COUNTIFS(K:K, "R") -> 1
J7: Open/Pending (OP) | L7: =COUNTIFS(K:K, "OP") -> 0
J8: Total | L8: =SUM(L4:L7) -> 693
A10: Sr. | B10: Work Package | C10: Floor | D10: IR No. | E10: Submission Date | F10: Inspection Date | G10: Element | H10: Activity Description | I10: Level | J10: Location/ Grid Ref | K10: IR Status | L10: IR Closing date | M10: Pour Card No. | N10: Concrete Qty (m3) | O10: Attachment | P10: Remarks
A11: 1 | B11: Sub Structure | C11: Basement | D11: L1/1 | E11: 44826 | G11: Tower Crane | H11: Layout of Tower crane foundation Zone 8 | J11: Grid K-M/17-20 | K11: A | L11: 44840 | O11: E:\Soft IRs\ICPL\L1-Tower IR's\new\1.pdf
A12: 2 | B12: Sub Structure | C12: Basement | D12: L1/2 | E12: 44827 | G12: Surface preparation | H12: Excavation, surface preparation and final bed level I Tower Zone 8 | J12: Grid K-M/17-20 | K12: A | L12: 44840 | O12: E:\Soft IRs\ICPL\L1-Tower IR's\new\2.pdf
A13: 3 | B13: Sub Structure | C13: Basement | D13: L1/3 | E13: 44827 | G13: Termite proofing | H13: Termite proofing for Tower Crane Zone 8 | J13: Grid K-M/17-20 | K13: A | L13: 44832 | O13: E:\Soft IRs\ICPL\L1-Tower IR's\new\3.pdf
A14: =1+A13 -> 4 | B14: Sub Structure | C14: Basement | D14: L1/4 | E14: 44828 | G14: PCC | H14: PCC as per IFC drawing | J14: Grid K-M/17-20 | K14: A | L14: 44840 | N14: 16 | O14: E:\Soft IRs\ICPL\L1-Tower IR's\new\4.pdf
A15: =1+A14 -> 5 | B15: Sub Structure | C15: Basement | D15: L1/5 | E15: 44828 | G15: Tower Crane | H15: Layout of Tower Crane foundation and columns as per IFC Zone 8 | J15: Grid K-M/17-20 | K15: A | L15: 44840 | O15: E:\Soft IRs\ICPL\L1-Tower IR's\new\5.pdf
A16: =1+A15 -> 6 | B16: Sub Structure | C16: Basement | D16: L1/6 | E16: 44837 | G16: Tower Crane | H16: Steel fixing of Tower Crane foundation and dowels Zone 8 | J16: Grid K-M/17-20 | K16: A | L16: 44840 | O16: E:\Soft IRs\ICPL\L1-Tower IR's\new\6.pdf
A17: =1+A16 -> 7 | B17: Sub Structure | C17: Basement | D17: L1/7 | E17: 44838 | G17: Raft | H17: Layout and level of raft top of Tower crane columns Zone 8 | J17: Grid K-M/18-19 | K17: A | L17: 44840 | O17: E:\Soft IRs\ICPL\L1-Tower IR's\new\7.pdf
A18: =1+A17 -> 8 | B18: Sub Structure | C18: Basement | D18: L1/8 | E18: 44839 | G18: Raft concrete | H18: Raft concrete pouring 4000 psi | J18: Grid K-M/17-20 | K18: A | L18: 44840 | N18: 65 | O18: E:\Soft IRs\ICPL\L1-Tower IR's\new\8.pdf
A19: =1+A18 -> 9 | B19: Sub Structure | C19: Basement | D19: L1/9 | E19: 44836 | G19: Surface preparation | H19: Layout excavation, surface preparation and final bed level L Tower | J19: Grid G-T/15-26 | K19: A | L19: 44840 | O19: E:\Soft IRs\ICPL\L1-Tower IR's\new\9.pdf
A20: =1+A19 -> 10 | B20: Sub Structure | C20: Basement | D20: L1/10 | E20: 44845 | G20: Surface preparation | H20: Excavation, Surface preparation and final bed level of Lift, service lift and sumpits | J20: Grid G-T/15-26 | K20: A | L20: 44846 | O20: E:\Soft IRs\ICPL\L1-Tower IR's\new\10.pdf
A21: =1+A20 -> 11 | B21: Sub Structure | C21: Basement | D21: L1/11 | E21: 44847 | G21: PCC | H21: 1st layer PCC level Layout of lift, service Lift, sumpit | J21: Grid G-T/15-26 | K21: A | L21: 44851 | M21: PC-19 | N21: 9 | O21: E:\Soft IRs\ICPL\L1-Tower IR's\new\11.pdf
A22: =1+A21 -> 12 | B22: Sub Structure | C22: Basement | D22: L1/12 | E22: 44858 | G22: Brick work | H22: Brick work of lift, service lift, sumpit and allow for plaster | J22: Grid G-T/15-26 | K22: A | L22: 44866 | O22: E:\Soft IRs\ICPL\L1-Tower IR's\new\12.pdf
A23: =1+A22 -> 13 | B23: Sub Structure | C23: Basement | D23: L1/13 | E23: 44858 | G23: Surface preparation | H23: Surface preparation level and allow for termite proofing 1st Layer PCC | J23: Grid F-G/20-26 | K23: A | L23: 44866 | O23: E:\Soft IRs\ICPL\L1-Tower IR's\new\13.pdf
A24: =1+A23 -> 14 | B24: Sub Structure | C24: Basement | D24: L1/14 | E24: 44859 | G24: PCC | H24: 1st layer PCC level and allow for brickwork | J24: Grid F-T/26-26 | K24: A | L24: 44866 | O24: E:\Soft IRs\ICPL\L1-Tower IR's\new\14.pdf
A25: =1+A24 -> 15 | B25: Sub Structure | C25: Basement | D25: L1/15
A26: =1+A25 -> 16 | B26: Sub Structure | C26: Basement | D26: L1/16 | E26: 44859 | G26: Termite proofing | H26: Termite proofing before PCC | J26: Grid F-G/20-26 | K26: A | L26: 44859 | O26: E:\Soft IRs\ICPL\L1-Tower IR's\new\16.pdf
A27: =1+A26 -> 17 | B27: Sub Structure | C27: Basement | D27: L1/17 | E27: 44860 | G27: Brick work | H27: Brick work and allow for plaster of raft protection wall | J27: Grid F-H/26 | K27: A | L27: 44866 | O27: E:\Soft IRs\ICPL\L1-Tower IR's\new\17.pdf
A28: =1+A27 -> 18 | B28: Sub Structure | C28: Basement | D28: L1/18 | E28: 44860 | G28: Surface preparation | H28: Surface preparation and allow for termite proofing | J28: Grid H-L/20-26 | K28: A | L28: 44866 | O28: E:\Soft IRs\ICPL\L1-Tower IR's\new\18.pdf
A29: =1+A28 -> 19 | B29: Sub Structure | C29: Basement | D29: L1/19 | E29: 44860 | G29: Termite proofing | H29: Termite proofing and allow for PCC | J29: Grid H-L/20-26 | K29: A | L29: 44866 | O29: E:\Soft IRs\ICPL\L1-Tower IR's\new\19.pdf
A30: =1+A29 -> 20 | B30: Sub Structure | C30: Basement | D30: L1/20 | E30: 44861 | G30: PCC Level | H30: Layout and 1st PCC Level and allow for bricki work | J30: Grid G-L/20 | K30: A | L30: 44866 | O30: E:\Soft IRs\ICPL\L1-Tower IR's\new\20.pdf
A31: =1+A30 -> 21 | B31: Sub Structure | C31: Basement | D31: L1/21 | E31: 44865 | G31: PCC | H31: 1st layer PCC level and allow for primer and membrane | J31: Grid F-H/11-20 | K31: A | L31: 44866 | O31: E:\Soft IRs\ICPL\L1-Tower IR's\new\21.pdf
B32: Sub Structure | C32: Basement | D32: L1/22 | E32: 44865 | G32: PCC | H32: 1st layer of PCC level and allow for primer and membrane | J32: Grid G-H/20-26 | K32: A | L32: 44866 | O32: E:\Soft IRs\ICPL\L1-Tower IR's\new\22.pdf
B33: Sub Structure | C33: Basement | D33: L1/23 | E33: 44866 | G33: Primer, membrane | H33: Primer and membrane and allow for 2nd layer PCC | J33: Grid G-H/20-26 | K33: A | L33: 44873 | O33: E:\14.Soft IRs\ICPL\L1-Tower IR's\new\23.pdf
B34: Sub Structure | C34: Basement | D34: L1/24 | E34: 44866 | G34: Primer, membrane | H34: Primer and membrane and allow for 2nd layer PCC | J34: Grid F-H/11-20, F/20-26 | K34: A | L34: 44873 | O34: E:\14.Soft IRs\ICPL\L1-Tower IR's\new\24.pdf
B35: Sub Structure | C35: Basement | D35: L1/25 | E35: 44866 | G35: PCC | H35: 2nd layer PCC Level | J35: Grid F-H/15-26 | K35: A | L35: 44873 | O35: E:\14.Soft IRs\ICPL\L1-Tower IR's\new\25.pdf
B36: Sub Structure | C36: Basement | D36: L1/26 | E36: 44866 | G36: Surface preparation | H36: Surface preparation and allow for termite proofing | J36: Grid L-T/15-26 | K36: A | L36: 44873 | O36: E:\14.Soft IRs\ICPL\L1-Tower IR's\new\26.pdf
B37: Sub Structure | C37: Basement | D37: L1/27 | E37: 44866 | G37: Brick work | H37: Brick work and allow for plaster of raft protection wall | J37: Grid H-T/26 | K37: A | L37: 44873 | O37: E:\14.Soft IRs\ICPL\L1-Tower IR's\new\27.pdf
B38: Sub Structure | C38: Basement | D38: L1/28 | E38: 44868 | G38: PCC | H38: 1st layer PCC level and allow for primer and membrane of lift and sumpits | J38: L1 Tower lift,sumpits | K38: A | L38: 44873 | O38: E:\14.Soft IRs\ICPL\L1-Tower IR's\new\28.pdf
B39: Sub Structure | C39: Basement | D39: L1/29 | E39: 44869 | G39: Layout,level | H39: Layout and level of RTW1, columns and service lift and allow for steel | J39: F-H/20-26 | K39: A | L39: 44873 | O39: E:\14.Soft IRs\ICPL\L1-Tower IR's\new\29.pdf
B40: Sub Structure | C40: Basement | D40: L1/30 | E40: 44869 | G40: PCC | H40: 1st layer of PCC and allow for Primer & Mebrane | J40: J-N/20-26 | K40: A | L40: 44873 | O40: E:\14.Soft IRs\ICPL\L1-Tower IR's\new\30.pdf
B41: Sub Structure | C41: Basement | D41: L1/31 | E41: 44869 | G41: PCC | H41: Level of 2nd layer PCC before raft | J41: F-H/11-26 | K41: A | L41: 44873 | O41: E:\14.Soft IRs\ICPL\L1-Tower IR's\new\31.pdf
B42: Sub Structure | C42: Basement | D42: L1/32 | E42: 44869 | G42: Primer | H42: Check primer and membrane and allow for 2nd layer PCC | J42: J-N/20-26 | K42: A | L42: 44882
...

Sheet L2 Tower ICPL
C1: PROJECT: CONSTRUCTION OF LAKE CITY ROOF GARDEN APARTMENTS
J2: IR STATUS
D3: INSPECTION REQUEST LOG (L2 Tower) | J3: Fully Approved (A) | L3: =COUNTIFS(K:K,"A") -> 799
J4: Approved with comments (B) | L4: =COUNTIFS(K:K, "B") -> 5
J5: Rejected ( R) | L5: =COUNTIFS(K:K, "R") -> 0
J6: Open/Pending (OP) | L6: =COUNTIFS(K:K, "OP") -> 3
J7: Total | L7: =SUM(L3:L6) -> 807
A9: Sr. | B9: Work Package | C9: Floor | D9: IR No. | E9: Submission date | F9: Inspection Date | G9: Element | H9: Activity Description | J9: Location/ Grid Ref | K9: IR Status | L9: IR Closing date | M9: Pour Card No. | N9: Concrete Qty (m3) | O9: Attachment | P9: Remarks
B10: I TOWER
A11: 1 | B11: Sub Structure | C11: Basement | D11: L2/1 | E11: 44851 | G11: Excavation level | H11: Excavation level and surface preparation of service lift L2 Tower Zone 2 | J11: Grid G-T/1-7 | K11: A | L11: 44854 | O11: E:\Soft IRs\ICPL\L2 -Tower IR's\new\1.pdf
A12: 2 | B12: Sub Structure | C12: Basement | D12: L2/2
A13: 3 | B13: Sub Structure | C13: Basement | D13: L2/3 | E13: 44852 | G13: Layout of PCC | H13: Level and layout of PCC 1st layer of service lift | J13: Grid F-G/1-11 | K13: A | L13: 44854 | O13: E:\Soft IRs\ICPL\L2 -Tower IR's\new\3.pdf
A14: =1+A13 -> 4 | B14: Sub Structure | C14: Basement | D14: L2/4 | E14: 44852 | G14: Excavation level | H14: Excavation level, surface preparation for PCC | J14: Grid G-K/1-7 | K14: A | L14: 44854 | O14: E:\Soft IRs\ICPL\L2 -Tower IR's\new\4.pdf
A15: =1+A14 -> 5 | B15: Sub Structure | C15: Basement | D15: L2/5 | E15: 44853 | G15: 1st PCC level | H15: Layout and 1st PCC level | J15: Grid G-K/1-7, F-G/11-13 | K15: A | L15: 44854 | O15: E:\Soft IRs\ICPL\L2 -Tower IR's\new\5.pdf
A16: =1+A15 -> 6 | B16: Sub Structure | C16: Basement | D16: L2/6 | E16: 44853 | G16: Layout of isolated | H16: Layout of isolated footing for termite proofing and PCC | J16: Grid F-J/7-11 | K16: A | L16: 44854 | O16: E:\Soft IRs\ICPL\L2 -Tower IR's\new\6.pdf
A17: =1+A16 -> 7 | B17: Sub Structure | C17: Basement | D17: L2/7 | E17: 44853 | G17: Brick work | H17: Brickwork of service lift and brickwork for raft protection | J17: Grid F-H/H-J/3-3 | K17: A | L17: 44858 | O17: E:\Soft IRs\ICPL\L2 -Tower IR's\new\7.pdf
A18: =1+A17 -> 8 | B18: Sub Structure | C18: Basement | D18: L2/8 | E18: 44854 | G18: Plaster | H18: Plaster of Raft Protection wall | J18: Grid F-H/1 | K18: A | L18: 44858 | O18: E:\Soft IRs\ICPL\L2 -Tower IR's\new\8.pdf
A19: =1+A18 -> 9 | B19: Sub Structure | C19: Basement | D19: L2/9 | E19: 44858 | G19: Layout | H19: Layout of Service Lift, column, foooting and retaining wall of SOG area for steel fixing | J19: Grid F-J/1-7 & F-H/7-11 | K19: A | L19: 44866 | O19: E:\Soft IRs\ICPL\L2 -Tower IR's\new\9.pdf
A20: =1+A19 -> 10 | B20: Sub Structure | C20: Basement | D20: L2/10 | E20: 44855 | G20: Plaster | H20: Plaster of service lift wall and allow for primer and membrane on wall | J20: Grid H-J/2-4 | K20: A | L20: 44858 | O20: E:\Soft IRs\ICPL\L2 -Tower IR's\new\10.pdf
A21: =1+A20 -> 11 | B21: Sub Structure | C21: Basement | D21: L2/11 | E21: 44855 | G21: Primer | H21: Primer and membrane for 2nd layer of PCC | J21: Grid F-K/1-7 | K21: A | L21: 44858 | O21: E:\Soft IRs\ICPL\L2 -Tower IR's\new\11.pdf
B22: Sub Structure | C22: Basement | D22: L2/12 | E22: 44855 | G22: Level | H22: Level for 2nd layer of PCC of SOG Area L2 Tower | J22: Grid F-K/1-7 & F-H/7-11 | K22: A | L22: 44858 | O22: E:\Soft IRs\ICPL\L2 -Tower IR's\new\12.pdf
A23: =1+A21 -> 12 | B23: Sub Structure | C23: Basement | D23: L2/13 | E23: 44851 | G23: Termite proofing | H23: Termite proofing before PCC | J23: Grid F-K/1-7 & F-H/7-11 | K23: A | L23: 44854 | O23: E:\Soft IRs\ICPL\L2 -Tower IR's\new\13.pdf
A24: =1+A23 -> 13 | B24: Sub Structure | C24: Basement | D24: L2/14 | E24: 44860 | G24: Steel fixing | H24: Steel fixing of Raft L2 Tower | J24: Grid F-G/1-7 | K24: A | L24: 44866 | O24: E:\Soft IRs\ICPL\L2 -Tower IR's\new\14.pdf
A25: =1+A24 -> 14 | B25: Sub Structure | C25: Basement | D25: L2/15 | E25: 44861 | G25: Joint | H25: Construction Joint and chicken Mesh of Pour 6 of L2 Tower | J25: Grid F-G/1-7 & H/7-11 | K25: A | L25: 44866 | O25: E:\Soft IRs\ICPL\L2 -Tower IR's\new\15.pdf
A26: =1+A25 -> 15 | B26: Sub Structure | C26: Basement | D26: L2/16 | E26: 44861 | G26: Water stopper | H26: PVC water stopper placing and fixing in raft foundation Zone 7 | J26: Grid F-G/1 | K26: A | L26: 44873 | O26: E:\14.Soft IRs\ICPL\L2 -Tower IR's\new\16.pdf
A27: =1+A26 -> 16 | B27: Sub Structure | C27: Basement | D27: L2/17 | E27: 44861 | G27: Steel fixing | H27: Steel fixing of SOG Area and footing Zone 8 and allow for pouring | J27: Grid F-G/1-7, F-H/7-11 | K27: A | L27: 44866 | O27: E:\Soft IRs\ICPL\L2 -Tower IR's\new\17.pdf
A28: =1+A27 -> 17 | B28: Sub Structure | C28: Basement | D28: L2/18 | E28: 44861 | G28: Layout, level | H28: Level and layout of SOG Area and isolated footing and allow for termite proofing | J28: Grid F-J/11-20, J-K/17-20 | K28: A | L28: 44873 | O28: E:\14.Soft IRs\ICPL\L2 -Tower IR's\new\18.pdf
A29: =1+A28 -> 18 | B29: Sub Structure | C29: Basement | D29: L2/19 | E29: 44861 | G29: Termite proofing | H29: Termite proofing and allow for 1st layer of PCC of SOG Area | J29: Grid F-J/11-20, J-K/17-20 | K29: A | L29: 44866 | O29: E:\Soft IRs\ICPL\L2 -Tower IR's\new\19.pdf
A30: =1+A29 -> 19 | B30: Sub Structure | C30: Basement | D30: L2/20 | E30: 44863 | G30: Layout, level | H30: RCC raft top level and layout of column and RTW Zone 7 L2 Tower | J30: Grid F/1-13, G-H/1-7 | K30: A | L30: 44866 | O30: E:\Soft IRs\ICPL\L2 -Tower IR's\new\20.pdf
A31: =1+A30 -> 20 | B31: Sub Structure | C31: Basement | D31: L2/21 | E31: 44865 | G31: Steel fixing | H31: Steel fixing of columns and allow for pouring | J31: Grid G/1-11 | K31: A | L31: 44866 | O31: E:\Soft IRs\ICPL\L2 -Tower IR's\new\21.pdf
A32: =1+A31 -> 21 | B32: Sub Structure | C32: Basement | D32: L2/22 | E32: 44870 | G32: Curing | H32: Check the curing of Raft L2 Tower | J32: Grid G-K/1-7, F/1-7 | K32: A | L32: 44879
A33: =1+A32 -> 22 | B33: Sub Structure | C33: Basement | D33: L2/23 | E33: 44873 | G33: Water stopper | H33: PVC vertical water stopper for expansion joint as per IFC | J33: Grid G/1 | K33: A | L33: 44879
A34: =1+A33 -> 23 | B34: Sub Structure | C34: Basement | D34: L2/24 | E34: 44873 | G34: Water stopper | H34: PVC Horizontal water stopper in RCC wall | J34: Grid F-G/1 | K34: A | L34: 44879
A35: =1+A34 -> 24 | B35: Sub Structure | C35: Basement | D35: L2/25 | E35: 44880 | G35: PCC | H35: 1st layer of PCC and allow for primer and membrane for isolated footing | J35: Grid M-M/15-19 | K35: A | L35: 44882
B36: Sub Structure | C36: Basement | D36: L2/26 | E36: 44923 | G36: Level, layout | H36: Excavation, Level, Layout, Surface Bed preparation of Tower Crane | J36: Grid K-M/7-10 | K36: A | L36: 44925
A37: =1+A35 -> 25 | B37: Sub Structure | C37: Basement | D37: L2/27 | E37: 44923 | G37: Termite proofing | H37: Termite Proofing & Allow for PCC of Tower Crane Foundation Zone 8 | J37: Grid K-M/7-10 | K37: A | L37: 44925
A38: =1+A37 -> 26 | B38: Sub Structure | C38: Basement | D38: L2/28 | E38: 44926 | G38: Level, layout | H38: Check level & Layout of PCC layer of Tower Crane Foundation Zone 8 | J38: Grid K-M/7-10 | K38: A | L38: 44928
A39: =1+A38 -> 27 | B39: Sub Structure | C39: Basement | D39: L2/29 | E39: 44931 | G39: Steel fixing | H39: Check top and bottom steel fixing of Tower Crane Foundation Zone 8 SOG | J39: Grid K-M/7-10 | K39: A | L39: 44931
A40: =1+A39 -> 28 | B40: Sub Structure | C40: Basement | D40: L2/30 | E40: 44931 | G40: Concrete Pouring | H40: Allow for concrete pouring of Tower Crane Foundation Zone 8 SOG | J40: Grid K-M/7-10 | K40: A | L40: 44932
A41: =1+A40 -> 29 | B41: Sub Structure | C41: Basement | D41: L2/31 | E41: 44935 | G41: Level, layout | H41: Check top raft level & layout of Tower Crane Zone 8 | J41: Grid K-M/7-10 | K41: A | L41: 44936
...

Sheet IIL I Tower IR
C1: PROJECT: CONSTRUCTION OF LAKE CITY ROOF GARDEN APARTMENTS
J2: IR STATUS
D3: INSPECTION REQUEST LOG (I Tower) IIL-CSL | J3: Fully Approved (A) | L3: =COUNTIFS(K:K,"A") -> 226
J4: Approved with comments (B) | L4: =COUNTIFS(K:K, "B") -> 34
J5: Rejected ( R) | L5: =COUNTIFS(K:K, "R") -> 3 | N5: As of : | P5: =TODAY() -> 46010
J6: Open/Pending (OP) | L6: =COUNTIFS(K:K, "OP") -> 2
J7: Total | L7: =SUM(L3:L6) -> 265
A9: Sr. | B9: Work Package | C9: Floor | D9: IR No. | E9: Submission Date | F9: Inspection Date | G9: Element | H9: Activity Description | I9: Level | J9: Location/ Grid Ref | K9: IR Status | L9: IR closing Date | M9: Pour Card No. | N9: Concrete Qty (m3) | O9: Attachment | P9: Remarks
A10: 1 | B10: Sub Structure | C10: Basement | D10: IT/1 | E10: 44821 | G10: Retaining wall | H10: Inspection of retaining wall, starter | J10: Grid F-G/7-8 | K10: A | L10: 44824 | O10: E:\Soft IRs\IIL\I Tower\1.pdf
